<robot name = "robot">
    <link name="Torso">
        <inertial>
            <origin xyz="0 2 10" rpy="0 0 0"/>
            <mass value="1" />
            <inertia ixx="100" ixy="0" ixz="0" iyy="100" iyz="0" izz="100" />
        </inertial>
        <visual>
            <origin xyz="0 2 10" rpy="0 0 0"/>
            <geometry>
                <box size="0.5 0.5 0.5" />
            </geometry>
            <material name="Blue">
            <color rgba="0 0 1.0 1.0"/>
            </material>
        </visual>
        <collision>
            <origin xyz="0 2 10" rpy="0 0 0"/>
            <geometry>
                <box size="0.5 0.5 0.5" />
            </geometry>
        </collision>
    </link>
    <joint name="Torso_Link0" type="revolute">
       <parent link="Torso"/>
       <child  link="Link0"/>
       <origin rpy="0 0 0" xyz="0 2.25 4.75" />
     <axis xyz="1 1 0"/>
       <limit effort="0.0" lower="-3.14159" upper="3.14159" velocity="0.0"/>
    </joint>
    <link name="LeftLink0">
        <inertial>
            <origin xyz="0 0.25 -0.25" rpy="0 0 0"/>
            <mass value="1" />
            <inertia ixx="100" ixy="0" ixz="0" iyy="100" iyz="0" izz="100" />
        </inertial>
        <visual>
            <origin xyz="0 0.25 -0.25" rpy="0 0 0"/>
            <geometry>
                <box size="0.6265015869215932 0.8759043605662777 0.39644034294134667" />
            </geometry>
            <material name="Blue">
            <color rgba="0 0 1.0 1.0"/>
            </material>
        </visual>
        <collision>
            <origin xyz="0 0.25 -0.25" rpy="0 0 0"/>
            <geometry>
                <box size="0.6265015869215932 0.8759043605662777 0.39644034294134667" />
            </geometry>
        </collision>
    </link>
    <link name="LeftLink1">
        <inertial>
            <origin xyz="0 0.25 -0.25" rpy="0 0 0"/>
            <mass value="1" />
            <inertia ixx="100" ixy="0" ixz="0" iyy="100" iyz="0" izz="100" />
        </inertial>
        <visual>
            <origin xyz="0 0.25 -0.25" rpy="0 0 0"/>
            <geometry>
                <box size="0.07095063344550778 0.28568632581745146 0.3089096438260416" />
            </geometry>
            <material name="Green">
            <color rgba="0 1.0 0 1.0"/>
            </material>
        </visual>
        <collision>
            <origin xyz="0 0.25 -0.25" rpy="0 0 0"/>
            <geometry>
                <box size="0.07095063344550778 0.28568632581745146 0.3089096438260416" />
            </geometry>
        </collision>
    </link>
    <link name="LeftLink2">
        <inertial>
            <origin xyz="0 0.25 -0.25" rpy="0 0 0"/>
            <mass value="1" />
            <inertia ixx="100" ixy="0" ixz="0" iyy="100" iyz="0" izz="100" />
        </inertial>
        <visual>
            <origin xyz="0 0.25 -0.25" rpy="0 0 0"/>
            <geometry>
                <box size="0.42799367033491564 0.7909681260355276 0.6868890911453087" />
            </geometry>
            <material name="Blue">
            <color rgba="0 0 1.0 1.0"/>
            </material>
        </visual>
        <collision>
            <origin xyz="0 0.25 -0.25" rpy="0 0 0"/>
            <geometry>
                <box size="0.42799367033491564 0.7909681260355276 0.6868890911453087" />
            </geometry>
        </collision>
    </link>
    <link name="LeftLink3">
        <inertial>
            <origin xyz="0 0.25 -0.25" rpy="0 0 0"/>
            <mass value="1" />
            <inertia ixx="100" ixy="0" ixz="0" iyy="100" iyz="0" izz="100" />
        </inertial>
        <visual>
            <origin xyz="0 0.25 -0.25" rpy="0 0 0"/>
            <geometry>
                <box size="0.10932471492117779 0.4741183786606654 0.7530045053944229" />
            </geometry>
            <material name="Green">
            <color rgba="0 1.0 0 1.0"/>
            </material>
        </visual>
        <collision>
            <origin xyz="0 0.25 -0.25" rpy="0 0 0"/>
            <geometry>
                <box size="0.10932471492117779 0.4741183786606654 0.7530045053944229" />
            </geometry>
        </collision>
    </link>
    <link name="LeftLink4">
        <inertial>
            <origin xyz="0 0.25 -0.25" rpy="0 0 0"/>
            <mass value="1" />
            <inertia ixx="100" ixy="0" ixz="0" iyy="100" iyz="0" izz="100" />
        </inertial>
        <visual>
            <origin xyz="0 0.25 -0.25" rpy="0 0 0"/>
            <geometry>
                <box size="0.5522475167125668 0.7306202779339102 0.790914681293578" />
            </geometry>
            <material name="Green">
            <color rgba="0 1.0 0 1.0"/>
            </material>
        </visual>
        <collision>
            <origin xyz="0 0.25 -0.25" rpy="0 0 0"/>
            <geometry>
                <box size="0.5522475167125668 0.7306202779339102 0.790914681293578" />
            </geometry>
        </collision>
    </link>
    <link name="LeftLink5">
        <inertial>
            <origin xyz="0 0.25 -0.25" rpy="0 0 0"/>
            <mass value="1" />
            <inertia ixx="100" ixy="0" ixz="0" iyy="100" iyz="0" izz="100" />
        </inertial>
        <visual>
            <origin xyz="0 0.25 -0.25" rpy="0 0 0"/>
            <geometry>
                <box size="0.2823153076276218 0.14874249355777802 0.7816821123396723" />
            </geometry>
            <material name="Blue">
            <color rgba="0 0 1.0 1.0"/>
            </material>
        </visual>
        <collision>
            <origin xyz="0 0.25 -0.25" rpy="0 0 0"/>
            <geometry>
                <box size="0.2823153076276218 0.14874249355777802 0.7816821123396723" />
            </geometry>
        </collision>
    </link>
    <link name="LeftLink6">
        <inertial>
            <origin xyz="0 0.25 -0.25" rpy="0 0 0"/>
            <mass value="1" />
            <inertia ixx="100" ixy="0" ixz="0" iyy="100" iyz="0" izz="100" />
        </inertial>
        <visual>
            <origin xyz="0 0.25 -0.25" rpy="0 0 0"/>
            <geometry>
                <box size="0.022083856030610916 0.5270431900388541 0.556574934355055" />
            </geometry>
            <material name="Green">
            <color rgba="0 1.0 0 1.0"/>
            </material>
        </visual>
        <collision>
            <origin xyz="0 0.25 -0.25" rpy="0 0 0"/>
            <geometry>
                <box size="0.022083856030610916 0.5270431900388541 0.556574934355055" />
            </geometry>
        </collision>
    </link>
    <link name="LeftLink7">
        <inertial>
            <origin xyz="0 0.25 -0.25" rpy="0 0 0"/>
            <mass value="1" />
            <inertia ixx="100" ixy="0" ixz="0" iyy="100" iyz="0" izz="100" />
        </inertial>
        <visual>
            <origin xyz="0 0.25 -0.25" rpy="0 0 0"/>
            <geometry>
                <box size="0.640213295925364 0.8243262019551382 0.7849873388386022" />
            </geometry>
            <material name="Blue">
            <color rgba="0 0 1.0 1.0"/>
            </material>
        </visual>
        <collision>
            <origin xyz="0 0.25 -0.25" rpy="0 0 0"/>
            <geometry>
                <box size="0.640213295925364 0.8243262019551382 0.7849873388386022" />
            </geometry>
        </collision>
    </link>
    <link name="LeftLink8">
        <inertial>
            <origin xyz="0 0.25 -0.25" rpy="0 0 0"/>
            <mass value="1" />
            <inertia ixx="100" ixy="0" ixz="0" iyy="100" iyz="0" izz="100" />
        </inertial>
        <visual>
            <origin xyz="0 0.25 -0.25" rpy="0 0 0"/>
            <geometry>
                <box size="0.9767276982178947 0.24441857916391063 0.46931749300308645" />
            </geometry>
            <material name="Blue">
            <color rgba="0 0 1.0 1.0"/>
            </material>
        </visual>
        <collision>
            <origin xyz="0 0.25 -0.25" rpy="0 0 0"/>
            <geometry>
                <box size="0.9767276982178947 0.24441857916391063 0.46931749300308645" />
            </geometry>
        </collision>
    </link>
    <link name="LeftLink9">
        <inertial>
            <origin xyz="0 0.25 -0.25" rpy="0 0 0"/>
            <mass value="1" />
            <inertia ixx="100" ixy="0" ixz="0" iyy="100" iyz="0" izz="100" />
        </inertial>
        <visual>
            <origin xyz="0 0.25 -0.25" rpy="0 0 0"/>
            <geometry>
                <box size="0.4537301571499689 0.8898275867981407 0.26133831684566144" />
            </geometry>
            <material name="Blue">
            <color rgba="0 0 1.0 1.0"/>
            </material>
        </visual>
        <collision>
            <origin xyz="0 0.25 -0.25" rpy="0 0 0"/>
            <geometry>
                <box size="0.4537301571499689 0.8898275867981407 0.26133831684566144" />
            </geometry>
        </collision>
    </link>
    <link name="LeftLink10">
        <inertial>
            <origin xyz="0 0.25 -0.25" rpy="0 0 0"/>
            <mass value="1" />
            <inertia ixx="100" ixy="0" ixz="0" iyy="100" iyz="0" izz="100" />
        </inertial>
        <visual>
            <origin xyz="0 0.25 -0.25" rpy="0 0 0"/>
            <geometry>
                <box size="0.8399245111497322 0.795341266304772 0.8537172142377708" />
            </geometry>
            <material name="Blue">
            <color rgba="0 0 1.0 1.0"/>
            </material>
        </visual>
        <collision>
            <origin xyz="0 0.25 -0.25" rpy="0 0 0"/>
            <geometry>
                <box size="0.8399245111497322 0.795341266304772 0.8537172142377708" />
            </geometry>
        </collision>
    </link>
    <joint name="LeftLink0_LeftLink1" type="revolute">
       <parent link="LeftLink0"/>
       <child  link="eftLink1"/>
       <origin rpy="0 0 0" xyz="0 0.5 0" />
     <axis xyz="1 1 0"/>
       <limit effort="0.0" lower="-3.14159" upper="3.14159" velocity="0.0"/>
    </joint>
    <joint name="LeftLink1_LeftLink2" type="revolute">
       <parent link="LeftLink1"/>
       <child  link="eftLink2"/>
       <origin rpy="0 0 0" xyz="0 0.5 0" />
     <axis xyz="1 1 0"/>
       <limit effort="0.0" lower="-3.14159" upper="3.14159" velocity="0.0"/>
    </joint>
    <joint name="LeftLink2_LeftLink3" type="revolute">
       <parent link="LeftLink2"/>
       <child  link="eftLink3"/>
       <origin rpy="0 0 0" xyz="0 0.5 0" />
     <axis xyz="1 1 0"/>
       <limit effort="0.0" lower="-3.14159" upper="3.14159" velocity="0.0"/>
    </joint>
    <joint name="LeftLink3_LeftLink4" type="revolute">
       <parent link="LeftLink3"/>
       <child  link="eftLink4"/>
       <origin rpy="0 0 0" xyz="0 0.5 0" />
     <axis xyz="1 1 0"/>
       <limit effort="0.0" lower="-3.14159" upper="3.14159" velocity="0.0"/>
    </joint>
    <joint name="LeftLink4_LeftLink5" type="revolute">
       <parent link="LeftLink4"/>
       <child  link="eftLink5"/>
       <origin rpy="0 0 0" xyz="0 0.5 0" />
     <axis xyz="1 1 0"/>
       <limit effort="0.0" lower="-3.14159" upper="3.14159" velocity="0.0"/>
    </joint>
    <joint name="LeftLink5_LeftLink6" type="revolute">
       <parent link="LeftLink5"/>
       <child  link="eftLink6"/>
       <origin rpy="0 0 0" xyz="0 0.5 0" />
     <axis xyz="1 1 0"/>
       <limit effort="0.0" lower="-3.14159" upper="3.14159" velocity="0.0"/>
    </joint>
    <joint name="LeftLink6_LeftLink7" type="revolute">
       <parent link="LeftLink6"/>
       <child  link="eftLink7"/>
       <origin rpy="0 0 0" xyz="0 0.5 0" />
     <axis xyz="1 1 0"/>
       <limit effort="0.0" lower="-3.14159" upper="3.14159" velocity="0.0"/>
    </joint>
    <joint name="LeftLink7_LeftLink8" type="revolute">
       <parent link="LeftLink7"/>
       <child  link="eftLink8"/>
       <origin rpy="0 0 0" xyz="0 0.5 0" />
     <axis xyz="1 1 0"/>
       <limit effort="0.0" lower="-3.14159" upper="3.14159" velocity="0.0"/>
    </joint>
    <joint name="LeftLink8_LeftLink9" type="revolute">
       <parent link="LeftLink8"/>
       <child  link="eftLink9"/>
       <origin rpy="0 0 0" xyz="0 0.5 0" />
     <axis xyz="1 1 0"/>
       <limit effort="0.0" lower="-3.14159" upper="3.14159" velocity="0.0"/>
    </joint>
    <joint name="LeftLink9_LeftLink10" type="revolute">
       <parent link="LeftLink9"/>
       <child  link="eftLink10"/>
       <origin rpy="0 0 0" xyz="0 0.5 0" />
     <axis xyz="1 1 0"/>
       <limit effort="0.0" lower="-3.14159" upper="3.14159" velocity="0.0"/>
    </joint>
    <link name="RightLink0">
        <inertial>
            <origin xyz="0 -0.25 -0.25" rpy="0 0 0"/>
            <mass value="1" />
            <inertia ixx="100" ixy="0" ixz="0" iyy="100" iyz="0" izz="100" />
        </inertial>
        <visual>
            <origin xyz="0 -0.25 -0.25" rpy="0 0 0"/>
            <geometry>
                <box size="0.6265015869215932 0.8759043605662777 0.39644034294134667" />
            </geometry>
            <material name="Blue">
            <color rgba="0 0 1.0 1.0"/>
            </material>
        </visual>
        <collision>
            <origin xyz="0 -0.25 -0.25" rpy="0 0 0"/>
            <geometry>
                <box size="0.6265015869215932 0.8759043605662777 0.39644034294134667" />
            </geometry>
        </collision>
    </link>
    <link name="RightLink1">
        <inertial>
            <origin xyz="0 -0.25 -0.25" rpy="0 0 0"/>
            <mass value="1" />
            <inertia ixx="100" ixy="0" ixz="0" iyy="100" iyz="0" izz="100" />
        </inertial>
        <visual>
            <origin xyz="0 -0.25 -0.25" rpy="0 0 0"/>
            <geometry>
                <box size="0.07095063344550778 0.28568632581745146 0.3089096438260416" />
            </geometry>
            <material name="Blue">
            <color rgba="0 0 1.0 1.0"/>
            </material>
        </visual>
        <collision>
            <origin xyz="0 -0.25 -0.25" rpy="0 0 0"/>
            <geometry>
                <box size="0.07095063344550778 0.28568632581745146 0.3089096438260416" />
            </geometry>
        </collision>
    </link>
    <link name="RightLink2">
        <inertial>
            <origin xyz="0 -0.25 -0.25" rpy="0 0 0"/>
            <mass value="1" />
            <inertia ixx="100" ixy="0" ixz="0" iyy="100" iyz="0" izz="100" />
        </inertial>
        <visual>
            <origin xyz="0 -0.25 -0.25" rpy="0 0 0"/>
            <geometry>
                <box size="0.42799367033491564 0.7909681260355276 0.6868890911453087" />
            </geometry>
            <material name="Blue">
            <color rgba="0 0 1.0 1.0"/>
            </material>
        </visual>
        <collision>
            <origin xyz="0 -0.25 -0.25" rpy="0 0 0"/>
            <geometry>
                <box size="0.42799367033491564 0.7909681260355276 0.6868890911453087" />
            </geometry>
        </collision>
    </link>
    <link name="RightLink3">
        <inertial>
            <origin xyz="0 -0.25 -0.25" rpy="0 0 0"/>
            <mass value="1" />
            <inertia ixx="100" ixy="0" ixz="0" iyy="100" iyz="0" izz="100" />
        </inertial>
        <visual>
            <origin xyz="0 -0.25 -0.25" rpy="0 0 0"/>
            <geometry>
                <box size="0.10932471492117779 0.4741183786606654 0.7530045053944229" />
            </geometry>
            <material name="Green">
            <color rgba="0 1.0 0 1.0"/>
            </material>
        </visual>
        <collision>
            <origin xyz="0 -0.25 -0.25" rpy="0 0 0"/>
            <geometry>
                <box size="0.10932471492117779 0.4741183786606654 0.7530045053944229" />
            </geometry>
        </collision>
    </link>
    <link name="RightLink4">
        <inertial>
            <origin xyz="0 -0.25 -0.25" rpy="0 0 0"/>
            <mass value="1" />
            <inertia ixx="100" ixy="0" ixz="0" iyy="100" iyz="0" izz="100" />
        </inertial>
        <visual>
            <origin xyz="0 -0.25 -0.25" rpy="0 0 0"/>
            <geometry>
                <box size="0.5522475167125668 0.7306202779339102 0.790914681293578" />
            </geometry>
            <material name="Green">
            <color rgba="0 1.0 0 1.0"/>
            </material>
        </visual>
        <collision>
            <origin xyz="0 -0.25 -0.25" rpy="0 0 0"/>
            <geometry>
                <box size="0.5522475167125668 0.7306202779339102 0.790914681293578" />
            </geometry>
        </collision>
    </link>
    <link name="RightLink5">
        <inertial>
            <origin xyz="0 -0.25 -0.25" rpy="0 0 0"/>
            <mass value="1" />
            <inertia ixx="100" ixy="0" ixz="0" iyy="100" iyz="0" izz="100" />
        </inertial>
        <visual>
            <origin xyz="0 -0.25 -0.25" rpy="0 0 0"/>
            <geometry>
                <box size="0.2823153076276218 0.14874249355777802 0.7816821123396723" />
            </geometry>
            <material name="Blue">
            <color rgba="0 0 1.0 1.0"/>
            </material>
        </visual>
        <collision>
            <origin xyz="0 -0.25 -0.25" rpy="0 0 0"/>
            <geometry>
                <box size="0.2823153076276218 0.14874249355777802 0.7816821123396723" />
            </geometry>
        </collision>
    </link>
    <link name="RightLink6">
        <inertial>
            <origin xyz="0 -0.25 -0.25" rpy="0 0 0"/>
            <mass value="1" />
            <inertia ixx="100" ixy="0" ixz="0" iyy="100" iyz="0" izz="100" />
        </inertial>
        <visual>
            <origin xyz="0 -0.25 -0.25" rpy="0 0 0"/>
            <geometry>
                <box size="0.022083856030610916 0.5270431900388541 0.556574934355055" />
            </geometry>
            <material name="Green">
            <color rgba="0 1.0 0 1.0"/>
            </material>
        </visual>
        <collision>
            <origin xyz="0 -0.25 -0.25" rpy="0 0 0"/>
            <geometry>
                <box size="0.022083856030610916 0.5270431900388541 0.556574934355055" />
            </geometry>
        </collision>
    </link>
    <link name="RightLink7">
        <inertial>
            <origin xyz="0 -0.25 -0.25" rpy="0 0 0"/>
            <mass value="1" />
            <inertia ixx="100" ixy="0" ixz="0" iyy="100" iyz="0" izz="100" />
        </inertial>
        <visual>
            <origin xyz="0 -0.25 -0.25" rpy="0 0 0"/>
            <geometry>
                <box size="0.640213295925364 0.8243262019551382 0.7849873388386022" />
            </geometry>
            <material name="Green">
            <color rgba="0 1.0 0 1.0"/>
            </material>
        </visual>
        <collision>
            <origin xyz="0 -0.25 -0.25" rpy="0 0 0"/>
            <geometry>
                <box size="0.640213295925364 0.8243262019551382 0.7849873388386022" />
            </geometry>
        </collision>
    </link>
    <link name="RightLink8">
        <inertial>
            <origin xyz="0 -0.25 -0.25" rpy="0 0 0"/>
            <mass value="1" />
            <inertia ixx="100" ixy="0" ixz="0" iyy="100" iyz="0" izz="100" />
        </inertial>
        <visual>
            <origin xyz="0 -0.25 -0.25" rpy="0 0 0"/>
            <geometry>
                <box size="0.9767276982178947 0.24441857916391063 0.46931749300308645" />
            </geometry>
            <material name="Blue">
            <color rgba="0 0 1.0 1.0"/>
            </material>
        </visual>
        <collision>
            <origin xyz="0 -0.25 -0.25" rpy="0 0 0"/>
            <geometry>
                <box size="0.9767276982178947 0.24441857916391063 0.46931749300308645" />
            </geometry>
        </collision>
    </link>
    <link name="RightLink9">
        <inertial>
            <origin xyz="0 -0.25 -0.25" rpy="0 0 0"/>
            <mass value="1" />
            <inertia ixx="100" ixy="0" ixz="0" iyy="100" iyz="0" izz="100" />
        </inertial>
        <visual>
            <origin xyz="0 -0.25 -0.25" rpy="0 0 0"/>
            <geometry>
                <box size="0.4537301571499689 0.8898275867981407 0.26133831684566144" />
            </geometry>
            <material name="Blue">
            <color rgba="0 0 1.0 1.0"/>
            </material>
        </visual>
        <collision>
            <origin xyz="0 -0.25 -0.25" rpy="0 0 0"/>
            <geometry>
                <box size="0.4537301571499689 0.8898275867981407 0.26133831684566144" />
            </geometry>
        </collision>
    </link>
    <link name="RightLink10">
        <inertial>
            <origin xyz="0 -0.25 -0.25" rpy="0 0 0"/>
            <mass value="1" />
            <inertia ixx="100" ixy="0" ixz="0" iyy="100" iyz="0" izz="100" />
        </inertial>
        <visual>
            <origin xyz="0 -0.25 -0.25" rpy="0 0 0"/>
            <geometry>
                <box size="0.8399245111497322 0.795341266304772 0.8537172142377708" />
            </geometry>
            <material name="Blue">
            <color rgba="0 0 1.0 1.0"/>
            </material>
        </visual>
        <collision>
            <origin xyz="0 -0.25 -0.25" rpy="0 0 0"/>
            <geometry>
                <box size="0.8399245111497322 0.795341266304772 0.8537172142377708" />
            </geometry>
        </collision>
    </link>
    <joint name="RightLink0_RightLink1" type="revolute">
       <parent link="RightLink0"/>
       <child  link="ightLink1"/>
       <origin rpy="0 0 0" xyz="0 0.5 0" />
     <axis xyz="1 1 0"/>
       <limit effort="0.0" lower="-3.14159" upper="3.14159" velocity="0.0"/>
    </joint>
    <joint name="RightLink1_RightLink2" type="revolute">
       <parent link="RightLink1"/>
       <child  link="ightLink2"/>
       <origin rpy="0 0 0" xyz="0 0.5 0" />
     <axis xyz="1 1 0"/>
       <limit effort="0.0" lower="-3.14159" upper="3.14159" velocity="0.0"/>
    </joint>
    <joint name="RightLink2_RightLink3" type="revolute">
       <parent link="RightLink2"/>
       <child  link="ightLink3"/>
       <origin rpy="0 0 0" xyz="0 0.5 0" />
     <axis xyz="1 1 0"/>
       <limit effort="0.0" lower="-3.14159" upper="3.14159" velocity="0.0"/>
    </joint>
    <joint name="RightLink3_RightLink4" type="revolute">
       <parent link="RightLink3"/>
       <child  link="ightLink4"/>
       <origin rpy="0 0 0" xyz="0 0.5 0" />
     <axis xyz="1 1 0"/>
       <limit effort="0.0" lower="-3.14159" upper="3.14159" velocity="0.0"/>
    </joint>
    <joint name="RightLink4_RightLink5" type="revolute">
       <parent link="RightLink4"/>
       <child  link="ightLink5"/>
       <origin rpy="0 0 0" xyz="0 0.5 0" />
     <axis xyz="1 1 0"/>
       <limit effort="0.0" lower="-3.14159" upper="3.14159" velocity="0.0"/>
    </joint>
    <joint name="RightLink5_RightLink6" type="revolute">
       <parent link="RightLink5"/>
       <child  link="ightLink6"/>
       <origin rpy="0 0 0" xyz="0 0.5 0" />
     <axis xyz="1 1 0"/>
       <limit effort="0.0" lower="-3.14159" upper="3.14159" velocity="0.0"/>
    </joint>
    <joint name="RightLink6_RightLink7" type="revolute">
       <parent link="RightLink6"/>
       <child  link="ightLink7"/>
       <origin rpy="0 0 0" xyz="0 0.5 0" />
     <axis xyz="1 1 0"/>
       <limit effort="0.0" lower="-3.14159" upper="3.14159" velocity="0.0"/>
    </joint>
    <joint name="RightLink7_RightLink8" type="revolute">
       <parent link="RightLink7"/>
       <child  link="ightLink8"/>
       <origin rpy="0 0 0" xyz="0 0.5 0" />
     <axis xyz="1 1 0"/>
       <limit effort="0.0" lower="-3.14159" upper="3.14159" velocity="0.0"/>
    </joint>
    <joint name="RightLink8_RightLink9" type="revolute">
       <parent link="RightLink8"/>
       <child  link="ightLink9"/>
       <origin rpy="0 0 0" xyz="0 0.5 0" />
     <axis xyz="1 1 0"/>
       <limit effort="0.0" lower="-3.14159" upper="3.14159" velocity="0.0"/>
    </joint>
    <joint name="RightLink9_RightLink10" type="revolute">
       <parent link="RightLink9"/>
       <child  link="ightLink10"/>
       <origin rpy="0 0 0" xyz="0 0.5 0" />
     <axis xyz="1 1 0"/>
       <limit effort="0.0" lower="-3.14159" upper="3.14159" velocity="0.0"/>
    </joint>
</robot>