<robot name = "robot">
    <link name="Torso">
        <inertial>
            <origin xyz="0 2 10" rpy="0 0 0"/>
            <mass value="1" />
            <inertia ixx="100" ixy="0" ixz="0" iyy="100" iyz="0" izz="100" />
        </inertial>
        <visual>
            <origin xyz="0 2 10" rpy="0 0 0"/>
            <geometry>
                <box size="0.5 0.5 0.5" />
            </geometry>
            <material name="Blue">
            <color rgba="0 0 1.0 1.0"/>
            </material>
        </visual>
        <collision>
            <origin xyz="0 2 10" rpy="0 0 0"/>
            <geometry>
                <box size="0.5 0.5 0.5" />
            </geometry>
        </collision>
    </link>
    <joint name="Torso_Link0" type="revolute">
       <parent link="Torso"/>
       <child  link="Link0"/>
       <origin rpy="0 0 0" xyz="0 2.25 4.75" />
     <axis xyz="1 1 0"/>
       <limit effort="0.0" lower="-3.14159" upper="3.14159" velocity="0.0"/>
    </joint>
    <link name="LeftLink0">
        <inertial>
            <origin xyz="0 0.25 -0.25" rpy="0 0 0"/>
            <mass value="1" />
            <inertia ixx="100" ixy="0" ixz="0" iyy="100" iyz="0" izz="100" />
        </inertial>
        <visual>
            <origin xyz="0 0.25 -0.25" rpy="0 0 0"/>
            <geometry>
                <box size="0.6758111505934802 0.4043326982704415 0.5007347387398641" />
            </geometry>
            <material name="Blue">
            <color rgba="0 0 1.0 1.0"/>
            </material>
        </visual>
        <collision>
            <origin xyz="0 0.25 -0.25" rpy="0 0 0"/>
            <geometry>
                <box size="0.6758111505934802 0.4043326982704415 0.5007347387398641" />
            </geometry>
        </collision>
    </link>
    <link name="LeftLink1">
        <inertial>
            <origin xyz="0 0.25 -0.25" rpy="0 0 0"/>
            <mass value="1" />
            <inertia ixx="100" ixy="0" ixz="0" iyy="100" iyz="0" izz="100" />
        </inertial>
        <visual>
            <origin xyz="0 0.25 -0.25" rpy="0 0 0"/>
            <geometry>
                <box size="0.7657926160734788 0.13184358670242757 0.12131709457562234" />
            </geometry>
            <material name="Green">
            <color rgba="0 1.0 0 1.0"/>
            </material>
        </visual>
        <collision>
            <origin xyz="0 0.25 -0.25" rpy="0 0 0"/>
            <geometry>
                <box size="0.7657926160734788 0.13184358670242757 0.12131709457562234" />
            </geometry>
        </collision>
    </link>
    <link name="LeftLink2">
        <inertial>
            <origin xyz="0 0.25 -0.25" rpy="0 0 0"/>
            <mass value="1" />
            <inertia ixx="100" ixy="0" ixz="0" iyy="100" iyz="0" izz="100" />
        </inertial>
        <visual>
            <origin xyz="0 0.25 -0.25" rpy="0 0 0"/>
            <geometry>
                <box size="0.31086306249713036 0.5089521486547077 0.49818833740184665" />
            </geometry>
            <material name="Green">
            <color rgba="0 1.0 0 1.0"/>
            </material>
        </visual>
        <collision>
            <origin xyz="0 0.25 -0.25" rpy="0 0 0"/>
            <geometry>
                <box size="0.31086306249713036 0.5089521486547077 0.49818833740184665" />
            </geometry>
        </collision>
    </link>
    <link name="LeftLink3">
        <inertial>
            <origin xyz="0 0.25 -0.25" rpy="0 0 0"/>
            <mass value="1" />
            <inertia ixx="100" ixy="0" ixz="0" iyy="100" iyz="0" izz="100" />
        </inertial>
        <visual>
            <origin xyz="0 0.25 -0.25" rpy="0 0 0"/>
            <geometry>
                <box size="0.046745081059601845 0.34970774215511136 0.9361783244530244" />
            </geometry>
            <material name="Blue">
            <color rgba="0 0 1.0 1.0"/>
            </material>
        </visual>
        <collision>
            <origin xyz="0 0.25 -0.25" rpy="0 0 0"/>
            <geometry>
                <box size="0.046745081059601845 0.34970774215511136 0.9361783244530244" />
            </geometry>
        </collision>
    </link>
    <link name="LeftLink4">
        <inertial>
            <origin xyz="0 0.25 -0.25" rpy="0 0 0"/>
            <mass value="1" />
            <inertia ixx="100" ixy="0" ixz="0" iyy="100" iyz="0" izz="100" />
        </inertial>
        <visual>
            <origin xyz="0 0.25 -0.25" rpy="0 0 0"/>
            <geometry>
                <box size="0.813649496243857 0.9746350589125302 0.7004705959624002" />
            </geometry>
            <material name="Green">
            <color rgba="0 1.0 0 1.0"/>
            </material>
        </visual>
        <collision>
            <origin xyz="0 0.25 -0.25" rpy="0 0 0"/>
            <geometry>
                <box size="0.813649496243857 0.9746350589125302 0.7004705959624002" />
            </geometry>
        </collision>
    </link>
    <link name="LeftLink5">
        <inertial>
            <origin xyz="0 0.25 -0.25" rpy="0 0 0"/>
            <mass value="1" />
            <inertia ixx="100" ixy="0" ixz="0" iyy="100" iyz="0" izz="100" />
        </inertial>
        <visual>
            <origin xyz="0 0.25 -0.25" rpy="0 0 0"/>
            <geometry>
                <box size="0.7658875800092235 0.9753861114157342 0.16662103494302116" />
            </geometry>
            <material name="Green">
            <color rgba="0 1.0 0 1.0"/>
            </material>
        </visual>
        <collision>
            <origin xyz="0 0.25 -0.25" rpy="0 0 0"/>
            <geometry>
                <box size="0.7658875800092235 0.9753861114157342 0.16662103494302116" />
            </geometry>
        </collision>
    </link>
    <link name="LeftLink6">
        <inertial>
            <origin xyz="0 0.25 -0.25" rpy="0 0 0"/>
            <mass value="1" />
            <inertia ixx="100" ixy="0" ixz="0" iyy="100" iyz="0" izz="100" />
        </inertial>
        <visual>
            <origin xyz="0 0.25 -0.25" rpy="0 0 0"/>
            <geometry>
                <box size="0.8800184017737652 0.9812178753036117 0.23860746250271714" />
            </geometry>
            <material name="Blue">
            <color rgba="0 0 1.0 1.0"/>
            </material>
        </visual>
        <collision>
            <origin xyz="0 0.25 -0.25" rpy="0 0 0"/>
            <geometry>
                <box size="0.8800184017737652 0.9812178753036117 0.23860746250271714" />
            </geometry>
        </collision>
    </link>
    <link name="LeftLink7">
        <inertial>
            <origin xyz="0 0.25 -0.25" rpy="0 0 0"/>
            <mass value="1" />
            <inertia ixx="100" ixy="0" ixz="0" iyy="100" iyz="0" izz="100" />
        </inertial>
        <visual>
            <origin xyz="0 0.25 -0.25" rpy="0 0 0"/>
            <geometry>
                <box size="0.14124226965458497 0.8637794823920913 0.5937427616707075" />
            </geometry>
            <material name="Blue">
            <color rgba="0 0 1.0 1.0"/>
            </material>
        </visual>
        <collision>
            <origin xyz="0 0.25 -0.25" rpy="0 0 0"/>
            <geometry>
                <box size="0.14124226965458497 0.8637794823920913 0.5937427616707075" />
            </geometry>
        </collision>
    </link>
    <link name="LeftLink8">
        <inertial>
            <origin xyz="0 0.25 -0.25" rpy="0 0 0"/>
            <mass value="1" />
            <inertia ixx="100" ixy="0" ixz="0" iyy="100" iyz="0" izz="100" />
        </inertial>
        <visual>
            <origin xyz="0 0.25 -0.25" rpy="0 0 0"/>
            <geometry>
                <box size="0.8200447468242871 0.711412200169552 0.7961369119826208" />
            </geometry>
            <material name="Blue">
            <color rgba="0 0 1.0 1.0"/>
            </material>
        </visual>
        <collision>
            <origin xyz="0 0.25 -0.25" rpy="0 0 0"/>
            <geometry>
                <box size="0.8200447468242871 0.711412200169552 0.7961369119826208" />
            </geometry>
        </collision>
    </link>
    <link name="LeftLink9">
        <inertial>
            <origin xyz="0 0.25 -0.25" rpy="0 0 0"/>
            <mass value="1" />
            <inertia ixx="100" ixy="0" ixz="0" iyy="100" iyz="0" izz="100" />
        </inertial>
        <visual>
            <origin xyz="0 0.25 -0.25" rpy="0 0 0"/>
            <geometry>
                <box size="0.18301809495628463 0.4364497830236306 0.872697126162834" />
            </geometry>
            <material name="Blue">
            <color rgba="0 0 1.0 1.0"/>
            </material>
        </visual>
        <collision>
            <origin xyz="0 0.25 -0.25" rpy="0 0 0"/>
            <geometry>
                <box size="0.18301809495628463 0.4364497830236306 0.872697126162834" />
            </geometry>
        </collision>
    </link>
    <link name="LeftLink10">
        <inertial>
            <origin xyz="0 0.25 -0.25" rpy="0 0 0"/>
            <mass value="1" />
            <inertia ixx="100" ixy="0" ixz="0" iyy="100" iyz="0" izz="100" />
        </inertial>
        <visual>
            <origin xyz="0 0.25 -0.25" rpy="0 0 0"/>
            <geometry>
                <box size="0.2868838881852843 0.026872955395925713 0.08534544779641673" />
            </geometry>
            <material name="Blue">
            <color rgba="0 0 1.0 1.0"/>
            </material>
        </visual>
        <collision>
            <origin xyz="0 0.25 -0.25" rpy="0 0 0"/>
            <geometry>
                <box size="0.2868838881852843 0.026872955395925713 0.08534544779641673" />
            </geometry>
        </collision>
    </link>
    <joint name="LeftLink0_LeftLink1" type="revolute">
       <parent link="LeftLink0"/>
       <child  link="eftLink1"/>
       <origin rpy="0 0 0" xyz="0 0.5 0" />
     <axis xyz="1 1 0"/>
       <limit effort="0.0" lower="-3.14159" upper="3.14159" velocity="0.0"/>
    </joint>
    <joint name="LeftLink1_LeftLink2" type="revolute">
       <parent link="LeftLink1"/>
       <child  link="eftLink2"/>
       <origin rpy="0 0 0" xyz="0 0.5 0" />
     <axis xyz="1 1 0"/>
       <limit effort="0.0" lower="-3.14159" upper="3.14159" velocity="0.0"/>
    </joint>
    <joint name="LeftLink2_LeftLink3" type="revolute">
       <parent link="LeftLink2"/>
       <child  link="eftLink3"/>
       <origin rpy="0 0 0" xyz="0 0.5 0" />
     <axis xyz="1 1 0"/>
       <limit effort="0.0" lower="-3.14159" upper="3.14159" velocity="0.0"/>
    </joint>
    <joint name="LeftLink3_LeftLink4" type="revolute">
       <parent link="LeftLink3"/>
       <child  link="eftLink4"/>
       <origin rpy="0 0 0" xyz="0 0.5 0" />
     <axis xyz="1 1 0"/>
       <limit effort="0.0" lower="-3.14159" upper="3.14159" velocity="0.0"/>
    </joint>
    <joint name="LeftLink4_LeftLink5" type="revolute">
       <parent link="LeftLink4"/>
       <child  link="eftLink5"/>
       <origin rpy="0 0 0" xyz="0 0.5 0" />
     <axis xyz="1 1 0"/>
       <limit effort="0.0" lower="-3.14159" upper="3.14159" velocity="0.0"/>
    </joint>
    <joint name="LeftLink5_LeftLink6" type="revolute">
       <parent link="LeftLink5"/>
       <child  link="eftLink6"/>
       <origin rpy="0 0 0" xyz="0 0.5 0" />
     <axis xyz="1 1 0"/>
       <limit effort="0.0" lower="-3.14159" upper="3.14159" velocity="0.0"/>
    </joint>
    <joint name="LeftLink6_LeftLink7" type="revolute">
       <parent link="LeftLink6"/>
       <child  link="eftLink7"/>
       <origin rpy="0 0 0" xyz="0 0.5 0" />
     <axis xyz="1 1 0"/>
       <limit effort="0.0" lower="-3.14159" upper="3.14159" velocity="0.0"/>
    </joint>
    <joint name="LeftLink7_LeftLink8" type="revolute">
       <parent link="LeftLink7"/>
       <child  link="eftLink8"/>
       <origin rpy="0 0 0" xyz="0 0.5 0" />
     <axis xyz="1 1 0"/>
       <limit effort="0.0" lower="-3.14159" upper="3.14159" velocity="0.0"/>
    </joint>
    <joint name="LeftLink8_LeftLink9" type="revolute">
       <parent link="LeftLink8"/>
       <child  link="eftLink9"/>
       <origin rpy="0 0 0" xyz="0 0.5 0" />
     <axis xyz="1 1 0"/>
       <limit effort="0.0" lower="-3.14159" upper="3.14159" velocity="0.0"/>
    </joint>
    <joint name="LeftLink9_LeftLink10" type="revolute">
       <parent link="LeftLink9"/>
       <child  link="eftLink10"/>
       <origin rpy="0 0 0" xyz="0 0.5 0" />
     <axis xyz="1 1 0"/>
       <limit effort="0.0" lower="-3.14159" upper="3.14159" velocity="0.0"/>
    </joint>
    <link name="RightLink0">
        <inertial>
            <origin xyz="0 -0.25 -0.25" rpy="0 0 0"/>
            <mass value="1" />
            <inertia ixx="100" ixy="0" ixz="0" iyy="100" iyz="0" izz="100" />
        </inertial>
        <visual>
            <origin xyz="0 -0.25 -0.25" rpy="0 0 0"/>
            <geometry>
                <box size="0.6758111505934802 0.4043326982704415 0.5007347387398641" />
            </geometry>
            <material name="Blue">
            <color rgba="0 0 1.0 1.0"/>
            </material>
        </visual>
        <collision>
            <origin xyz="0 -0.25 -0.25" rpy="0 0 0"/>
            <geometry>
                <box size="0.6758111505934802 0.4043326982704415 0.5007347387398641" />
            </geometry>
        </collision>
    </link>
    <link name="RightLink1">
        <inertial>
            <origin xyz="0 -0.25 -0.25" rpy="0 0 0"/>
            <mass value="1" />
            <inertia ixx="100" ixy="0" ixz="0" iyy="100" iyz="0" izz="100" />
        </inertial>
        <visual>
            <origin xyz="0 -0.25 -0.25" rpy="0 0 0"/>
            <geometry>
                <box size="0.7657926160734788 0.13184358670242757 0.12131709457562234" />
            </geometry>
            <material name="Green">
            <color rgba="0 1.0 0 1.0"/>
            </material>
        </visual>
        <collision>
            <origin xyz="0 -0.25 -0.25" rpy="0 0 0"/>
            <geometry>
                <box size="0.7657926160734788 0.13184358670242757 0.12131709457562234" />
            </geometry>
        </collision>
    </link>
    <link name="RightLink2">
        <inertial>
            <origin xyz="0 -0.25 -0.25" rpy="0 0 0"/>
            <mass value="1" />
            <inertia ixx="100" ixy="0" ixz="0" iyy="100" iyz="0" izz="100" />
        </inertial>
        <visual>
            <origin xyz="0 -0.25 -0.25" rpy="0 0 0"/>
            <geometry>
                <box size="0.31086306249713036 0.5089521486547077 0.49818833740184665" />
            </geometry>
            <material name="Green">
            <color rgba="0 1.0 0 1.0"/>
            </material>
        </visual>
        <collision>
            <origin xyz="0 -0.25 -0.25" rpy="0 0 0"/>
            <geometry>
                <box size="0.31086306249713036 0.5089521486547077 0.49818833740184665" />
            </geometry>
        </collision>
    </link>
    <link name="RightLink3">
        <inertial>
            <origin xyz="0 -0.25 -0.25" rpy="0 0 0"/>
            <mass value="1" />
            <inertia ixx="100" ixy="0" ixz="0" iyy="100" iyz="0" izz="100" />
        </inertial>
        <visual>
            <origin xyz="0 -0.25 -0.25" rpy="0 0 0"/>
            <geometry>
                <box size="0.046745081059601845 0.34970774215511136 0.9361783244530244" />
            </geometry>
            <material name="Green">
            <color rgba="0 1.0 0 1.0"/>
            </material>
        </visual>
        <collision>
            <origin xyz="0 -0.25 -0.25" rpy="0 0 0"/>
            <geometry>
                <box size="0.046745081059601845 0.34970774215511136 0.9361783244530244" />
            </geometry>
        </collision>
    </link>
    <link name="RightLink4">
        <inertial>
            <origin xyz="0 -0.25 -0.25" rpy="0 0 0"/>
            <mass value="1" />
            <inertia ixx="100" ixy="0" ixz="0" iyy="100" iyz="0" izz="100" />
        </inertial>
        <visual>
            <origin xyz="0 -0.25 -0.25" rpy="0 0 0"/>
            <geometry>
                <box size="0.813649496243857 0.9746350589125302 0.7004705959624002" />
            </geometry>
            <material name="Blue">
            <color rgba="0 0 1.0 1.0"/>
            </material>
        </visual>
        <collision>
            <origin xyz="0 -0.25 -0.25" rpy="0 0 0"/>
            <geometry>
                <box size="0.813649496243857 0.9746350589125302 0.7004705959624002" />
            </geometry>
        </collision>
    </link>
    <link name="RightLink5">
        <inertial>
            <origin xyz="0 -0.25 -0.25" rpy="0 0 0"/>
            <mass value="1" />
            <inertia ixx="100" ixy="0" ixz="0" iyy="100" iyz="0" izz="100" />
        </inertial>
        <visual>
            <origin xyz="0 -0.25 -0.25" rpy="0 0 0"/>
            <geometry>
                <box size="0.7658875800092235 0.9753861114157342 0.16662103494302116" />
            </geometry>
            <material name="Blue">
            <color rgba="0 0 1.0 1.0"/>
            </material>
        </visual>
        <collision>
            <origin xyz="0 -0.25 -0.25" rpy="0 0 0"/>
            <geometry>
                <box size="0.7658875800092235 0.9753861114157342 0.16662103494302116" />
            </geometry>
        </collision>
    </link>
    <link name="RightLink6">
        <inertial>
            <origin xyz="0 -0.25 -0.25" rpy="0 0 0"/>
            <mass value="1" />
            <inertia ixx="100" ixy="0" ixz="0" iyy="100" iyz="0" izz="100" />
        </inertial>
        <visual>
            <origin xyz="0 -0.25 -0.25" rpy="0 0 0"/>
            <geometry>
                <box size="0.8800184017737652 0.9812178753036117 0.23860746250271714" />
            </geometry>
            <material name="Blue">
            <color rgba="0 0 1.0 1.0"/>
            </material>
        </visual>
        <collision>
            <origin xyz="0 -0.25 -0.25" rpy="0 0 0"/>
            <geometry>
                <box size="0.8800184017737652 0.9812178753036117 0.23860746250271714" />
            </geometry>
        </collision>
    </link>
    <link name="RightLink7">
        <inertial>
            <origin xyz="0 -0.25 -0.25" rpy="0 0 0"/>
            <mass value="1" />
            <inertia ixx="100" ixy="0" ixz="0" iyy="100" iyz="0" izz="100" />
        </inertial>
        <visual>
            <origin xyz="0 -0.25 -0.25" rpy="0 0 0"/>
            <geometry>
                <box size="0.14124226965458497 0.8637794823920913 0.5937427616707075" />
            </geometry>
            <material name="Green">
            <color rgba="0 1.0 0 1.0"/>
            </material>
        </visual>
        <collision>
            <origin xyz="0 -0.25 -0.25" rpy="0 0 0"/>
            <geometry>
                <box size="0.14124226965458497 0.8637794823920913 0.5937427616707075" />
            </geometry>
        </collision>
    </link>
    <link name="RightLink8">
        <inertial>
            <origin xyz="0 -0.25 -0.25" rpy="0 0 0"/>
            <mass value="1" />
            <inertia ixx="100" ixy="0" ixz="0" iyy="100" iyz="0" izz="100" />
        </inertial>
        <visual>
            <origin xyz="0 -0.25 -0.25" rpy="0 0 0"/>
            <geometry>
                <box size="0.8200447468242871 0.711412200169552 0.7961369119826208" />
            </geometry>
            <material name="Blue">
            <color rgba="0 0 1.0 1.0"/>
            </material>
        </visual>
        <collision>
            <origin xyz="0 -0.25 -0.25" rpy="0 0 0"/>
            <geometry>
                <box size="0.8200447468242871 0.711412200169552 0.7961369119826208" />
            </geometry>
        </collision>
    </link>
    <link name="RightLink9">
        <inertial>
            <origin xyz="0 -0.25 -0.25" rpy="0 0 0"/>
            <mass value="1" />
            <inertia ixx="100" ixy="0" ixz="0" iyy="100" iyz="0" izz="100" />
        </inertial>
        <visual>
            <origin xyz="0 -0.25 -0.25" rpy="0 0 0"/>
            <geometry>
                <box size="0.18301809495628463 0.4364497830236306 0.872697126162834" />
            </geometry>
            <material name="Blue">
            <color rgba="0 0 1.0 1.0"/>
            </material>
        </visual>
        <collision>
            <origin xyz="0 -0.25 -0.25" rpy="0 0 0"/>
            <geometry>
                <box size="0.18301809495628463 0.4364497830236306 0.872697126162834" />
            </geometry>
        </collision>
    </link>
    <link name="RightLink10">
        <inertial>
            <origin xyz="0 -0.25 -0.25" rpy="0 0 0"/>
            <mass value="1" />
            <inertia ixx="100" ixy="0" ixz="0" iyy="100" iyz="0" izz="100" />
        </inertial>
        <visual>
            <origin xyz="0 -0.25 -0.25" rpy="0 0 0"/>
            <geometry>
                <box size="0.2868838881852843 0.026872955395925713 0.08534544779641673" />
            </geometry>
            <material name="Blue">
            <color rgba="0 0 1.0 1.0"/>
            </material>
        </visual>
        <collision>
            <origin xyz="0 -0.25 -0.25" rpy="0 0 0"/>
            <geometry>
                <box size="0.2868838881852843 0.026872955395925713 0.08534544779641673" />
            </geometry>
        </collision>
    </link>
    <joint name="RightLink0_RightLink1" type="revolute">
       <parent link="RightLink0"/>
       <child  link="ightLink1"/>
       <origin rpy="0 0 0" xyz="0 0.5 0" />
     <axis xyz="1 1 0"/>
       <limit effort="0.0" lower="-3.14159" upper="3.14159" velocity="0.0"/>
    </joint>
    <joint name="RightLink1_RightLink2" type="revolute">
       <parent link="RightLink1"/>
       <child  link="ightLink2"/>
       <origin rpy="0 0 0" xyz="0 0.5 0" />
     <axis xyz="1 1 0"/>
       <limit effort="0.0" lower="-3.14159" upper="3.14159" velocity="0.0"/>
    </joint>
    <joint name="RightLink2_RightLink3" type="revolute">
       <parent link="RightLink2"/>
       <child  link="ightLink3"/>
       <origin rpy="0 0 0" xyz="0 0.5 0" />
     <axis xyz="1 1 0"/>
       <limit effort="0.0" lower="-3.14159" upper="3.14159" velocity="0.0"/>
    </joint>
    <joint name="RightLink3_RightLink4" type="revolute">
       <parent link="RightLink3"/>
       <child  link="ightLink4"/>
       <origin rpy="0 0 0" xyz="0 0.5 0" />
     <axis xyz="1 1 0"/>
       <limit effort="0.0" lower="-3.14159" upper="3.14159" velocity="0.0"/>
    </joint>
    <joint name="RightLink4_RightLink5" type="revolute">
       <parent link="RightLink4"/>
       <child  link="ightLink5"/>
       <origin rpy="0 0 0" xyz="0 0.5 0" />
     <axis xyz="1 1 0"/>
       <limit effort="0.0" lower="-3.14159" upper="3.14159" velocity="0.0"/>
    </joint>
    <joint name="RightLink5_RightLink6" type="revolute">
       <parent link="RightLink5"/>
       <child  link="ightLink6"/>
       <origin rpy="0 0 0" xyz="0 0.5 0" />
     <axis xyz="1 1 0"/>
       <limit effort="0.0" lower="-3.14159" upper="3.14159" velocity="0.0"/>
    </joint>
    <joint name="RightLink6_RightLink7" type="revolute">
       <parent link="RightLink6"/>
       <child  link="ightLink7"/>
       <origin rpy="0 0 0" xyz="0 0.5 0" />
     <axis xyz="1 1 0"/>
       <limit effort="0.0" lower="-3.14159" upper="3.14159" velocity="0.0"/>
    </joint>
    <joint name="RightLink7_RightLink8" type="revolute">
       <parent link="RightLink7"/>
       <child  link="ightLink8"/>
       <origin rpy="0 0 0" xyz="0 0.5 0" />
     <axis xyz="1 1 0"/>
       <limit effort="0.0" lower="-3.14159" upper="3.14159" velocity="0.0"/>
    </joint>
    <joint name="RightLink8_RightLink9" type="revolute">
       <parent link="RightLink8"/>
       <child  link="ightLink9"/>
       <origin rpy="0 0 0" xyz="0 0.5 0" />
     <axis xyz="1 1 0"/>
       <limit effort="0.0" lower="-3.14159" upper="3.14159" velocity="0.0"/>
    </joint>
    <joint name="RightLink9_RightLink10" type="revolute">
       <parent link="RightLink9"/>
       <child  link="ightLink10"/>
       <origin rpy="0 0 0" xyz="0 0.5 0" />
     <axis xyz="1 1 0"/>
       <limit effort="0.0" lower="-3.14159" upper="3.14159" velocity="0.0"/>
    </joint>
</robot>