<robot name = "robot">
    <link name="Torso">
        <inertial>
            <origin xyz="0 2 10" rpy="0 0 0"/>
            <mass value="1" />
            <inertia ixx="100" ixy="0" ixz="0" iyy="100" iyz="0" izz="100" />
        </inertial>
        <visual>
            <origin xyz="0 2 10" rpy="0 0 0"/>
            <geometry>
                <box size="0.5 0.5 0.5" />
            </geometry>
            <material name="Red">
            <color rgba="1.0 0 0 1.0"/>
            </material>
        </visual>
        <collision>
            <origin xyz="0 2 10" rpy="0 0 0"/>
            <geometry>
                <box size="0.5 0.5 0.5" />
            </geometry>
        </collision>
    </link>
    <link name="0Link0">
        <inertial>
            <origin xyz="0 0 -0.5" rpy="0 0 0"/>
            <mass value="1" />
            <inertia ixx="100" ixy="0" ixz="0" iyy="100" iyz="0" izz="100" />
        </inertial>
        <visual>
            <origin xyz="0 0 -0.5" rpy="0 0 0"/>
            <geometry>
                <box size="0.9526084856470317 0.857823789220692 0.9109969765779635" />
            </geometry>
            <material name="Green">
            <color rgba="0 1.0 0 1.0"/>
            </material>
        </visual>
        <collision>
            <origin xyz="0 0 -0.5" rpy="0 0 0"/>
            <geometry>
                <box size="0.9526084856470317 0.857823789220692 0.9109969765779635" />
            </geometry>
        </collision>
    </link>
    <link name="0Link1">
        <inertial>
            <origin xyz="0 0 -0.5" rpy="0 0 0"/>
            <mass value="1" />
            <inertia ixx="100" ixy="0" ixz="0" iyy="100" iyz="0" izz="100" />
        </inertial>
        <visual>
            <origin xyz="0 0 -0.5" rpy="0 0 0"/>
            <geometry>
                <box size="0.5702651225969384 0.2969190194551019 0.3209942926973711" />
            </geometry>
            <material name="Blue">
            <color rgba="0 0 1.0 1.0"/>
            </material>
        </visual>
        <collision>
            <origin xyz="0 0 -0.5" rpy="0 0 0"/>
            <geometry>
                <box size="0.5702651225969384 0.2969190194551019 0.3209942926973711" />
            </geometry>
        </collision>
    </link>
    <link name="0Link2">
        <inertial>
            <origin xyz="0 0 -0.5" rpy="0 0 0"/>
            <mass value="1" />
            <inertia ixx="100" ixy="0" ixz="0" iyy="100" iyz="0" izz="100" />
        </inertial>
        <visual>
            <origin xyz="0 0 -0.5" rpy="0 0 0"/>
            <geometry>
                <box size="0.9561647977753285 0.40102610761719315 0.5918012709038877" />
            </geometry>
            <material name="Green">
            <color rgba="0 1.0 0 1.0"/>
            </material>
        </visual>
        <collision>
            <origin xyz="0 0 -0.5" rpy="0 0 0"/>
            <geometry>
                <box size="0.9561647977753285 0.40102610761719315 0.5918012709038877" />
            </geometry>
        </collision>
    </link>
    <link name="0Link3">
        <inertial>
            <origin xyz="0 0 -0.5" rpy="0 0 0"/>
            <mass value="1" />
            <inertia ixx="100" ixy="0" ixz="0" iyy="100" iyz="0" izz="100" />
        </inertial>
        <visual>
            <origin xyz="0 0 -0.5" rpy="0 0 0"/>
            <geometry>
                <box size="0.007925722802325508 0.04927765919278437 0.7524821349549202" />
            </geometry>
            <material name="Green">
            <color rgba="0 1.0 0 1.0"/>
            </material>
        </visual>
        <collision>
            <origin xyz="0 0 -0.5" rpy="0 0 0"/>
            <geometry>
                <box size="0.007925722802325508 0.04927765919278437 0.7524821349549202" />
            </geometry>
        </collision>
    </link>
    <link name="0Link4">
        <inertial>
            <origin xyz="0 0 -0.5" rpy="0 0 0"/>
            <mass value="1" />
            <inertia ixx="100" ixy="0" ixz="0" iyy="100" iyz="0" izz="100" />
        </inertial>
        <visual>
            <origin xyz="0 0 -0.5" rpy="0 0 0"/>
            <geometry>
                <box size="0.5029987335840149 0.6839465273442776 0.6719478653798212" />
            </geometry>
            <material name="Green">
            <color rgba="0 1.0 0 1.0"/>
            </material>
        </visual>
        <collision>
            <origin xyz="0 0 -0.5" rpy="0 0 0"/>
            <geometry>
                <box size="0.5029987335840149 0.6839465273442776 0.6719478653798212" />
            </geometry>
        </collision>
    </link>
    <link name="0Link5">
        <inertial>
            <origin xyz="0 0 -0.5" rpy="0 0 0"/>
            <mass value="1" />
            <inertia ixx="100" ixy="0" ixz="0" iyy="100" iyz="0" izz="100" />
        </inertial>
        <visual>
            <origin xyz="0 0 -0.5" rpy="0 0 0"/>
            <geometry>
                <box size="0.09495811390634612 0.702045296932598 0.015636059049412232" />
            </geometry>
            <material name="Blue">
            <color rgba="0 0 1.0 1.0"/>
            </material>
        </visual>
        <collision>
            <origin xyz="0 0 -0.5" rpy="0 0 0"/>
            <geometry>
                <box size="0.09495811390634612 0.702045296932598 0.015636059049412232" />
            </geometry>
        </collision>
    </link>
    <link name="0Link6">
        <inertial>
            <origin xyz="0 0 -0.5" rpy="0 0 0"/>
            <mass value="1" />
            <inertia ixx="100" ixy="0" ixz="0" iyy="100" iyz="0" izz="100" />
        </inertial>
        <visual>
            <origin xyz="0 0 -0.5" rpy="0 0 0"/>
            <geometry>
                <box size="0.4662680732016795 0.4237880458058878 0.35775744447962843" />
            </geometry>
            <material name="Blue">
            <color rgba="0 0 1.0 1.0"/>
            </material>
        </visual>
        <collision>
            <origin xyz="0 0 -0.5" rpy="0 0 0"/>
            <geometry>
                <box size="0.4662680732016795 0.4237880458058878 0.35775744447962843" />
            </geometry>
        </collision>
    </link>
    <link name="0Link7">
        <inertial>
            <origin xyz="0 0 -0.5" rpy="0 0 0"/>
            <mass value="1" />
            <inertia ixx="100" ixy="0" ixz="0" iyy="100" iyz="0" izz="100" />
        </inertial>
        <visual>
            <origin xyz="0 0 -0.5" rpy="0 0 0"/>
            <geometry>
                <box size="0.07577637993617847 0.6117621938385724 0.12841411752476428" />
            </geometry>
            <material name="Blue">
            <color rgba="0 0 1.0 1.0"/>
            </material>
        </visual>
        <collision>
            <origin xyz="0 0 -0.5" rpy="0 0 0"/>
            <geometry>
                <box size="0.07577637993617847 0.6117621938385724 0.12841411752476428" />
            </geometry>
        </collision>
    </link>
    <link name="0Link8">
        <inertial>
            <origin xyz="0 0 -0.5" rpy="0 0 0"/>
            <mass value="1" />
            <inertia ixx="100" ixy="0" ixz="0" iyy="100" iyz="0" izz="100" />
        </inertial>
        <visual>
            <origin xyz="0 0 -0.5" rpy="0 0 0"/>
            <geometry>
                <box size="0.09355773874230289 0.30268635494142815 0.07831788699152964" />
            </geometry>
            <material name="Blue">
            <color rgba="0 0 1.0 1.0"/>
            </material>
        </visual>
        <collision>
            <origin xyz="0 0 -0.5" rpy="0 0 0"/>
            <geometry>
                <box size="0.09355773874230289 0.30268635494142815 0.07831788699152964" />
            </geometry>
        </collision>
    </link>
    <link name="0Link9">
        <inertial>
            <origin xyz="0 0 -0.5" rpy="0 0 0"/>
            <mass value="1" />
            <inertia ixx="100" ixy="0" ixz="0" iyy="100" iyz="0" izz="100" />
        </inertial>
        <visual>
            <origin xyz="0 0 -0.5" rpy="0 0 0"/>
            <geometry>
                <box size="0.7187327876964006 0.09975169481593527 0.6533306808545373" />
            </geometry>
            <material name="Blue">
            <color rgba="0 0 1.0 1.0"/>
            </material>
        </visual>
        <collision>
            <origin xyz="0 0 -0.5" rpy="0 0 0"/>
            <geometry>
                <box size="0.7187327876964006 0.09975169481593527 0.6533306808545373" />
            </geometry>
        </collision>
    </link>
    <link name="0Link10">
        <inertial>
            <origin xyz="0 0 -0.5" rpy="0 0 0"/>
            <mass value="1" />
            <inertia ixx="100" ixy="0" ixz="0" iyy="100" iyz="0" izz="100" />
        </inertial>
        <visual>
            <origin xyz="0 0 -0.5" rpy="0 0 0"/>
            <geometry>
                <box size="0.15629635637716488 0.06784355195729397 0.16654174878801575" />
            </geometry>
            <material name="Blue">
            <color rgba="0 0 1.0 1.0"/>
            </material>
        </visual>
        <collision>
            <origin xyz="0 0 -0.5" rpy="0 0 0"/>
            <geometry>
                <box size="0.15629635637716488 0.06784355195729397 0.16654174878801575" />
            </geometry>
        </collision>
    </link>
    <link name="0Link11">
        <inertial>
            <origin xyz="0 0 -0.5" rpy="0 0 0"/>
            <mass value="1" />
            <inertia ixx="100" ixy="0" ixz="0" iyy="100" iyz="0" izz="100" />
        </inertial>
        <visual>
            <origin xyz="0 0 -0.5" rpy="0 0 0"/>
            <geometry>
                <box size="0.2301322302544988 0.7211286907999914 0.618042574081211" />
            </geometry>
            <material name="Blue">
            <color rgba="0 0 1.0 1.0"/>
            </material>
        </visual>
        <collision>
            <origin xyz="0 0 -0.5" rpy="0 0 0"/>
            <geometry>
                <box size="0.2301322302544988 0.7211286907999914 0.618042574081211" />
            </geometry>
        </collision>
    </link>
    <link name="0Link12">
        <inertial>
            <origin xyz="0 0 -0.5" rpy="0 0 0"/>
            <mass value="1" />
            <inertia ixx="100" ixy="0" ixz="0" iyy="100" iyz="0" izz="100" />
        </inertial>
        <visual>
            <origin xyz="0 0 -0.5" rpy="0 0 0"/>
            <geometry>
                <box size="0.9566610826822173 0.7003009325986544 0.5358773636590153" />
            </geometry>
            <material name="Blue">
            <color rgba="0 0 1.0 1.0"/>
            </material>
        </visual>
        <collision>
            <origin xyz="0 0 -0.5" rpy="0 0 0"/>
            <geometry>
                <box size="0.9566610826822173 0.7003009325986544 0.5358773636590153" />
            </geometry>
        </collision>
    </link>
    <link name="0Link13">
        <inertial>
            <origin xyz="0 0 -0.5" rpy="0 0 0"/>
            <mass value="1" />
            <inertia ixx="100" ixy="0" ixz="0" iyy="100" iyz="0" izz="100" />
        </inertial>
        <visual>
            <origin xyz="0 0 -0.5" rpy="0 0 0"/>
            <geometry>
                <box size="0.2647853339593573 0.6048753489914247 0.30284738073346484" />
            </geometry>
            <material name="Blue">
            <color rgba="0 0 1.0 1.0"/>
            </material>
        </visual>
        <collision>
            <origin xyz="0 0 -0.5" rpy="0 0 0"/>
            <geometry>
                <box size="0.2647853339593573 0.6048753489914247 0.30284738073346484" />
            </geometry>
        </collision>
    </link>
    <link name="0Link14">
        <inertial>
            <origin xyz="0 0 -0.5" rpy="0 0 0"/>
            <mass value="1" />
            <inertia ixx="100" ixy="0" ixz="0" iyy="100" iyz="0" izz="100" />
        </inertial>
        <visual>
            <origin xyz="0 0 -0.5" rpy="0 0 0"/>
            <geometry>
                <box size="0.04705018607613498 0.41805156645969765 0.5275875957564469" />
            </geometry>
            <material name="Blue">
            <color rgba="0 0 1.0 1.0"/>
            </material>
        </visual>
        <collision>
            <origin xyz="0 0 -0.5" rpy="0 0 0"/>
            <geometry>
                <box size="0.04705018607613498 0.41805156645969765 0.5275875957564469" />
            </geometry>
        </collision>
    </link>
    <link name="0Link15">
        <inertial>
            <origin xyz="0 0 -0.5" rpy="0 0 0"/>
            <mass value="1" />
            <inertia ixx="100" ixy="0" ixz="0" iyy="100" iyz="0" izz="100" />
        </inertial>
        <visual>
            <origin xyz="0 0 -0.5" rpy="0 0 0"/>
            <geometry>
                <box size="0.1512919248503144 0.33344561706960596 0.6610549306428979" />
            </geometry>
            <material name="Blue">
            <color rgba="0 0 1.0 1.0"/>
            </material>
        </visual>
        <collision>
            <origin xyz="0 0 -0.5" rpy="0 0 0"/>
            <geometry>
                <box size="0.1512919248503144 0.33344561706960596 0.6610549306428979" />
            </geometry>
        </collision>
    </link>
    <link name="0Link16">
        <inertial>
            <origin xyz="0 0 -0.5" rpy="0 0 0"/>
            <mass value="1" />
            <inertia ixx="100" ixy="0" ixz="0" iyy="100" iyz="0" izz="100" />
        </inertial>
        <visual>
            <origin xyz="0 0 -0.5" rpy="0 0 0"/>
            <geometry>
                <box size="0.12413599875686221 0.9711510185430606 0.3580913729420746" />
            </geometry>
            <material name="Blue">
            <color rgba="0 0 1.0 1.0"/>
            </material>
        </visual>
        <collision>
            <origin xyz="0 0 -0.5" rpy="0 0 0"/>
            <geometry>
                <box size="0.12413599875686221 0.9711510185430606 0.3580913729420746" />
            </geometry>
        </collision>
    </link>
    <joint name="Torso_0Link0" type="revolute">
       <parent link="Torso"/>
       <child  link="0Link0"/>
       <origin rpy="0 0 0" xyz="0.0 2.0 9.5" />
     <axis xyz="1 1 0"/>
       <limit effort="0.0" lower="-3.14159" upper="3.14159" velocity="0.0"/>
    </joint>
    <joint name="0Link0_0Link1" type="revolute">
       <parent link="0Link0"/>
       <child  link="0Link1"/>
       <origin rpy="0 0 0" xyz="0 0 -0.5" />
     <axis xyz="1 1 0"/>
       <limit effort="0.0" lower="-3.14159" upper="3.14159" velocity="0.0"/>
    </joint>
    <joint name="0Link1_0Link2" type="revolute">
       <parent link="0Link1"/>
       <child  link="0Link2"/>
       <origin rpy="0 0 0" xyz="0 0 -0.5" />
     <axis xyz="1 1 0"/>
       <limit effort="0.0" lower="-3.14159" upper="3.14159" velocity="0.0"/>
    </joint>
    <joint name="0Link2_0Link3" type="revolute">
       <parent link="0Link2"/>
       <child  link="0Link3"/>
       <origin rpy="0 0 0" xyz="0 0 -0.5" />
     <axis xyz="1 1 0"/>
       <limit effort="0.0" lower="-3.14159" upper="3.14159" velocity="0.0"/>
    </joint>
    <joint name="0Link3_0Link4" type="revolute">
       <parent link="0Link3"/>
       <child  link="0Link4"/>
       <origin rpy="0 0 0" xyz="0 0 -0.5" />
     <axis xyz="1 1 0"/>
       <limit effort="0.0" lower="-3.14159" upper="3.14159" velocity="0.0"/>
    </joint>
    <joint name="0Link4_0Link5" type="revolute">
       <parent link="0Link4"/>
       <child  link="0Link5"/>
       <origin rpy="0 0 0" xyz="0 0 -0.5" />
     <axis xyz="1 1 0"/>
       <limit effort="0.0" lower="-3.14159" upper="3.14159" velocity="0.0"/>
    </joint>
    <joint name="0Link5_0Link6" type="revolute">
       <parent link="0Link5"/>
       <child  link="0Link6"/>
       <origin rpy="0 0 0" xyz="0 0 -0.5" />
     <axis xyz="1 1 0"/>
       <limit effort="0.0" lower="-3.14159" upper="3.14159" velocity="0.0"/>
    </joint>
    <joint name="0Link6_0Link7" type="revolute">
       <parent link="0Link6"/>
       <child  link="0Link7"/>
       <origin rpy="0 0 0" xyz="0 0 -0.5" />
     <axis xyz="1 1 0"/>
       <limit effort="0.0" lower="-3.14159" upper="3.14159" velocity="0.0"/>
    </joint>
    <joint name="0Link7_0Link8" type="revolute">
       <parent link="0Link7"/>
       <child  link="0Link8"/>
       <origin rpy="0 0 0" xyz="0 0 -0.5" />
     <axis xyz="1 1 0"/>
       <limit effort="0.0" lower="-3.14159" upper="3.14159" velocity="0.0"/>
    </joint>
    <joint name="0Link8_0Link9" type="revolute">
       <parent link="0Link8"/>
       <child  link="0Link9"/>
       <origin rpy="0 0 0" xyz="0 0 -0.5" />
     <axis xyz="1 1 0"/>
       <limit effort="0.0" lower="-3.14159" upper="3.14159" velocity="0.0"/>
    </joint>
    <joint name="0Link9_0Link10" type="revolute">
       <parent link="0Link9"/>
       <child  link="0Link10"/>
       <origin rpy="0 0 0" xyz="0 0 -0.5" />
     <axis xyz="1 1 0"/>
       <limit effort="0.0" lower="-3.14159" upper="3.14159" velocity="0.0"/>
    </joint>
    <joint name="0Link10_0Link11" type="revolute">
       <parent link="0Link10"/>
       <child  link="0Link11"/>
       <origin rpy="0 0 0" xyz="0 0 -0.5" />
     <axis xyz="1 1 0"/>
       <limit effort="0.0" lower="-3.14159" upper="3.14159" velocity="0.0"/>
    </joint>
    <joint name="0Link11_0Link12" type="revolute">
       <parent link="0Link11"/>
       <child  link="0Link12"/>
       <origin rpy="0 0 0" xyz="0 0 -0.5" />
     <axis xyz="1 1 0"/>
       <limit effort="0.0" lower="-3.14159" upper="3.14159" velocity="0.0"/>
    </joint>
    <joint name="0Link12_0Link13" type="revolute">
       <parent link="0Link12"/>
       <child  link="0Link13"/>
       <origin rpy="0 0 0" xyz="0 0 -0.5" />
     <axis xyz="1 1 0"/>
       <limit effort="0.0" lower="-3.14159" upper="3.14159" velocity="0.0"/>
    </joint>
    <joint name="0Link13_0Link14" type="revolute">
       <parent link="0Link13"/>
       <child  link="0Link14"/>
       <origin rpy="0 0 0" xyz="0 0 -0.5" />
     <axis xyz="1 1 0"/>
       <limit effort="0.0" lower="-3.14159" upper="3.14159" velocity="0.0"/>
    </joint>
    <joint name="0Link14_0Link15" type="revolute">
       <parent link="0Link14"/>
       <child  link="0Link15"/>
       <origin rpy="0 0 0" xyz="0 0 -0.5" />
     <axis xyz="1 1 0"/>
       <limit effort="0.0" lower="-3.14159" upper="3.14159" velocity="0.0"/>
    </joint>
    <joint name="0Link15_0Link16" type="revolute">
       <parent link="0Link15"/>
       <child  link="0Link16"/>
       <origin rpy="0 0 0" xyz="0 0 -0.5" />
     <axis xyz="1 1 0"/>
       <limit effort="0.0" lower="-3.14159" upper="3.14159" velocity="0.0"/>
    </joint>
    <link name="1Link0">
        <inertial>
            <origin xyz="-0.5 0 0" rpy="0 0 0"/>
            <mass value="1" />
            <inertia ixx="100" ixy="0" ixz="0" iyy="100" iyz="0" izz="100" />
        </inertial>
        <visual>
            <origin xyz="-0.5 0 0" rpy="0 0 0"/>
            <geometry>
                <box size="0.2968610759151319 0.42684862921955047 0.9814308581461079" />
            </geometry>
            <material name="Blue">
            <color rgba="0 0 1.0 1.0"/>
            </material>
        </visual>
        <collision>
            <origin xyz="-0.5 0 0" rpy="0 0 0"/>
            <geometry>
                <box size="0.2968610759151319 0.42684862921955047 0.9814308581461079" />
            </geometry>
        </collision>
    </link>
    <link name="1Link1">
        <inertial>
            <origin xyz="-0.5 0 0" rpy="0 0 0"/>
            <mass value="1" />
            <inertia ixx="100" ixy="0" ixz="0" iyy="100" iyz="0" izz="100" />
        </inertial>
        <visual>
            <origin xyz="-0.5 0 0" rpy="0 0 0"/>
            <geometry>
                <box size="0.21961219163138557 0.7367811061451195 0.5311150222194219" />
            </geometry>
            <material name="Blue">
            <color rgba="0 0 1.0 1.0"/>
            </material>
        </visual>
        <collision>
            <origin xyz="-0.5 0 0" rpy="0 0 0"/>
            <geometry>
                <box size="0.21961219163138557 0.7367811061451195 0.5311150222194219" />
            </geometry>
        </collision>
    </link>
    <link name="1Link2">
        <inertial>
            <origin xyz="-0.5 0 0" rpy="0 0 0"/>
            <mass value="1" />
            <inertia ixx="100" ixy="0" ixz="0" iyy="100" iyz="0" izz="100" />
        </inertial>
        <visual>
            <origin xyz="-0.5 0 0" rpy="0 0 0"/>
            <geometry>
                <box size="0.5313915287942091 0.6936264271508602 0.1638603471704112" />
            </geometry>
            <material name="Blue">
            <color rgba="0 0 1.0 1.0"/>
            </material>
        </visual>
        <collision>
            <origin xyz="-0.5 0 0" rpy="0 0 0"/>
            <geometry>
                <box size="0.5313915287942091 0.6936264271508602 0.1638603471704112" />
            </geometry>
        </collision>
    </link>
    <link name="1Link3">
        <inertial>
            <origin xyz="-0.5 0 0" rpy="0 0 0"/>
            <mass value="1" />
            <inertia ixx="100" ixy="0" ixz="0" iyy="100" iyz="0" izz="100" />
        </inertial>
        <visual>
            <origin xyz="-0.5 0 0" rpy="0 0 0"/>
            <geometry>
                <box size="0.49760846149876203 0.04773639678385322 0.8150847144498399" />
            </geometry>
            <material name="Green">
            <color rgba="0 1.0 0 1.0"/>
            </material>
        </visual>
        <collision>
            <origin xyz="-0.5 0 0" rpy="0 0 0"/>
            <geometry>
                <box size="0.49760846149876203 0.04773639678385322 0.8150847144498399" />
            </geometry>
        </collision>
    </link>
    <link name="1Link4">
        <inertial>
            <origin xyz="-0.5 0 0" rpy="0 0 0"/>
            <mass value="1" />
            <inertia ixx="100" ixy="0" ixz="0" iyy="100" iyz="0" izz="100" />
        </inertial>
        <visual>
            <origin xyz="-0.5 0 0" rpy="0 0 0"/>
            <geometry>
                <box size="0.558578564787194 0.4811244331584438 0.038409778687265694" />
            </geometry>
            <material name="Blue">
            <color rgba="0 0 1.0 1.0"/>
            </material>
        </visual>
        <collision>
            <origin xyz="-0.5 0 0" rpy="0 0 0"/>
            <geometry>
                <box size="0.558578564787194 0.4811244331584438 0.038409778687265694" />
            </geometry>
        </collision>
    </link>
    <link name="1Link5">
        <inertial>
            <origin xyz="-0.5 0 0" rpy="0 0 0"/>
            <mass value="1" />
            <inertia ixx="100" ixy="0" ixz="0" iyy="100" iyz="0" izz="100" />
        </inertial>
        <visual>
            <origin xyz="-0.5 0 0" rpy="0 0 0"/>
            <geometry>
                <box size="0.2397944505707491 0.5717932329935865 0.8512684908481534" />
            </geometry>
            <material name="Blue">
            <color rgba="0 0 1.0 1.0"/>
            </material>
        </visual>
        <collision>
            <origin xyz="-0.5 0 0" rpy="0 0 0"/>
            <geometry>
                <box size="0.2397944505707491 0.5717932329935865 0.8512684908481534" />
            </geometry>
        </collision>
    </link>
    <link name="1Link6">
        <inertial>
            <origin xyz="-0.5 0 0" rpy="0 0 0"/>
            <mass value="1" />
            <inertia ixx="100" ixy="0" ixz="0" iyy="100" iyz="0" izz="100" />
        </inertial>
        <visual>
            <origin xyz="-0.5 0 0" rpy="0 0 0"/>
            <geometry>
                <box size="0.018636885301514527 0.712663558945338 0.33969241290824803" />
            </geometry>
            <material name="Green">
            <color rgba="0 1.0 0 1.0"/>
            </material>
        </visual>
        <collision>
            <origin xyz="-0.5 0 0" rpy="0 0 0"/>
            <geometry>
                <box size="0.018636885301514527 0.712663558945338 0.33969241290824803" />
            </geometry>
        </collision>
    </link>
    <link name="1Link7">
        <inertial>
            <origin xyz="-0.5 0 0" rpy="0 0 0"/>
            <mass value="1" />
            <inertia ixx="100" ixy="0" ixz="0" iyy="100" iyz="0" izz="100" />
        </inertial>
        <visual>
            <origin xyz="-0.5 0 0" rpy="0 0 0"/>
            <geometry>
                <box size="0.5567293264747872 0.680712297341224 0.5969863397432013" />
            </geometry>
            <material name="Green">
            <color rgba="0 1.0 0 1.0"/>
            </material>
        </visual>
        <collision>
            <origin xyz="-0.5 0 0" rpy="0 0 0"/>
            <geometry>
                <box size="0.5567293264747872 0.680712297341224 0.5969863397432013" />
            </geometry>
        </collision>
    </link>
    <link name="1Link8">
        <inertial>
            <origin xyz="-0.5 0 0" rpy="0 0 0"/>
            <mass value="1" />
            <inertia ixx="100" ixy="0" ixz="0" iyy="100" iyz="0" izz="100" />
        </inertial>
        <visual>
            <origin xyz="-0.5 0 0" rpy="0 0 0"/>
            <geometry>
                <box size="0.1185437145253565 0.45264249620780517 0.35835697807230404" />
            </geometry>
            <material name="Blue">
            <color rgba="0 0 1.0 1.0"/>
            </material>
        </visual>
        <collision>
            <origin xyz="-0.5 0 0" rpy="0 0 0"/>
            <geometry>
                <box size="0.1185437145253565 0.45264249620780517 0.35835697807230404" />
            </geometry>
        </collision>
    </link>
    <link name="1Link9">
        <inertial>
            <origin xyz="-0.5 0 0" rpy="0 0 0"/>
            <mass value="1" />
            <inertia ixx="100" ixy="0" ixz="0" iyy="100" iyz="0" izz="100" />
        </inertial>
        <visual>
            <origin xyz="-0.5 0 0" rpy="0 0 0"/>
            <geometry>
                <box size="0.034108152849768425 0.24520433958940935 0.269728415292645" />
            </geometry>
            <material name="Green">
            <color rgba="0 1.0 0 1.0"/>
            </material>
        </visual>
        <collision>
            <origin xyz="-0.5 0 0" rpy="0 0 0"/>
            <geometry>
                <box size="0.034108152849768425 0.24520433958940935 0.269728415292645" />
            </geometry>
        </collision>
    </link>
    <link name="1Link10">
        <inertial>
            <origin xyz="-0.5 0 0" rpy="0 0 0"/>
            <mass value="1" />
            <inertia ixx="100" ixy="0" ixz="0" iyy="100" iyz="0" izz="100" />
        </inertial>
        <visual>
            <origin xyz="-0.5 0 0" rpy="0 0 0"/>
            <geometry>
                <box size="0.9780254262240613 0.8620866614665242 0.8439109155060915" />
            </geometry>
            <material name="Blue">
            <color rgba="0 0 1.0 1.0"/>
            </material>
        </visual>
        <collision>
            <origin xyz="-0.5 0 0" rpy="0 0 0"/>
            <geometry>
                <box size="0.9780254262240613 0.8620866614665242 0.8439109155060915" />
            </geometry>
        </collision>
    </link>
    <link name="1Link11">
        <inertial>
            <origin xyz="-0.5 0 0" rpy="0 0 0"/>
            <mass value="1" />
            <inertia ixx="100" ixy="0" ixz="0" iyy="100" iyz="0" izz="100" />
        </inertial>
        <visual>
            <origin xyz="-0.5 0 0" rpy="0 0 0"/>
            <geometry>
                <box size="0.19586086534238834 0.4676502110614217 0.9146416067377156" />
            </geometry>
            <material name="Blue">
            <color rgba="0 0 1.0 1.0"/>
            </material>
        </visual>
        <collision>
            <origin xyz="-0.5 0 0" rpy="0 0 0"/>
            <geometry>
                <box size="0.19586086534238834 0.4676502110614217 0.9146416067377156" />
            </geometry>
        </collision>
    </link>
    <link name="1Link12">
        <inertial>
            <origin xyz="-0.5 0 0" rpy="0 0 0"/>
            <mass value="1" />
            <inertia ixx="100" ixy="0" ixz="0" iyy="100" iyz="0" izz="100" />
        </inertial>
        <visual>
            <origin xyz="-0.5 0 0" rpy="0 0 0"/>
            <geometry>
                <box size="0.37966643711310655 0.04397798293005728 0.2228535333009578" />
            </geometry>
            <material name="Blue">
            <color rgba="0 0 1.0 1.0"/>
            </material>
        </visual>
        <collision>
            <origin xyz="-0.5 0 0" rpy="0 0 0"/>
            <geometry>
                <box size="0.37966643711310655 0.04397798293005728 0.2228535333009578" />
            </geometry>
        </collision>
    </link>
    <link name="1Link13">
        <inertial>
            <origin xyz="-0.5 0 0" rpy="0 0 0"/>
            <mass value="1" />
            <inertia ixx="100" ixy="0" ixz="0" iyy="100" iyz="0" izz="100" />
        </inertial>
        <visual>
            <origin xyz="-0.5 0 0" rpy="0 0 0"/>
            <geometry>
                <box size="0.37839274928103817 0.8623292639440193 0.8244462882156565" />
            </geometry>
            <material name="Blue">
            <color rgba="0 0 1.0 1.0"/>
            </material>
        </visual>
        <collision>
            <origin xyz="-0.5 0 0" rpy="0 0 0"/>
            <geometry>
                <box size="0.37839274928103817 0.8623292639440193 0.8244462882156565" />
            </geometry>
        </collision>
    </link>
    <joint name="Torso_1Link0" type="revolute">
       <parent link="Torso"/>
       <child  link="1Link0"/>
       <origin rpy="0 0 0" xyz="-0.5 2.0 10.0" />
     <axis xyz="1 1 0"/>
       <limit effort="0.0" lower="-3.14159" upper="3.14159" velocity="0.0"/>
    </joint>
    <joint name="1Link0_1Link1" type="revolute">
       <parent link="1Link0"/>
       <child  link="1Link1"/>
       <origin rpy="0 0 0" xyz="-0.5 0 0" />
     <axis xyz="1 1 0"/>
       <limit effort="0.0" lower="-3.14159" upper="3.14159" velocity="0.0"/>
    </joint>
    <joint name="1Link1_1Link2" type="revolute">
       <parent link="1Link1"/>
       <child  link="1Link2"/>
       <origin rpy="0 0 0" xyz="-0.5 0 0" />
     <axis xyz="1 1 0"/>
       <limit effort="0.0" lower="-3.14159" upper="3.14159" velocity="0.0"/>
    </joint>
    <joint name="1Link2_1Link3" type="revolute">
       <parent link="1Link2"/>
       <child  link="1Link3"/>
       <origin rpy="0 0 0" xyz="-0.5 0 0" />
     <axis xyz="1 1 0"/>
       <limit effort="0.0" lower="-3.14159" upper="3.14159" velocity="0.0"/>
    </joint>
    <joint name="1Link3_1Link4" type="revolute">
       <parent link="1Link3"/>
       <child  link="1Link4"/>
       <origin rpy="0 0 0" xyz="-0.5 0 0" />
     <axis xyz="1 1 0"/>
       <limit effort="0.0" lower="-3.14159" upper="3.14159" velocity="0.0"/>
    </joint>
    <joint name="1Link4_1Link5" type="revolute">
       <parent link="1Link4"/>
       <child  link="1Link5"/>
       <origin rpy="0 0 0" xyz="-0.5 0 0" />
     <axis xyz="1 1 0"/>
       <limit effort="0.0" lower="-3.14159" upper="3.14159" velocity="0.0"/>
    </joint>
    <joint name="1Link5_1Link6" type="revolute">
       <parent link="1Link5"/>
       <child  link="1Link6"/>
       <origin rpy="0 0 0" xyz="-0.5 0 0" />
     <axis xyz="1 1 0"/>
       <limit effort="0.0" lower="-3.14159" upper="3.14159" velocity="0.0"/>
    </joint>
    <joint name="1Link6_1Link7" type="revolute">
       <parent link="1Link6"/>
       <child  link="1Link7"/>
       <origin rpy="0 0 0" xyz="-0.5 0 0" />
     <axis xyz="1 1 0"/>
       <limit effort="0.0" lower="-3.14159" upper="3.14159" velocity="0.0"/>
    </joint>
    <joint name="1Link7_1Link8" type="revolute">
       <parent link="1Link7"/>
       <child  link="1Link8"/>
       <origin rpy="0 0 0" xyz="-0.5 0 0" />
     <axis xyz="1 1 0"/>
       <limit effort="0.0" lower="-3.14159" upper="3.14159" velocity="0.0"/>
    </joint>
    <joint name="1Link8_1Link9" type="revolute">
       <parent link="1Link8"/>
       <child  link="1Link9"/>
       <origin rpy="0 0 0" xyz="-0.5 0 0" />
     <axis xyz="1 1 0"/>
       <limit effort="0.0" lower="-3.14159" upper="3.14159" velocity="0.0"/>
    </joint>
    <joint name="1Link9_1Link10" type="revolute">
       <parent link="1Link9"/>
       <child  link="1Link10"/>
       <origin rpy="0 0 0" xyz="-0.5 0 0" />
     <axis xyz="1 1 0"/>
       <limit effort="0.0" lower="-3.14159" upper="3.14159" velocity="0.0"/>
    </joint>
    <joint name="1Link10_1Link11" type="revolute">
       <parent link="1Link10"/>
       <child  link="1Link11"/>
       <origin rpy="0 0 0" xyz="-0.5 0 0" />
     <axis xyz="1 1 0"/>
       <limit effort="0.0" lower="-3.14159" upper="3.14159" velocity="0.0"/>
    </joint>
    <joint name="1Link11_1Link12" type="revolute">
       <parent link="1Link11"/>
       <child  link="1Link12"/>
       <origin rpy="0 0 0" xyz="-0.5 0 0" />
     <axis xyz="1 1 0"/>
       <limit effort="0.0" lower="-3.14159" upper="3.14159" velocity="0.0"/>
    </joint>
    <joint name="1Link12_1Link13" type="revolute">
       <parent link="1Link12"/>
       <child  link="1Link13"/>
       <origin rpy="0 0 0" xyz="-0.5 0 0" />
     <axis xyz="1 1 0"/>
       <limit effort="0.0" lower="-3.14159" upper="3.14159" velocity="0.0"/>
    </joint>
    <link name="2Link0">
        <inertial>
            <origin xyz="0 0 0.5" rpy="0 0 0"/>
            <mass value="1" />
            <inertia ixx="100" ixy="0" ixz="0" iyy="100" iyz="0" izz="100" />
        </inertial>
        <visual>
            <origin xyz="0 0 0.5" rpy="0 0 0"/>
            <geometry>
                <box size="0.2969205175594043 0.403355366280455 0.7944034766236732" />
            </geometry>
            <material name="Blue">
            <color rgba="0 0 1.0 1.0"/>
            </material>
        </visual>
        <collision>
            <origin xyz="0 0 0.5" rpy="0 0 0"/>
            <geometry>
                <box size="0.2969205175594043 0.403355366280455 0.7944034766236732" />
            </geometry>
        </collision>
    </link>
    <link name="2Link1">
        <inertial>
            <origin xyz="0 0 0.5" rpy="0 0 0"/>
            <mass value="1" />
            <inertia ixx="100" ixy="0" ixz="0" iyy="100" iyz="0" izz="100" />
        </inertial>
        <visual>
            <origin xyz="0 0 0.5" rpy="0 0 0"/>
            <geometry>
                <box size="0.08944868005042605 0.6580178704806214 0.35613502058337676" />
            </geometry>
            <material name="Blue">
            <color rgba="0 0 1.0 1.0"/>
            </material>
        </visual>
        <collision>
            <origin xyz="0 0 0.5" rpy="0 0 0"/>
            <geometry>
                <box size="0.08944868005042605 0.6580178704806214 0.35613502058337676" />
            </geometry>
        </collision>
    </link>
    <link name="2Link2">
        <inertial>
            <origin xyz="0 0 0.5" rpy="0 0 0"/>
            <mass value="1" />
            <inertia ixx="100" ixy="0" ixz="0" iyy="100" iyz="0" izz="100" />
        </inertial>
        <visual>
            <origin xyz="0 0 0.5" rpy="0 0 0"/>
            <geometry>
                <box size="0.31419928513285755 0.7232559699970147 0.9435412283247877" />
            </geometry>
            <material name="Green">
            <color rgba="0 1.0 0 1.0"/>
            </material>
        </visual>
        <collision>
            <origin xyz="0 0 0.5" rpy="0 0 0"/>
            <geometry>
                <box size="0.31419928513285755 0.7232559699970147 0.9435412283247877" />
            </geometry>
        </collision>
    </link>
    <link name="2Link3">
        <inertial>
            <origin xyz="0 0 0.5" rpy="0 0 0"/>
            <mass value="1" />
            <inertia ixx="100" ixy="0" ixz="0" iyy="100" iyz="0" izz="100" />
        </inertial>
        <visual>
            <origin xyz="0 0 0.5" rpy="0 0 0"/>
            <geometry>
                <box size="0.9727221180071263 0.3162529521237918 0.7352712183796052" />
            </geometry>
            <material name="Green">
            <color rgba="0 1.0 0 1.0"/>
            </material>
        </visual>
        <collision>
            <origin xyz="0 0 0.5" rpy="0 0 0"/>
            <geometry>
                <box size="0.9727221180071263 0.3162529521237918 0.7352712183796052" />
            </geometry>
        </collision>
    </link>
    <link name="2Link4">
        <inertial>
            <origin xyz="0 0 0.5" rpy="0 0 0"/>
            <mass value="1" />
            <inertia ixx="100" ixy="0" ixz="0" iyy="100" iyz="0" izz="100" />
        </inertial>
        <visual>
            <origin xyz="0 0 0.5" rpy="0 0 0"/>
            <geometry>
                <box size="0.4071636491006084 0.9201790373080202 0.5212929840568531" />
            </geometry>
            <material name="Green">
            <color rgba="0 1.0 0 1.0"/>
            </material>
        </visual>
        <collision>
            <origin xyz="0 0 0.5" rpy="0 0 0"/>
            <geometry>
                <box size="0.4071636491006084 0.9201790373080202 0.5212929840568531" />
            </geometry>
        </collision>
    </link>
    <link name="2Link5">
        <inertial>
            <origin xyz="0 0 0.5" rpy="0 0 0"/>
            <mass value="1" />
            <inertia ixx="100" ixy="0" ixz="0" iyy="100" iyz="0" izz="100" />
        </inertial>
        <visual>
            <origin xyz="0 0 0.5" rpy="0 0 0"/>
            <geometry>
                <box size="0.9446462346412294 0.009267758064406717 0.43746298899893665" />
            </geometry>
            <material name="Blue">
            <color rgba="0 0 1.0 1.0"/>
            </material>
        </visual>
        <collision>
            <origin xyz="0 0 0.5" rpy="0 0 0"/>
            <geometry>
                <box size="0.9446462346412294 0.009267758064406717 0.43746298899893665" />
            </geometry>
        </collision>
    </link>
    <link name="2Link6">
        <inertial>
            <origin xyz="0 0 0.5" rpy="0 0 0"/>
            <mass value="1" />
            <inertia ixx="100" ixy="0" ixz="0" iyy="100" iyz="0" izz="100" />
        </inertial>
        <visual>
            <origin xyz="0 0 0.5" rpy="0 0 0"/>
            <geometry>
                <box size="0.4061860120665206 0.6378012671086278 0.06760472292880082" />
            </geometry>
            <material name="Blue">
            <color rgba="0 0 1.0 1.0"/>
            </material>
        </visual>
        <collision>
            <origin xyz="0 0 0.5" rpy="0 0 0"/>
            <geometry>
                <box size="0.4061860120665206 0.6378012671086278 0.06760472292880082" />
            </geometry>
        </collision>
    </link>
    <link name="2Link7">
        <inertial>
            <origin xyz="0 0 0.5" rpy="0 0 0"/>
            <mass value="1" />
            <inertia ixx="100" ixy="0" ixz="0" iyy="100" iyz="0" izz="100" />
        </inertial>
        <visual>
            <origin xyz="0 0 0.5" rpy="0 0 0"/>
            <geometry>
                <box size="0.82042758202129 0.8189115046699748 0.501774532288598" />
            </geometry>
            <material name="Blue">
            <color rgba="0 0 1.0 1.0"/>
            </material>
        </visual>
        <collision>
            <origin xyz="0 0 0.5" rpy="0 0 0"/>
            <geometry>
                <box size="0.82042758202129 0.8189115046699748 0.501774532288598" />
            </geometry>
        </collision>
    </link>
    <link name="2Link8">
        <inertial>
            <origin xyz="0 0 0.5" rpy="0 0 0"/>
            <mass value="1" />
            <inertia ixx="100" ixy="0" ixz="0" iyy="100" iyz="0" izz="100" />
        </inertial>
        <visual>
            <origin xyz="0 0 0.5" rpy="0 0 0"/>
            <geometry>
                <box size="0.06391262887232607 0.9525171683635443 0.22259012784128307" />
            </geometry>
            <material name="Blue">
            <color rgba="0 0 1.0 1.0"/>
            </material>
        </visual>
        <collision>
            <origin xyz="0 0 0.5" rpy="0 0 0"/>
            <geometry>
                <box size="0.06391262887232607 0.9525171683635443 0.22259012784128307" />
            </geometry>
        </collision>
    </link>
    <link name="2Link9">
        <inertial>
            <origin xyz="0 0 0.5" rpy="0 0 0"/>
            <mass value="1" />
            <inertia ixx="100" ixy="0" ixz="0" iyy="100" iyz="0" izz="100" />
        </inertial>
        <visual>
            <origin xyz="0 0 0.5" rpy="0 0 0"/>
            <geometry>
                <box size="0.9161681255833678 0.5253461092144237 0.012666419713111665" />
            </geometry>
            <material name="Green">
            <color rgba="0 1.0 0 1.0"/>
            </material>
        </visual>
        <collision>
            <origin xyz="0 0 0.5" rpy="0 0 0"/>
            <geometry>
                <box size="0.9161681255833678 0.5253461092144237 0.012666419713111665" />
            </geometry>
        </collision>
    </link>
    <link name="2Link10">
        <inertial>
            <origin xyz="0 0 0.5" rpy="0 0 0"/>
            <mass value="1" />
            <inertia ixx="100" ixy="0" ixz="0" iyy="100" iyz="0" izz="100" />
        </inertial>
        <visual>
            <origin xyz="0 0 0.5" rpy="0 0 0"/>
            <geometry>
                <box size="0.8101459050570706 0.36884670380932494 0.9866056600964334" />
            </geometry>
            <material name="Blue">
            <color rgba="0 0 1.0 1.0"/>
            </material>
        </visual>
        <collision>
            <origin xyz="0 0 0.5" rpy="0 0 0"/>
            <geometry>
                <box size="0.8101459050570706 0.36884670380932494 0.9866056600964334" />
            </geometry>
        </collision>
    </link>
    <link name="2Link11">
        <inertial>
            <origin xyz="0 0 0.5" rpy="0 0 0"/>
            <mass value="1" />
            <inertia ixx="100" ixy="0" ixz="0" iyy="100" iyz="0" izz="100" />
        </inertial>
        <visual>
            <origin xyz="0 0 0.5" rpy="0 0 0"/>
            <geometry>
                <box size="0.09261859599262479 0.6711801566041524 0.6361467906297125" />
            </geometry>
            <material name="Blue">
            <color rgba="0 0 1.0 1.0"/>
            </material>
        </visual>
        <collision>
            <origin xyz="0 0 0.5" rpy="0 0 0"/>
            <geometry>
                <box size="0.09261859599262479 0.6711801566041524 0.6361467906297125" />
            </geometry>
        </collision>
    </link>
    <link name="2Link12">
        <inertial>
            <origin xyz="0 0 0.5" rpy="0 0 0"/>
            <mass value="1" />
            <inertia ixx="100" ixy="0" ixz="0" iyy="100" iyz="0" izz="100" />
        </inertial>
        <visual>
            <origin xyz="0 0 0.5" rpy="0 0 0"/>
            <geometry>
                <box size="0.0029504597259258913 0.006212689504316082 0.12808952721842248" />
            </geometry>
            <material name="Blue">
            <color rgba="0 0 1.0 1.0"/>
            </material>
        </visual>
        <collision>
            <origin xyz="0 0 0.5" rpy="0 0 0"/>
            <geometry>
                <box size="0.0029504597259258913 0.006212689504316082 0.12808952721842248" />
            </geometry>
        </collision>
    </link>
    <link name="2Link13">
        <inertial>
            <origin xyz="0 0 0.5" rpy="0 0 0"/>
            <mass value="1" />
            <inertia ixx="100" ixy="0" ixz="0" iyy="100" iyz="0" izz="100" />
        </inertial>
        <visual>
            <origin xyz="0 0 0.5" rpy="0 0 0"/>
            <geometry>
                <box size="0.5782443255497006 0.4047548078622113 0.6616355604177938" />
            </geometry>
            <material name="Blue">
            <color rgba="0 0 1.0 1.0"/>
            </material>
        </visual>
        <collision>
            <origin xyz="0 0 0.5" rpy="0 0 0"/>
            <geometry>
                <box size="0.5782443255497006 0.4047548078622113 0.6616355604177938" />
            </geometry>
        </collision>
    </link>
    <link name="2Link14">
        <inertial>
            <origin xyz="0 0 0.5" rpy="0 0 0"/>
            <mass value="1" />
            <inertia ixx="100" ixy="0" ixz="0" iyy="100" iyz="0" izz="100" />
        </inertial>
        <visual>
            <origin xyz="0 0 0.5" rpy="0 0 0"/>
            <geometry>
                <box size="0.441025021112498 0.40184004684415386 0.4214990741486232" />
            </geometry>
            <material name="Blue">
            <color rgba="0 0 1.0 1.0"/>
            </material>
        </visual>
        <collision>
            <origin xyz="0 0 0.5" rpy="0 0 0"/>
            <geometry>
                <box size="0.441025021112498 0.40184004684415386 0.4214990741486232" />
            </geometry>
        </collision>
    </link>
    <link name="2Link15">
        <inertial>
            <origin xyz="0 0 0.5" rpy="0 0 0"/>
            <mass value="1" />
            <inertia ixx="100" ixy="0" ixz="0" iyy="100" iyz="0" izz="100" />
        </inertial>
        <visual>
            <origin xyz="0 0 0.5" rpy="0 0 0"/>
            <geometry>
                <box size="0.21901947997240112 0.5220825843197493 0.5784310791025122" />
            </geometry>
            <material name="Blue">
            <color rgba="0 0 1.0 1.0"/>
            </material>
        </visual>
        <collision>
            <origin xyz="0 0 0.5" rpy="0 0 0"/>
            <geometry>
                <box size="0.21901947997240112 0.5220825843197493 0.5784310791025122" />
            </geometry>
        </collision>
    </link>
    <joint name="Torso_2Link0" type="revolute">
       <parent link="Torso"/>
       <child  link="2Link0"/>
       <origin rpy="0 0 0" xyz="0.0 2.0 10.5" />
     <axis xyz="1 1 0"/>
       <limit effort="0.0" lower="-3.14159" upper="3.14159" velocity="0.0"/>
    </joint>
    <joint name="2Link0_2Link1" type="revolute">
       <parent link="2Link0"/>
       <child  link="2Link1"/>
       <origin rpy="0 0 0" xyz="0 0 0.5" />
     <axis xyz="1 1 0"/>
       <limit effort="0.0" lower="-3.14159" upper="3.14159" velocity="0.0"/>
    </joint>
    <joint name="2Link1_2Link2" type="revolute">
       <parent link="2Link1"/>
       <child  link="2Link2"/>
       <origin rpy="0 0 0" xyz="0 0 0.5" />
     <axis xyz="1 1 0"/>
       <limit effort="0.0" lower="-3.14159" upper="3.14159" velocity="0.0"/>
    </joint>
    <joint name="2Link2_2Link3" type="revolute">
       <parent link="2Link2"/>
       <child  link="2Link3"/>
       <origin rpy="0 0 0" xyz="0 0 0.5" />
     <axis xyz="1 1 0"/>
       <limit effort="0.0" lower="-3.14159" upper="3.14159" velocity="0.0"/>
    </joint>
    <joint name="2Link3_2Link4" type="revolute">
       <parent link="2Link3"/>
       <child  link="2Link4"/>
       <origin rpy="0 0 0" xyz="0 0 0.5" />
     <axis xyz="1 1 0"/>
       <limit effort="0.0" lower="-3.14159" upper="3.14159" velocity="0.0"/>
    </joint>
    <joint name="2Link4_2Link5" type="revolute">
       <parent link="2Link4"/>
       <child  link="2Link5"/>
       <origin rpy="0 0 0" xyz="0 0 0.5" />
     <axis xyz="1 1 0"/>
       <limit effort="0.0" lower="-3.14159" upper="3.14159" velocity="0.0"/>
    </joint>
    <joint name="2Link5_2Link6" type="revolute">
       <parent link="2Link5"/>
       <child  link="2Link6"/>
       <origin rpy="0 0 0" xyz="0 0 0.5" />
     <axis xyz="1 1 0"/>
       <limit effort="0.0" lower="-3.14159" upper="3.14159" velocity="0.0"/>
    </joint>
    <joint name="2Link6_2Link7" type="revolute">
       <parent link="2Link6"/>
       <child  link="2Link7"/>
       <origin rpy="0 0 0" xyz="0 0 0.5" />
     <axis xyz="1 1 0"/>
       <limit effort="0.0" lower="-3.14159" upper="3.14159" velocity="0.0"/>
    </joint>
    <joint name="2Link7_2Link8" type="revolute">
       <parent link="2Link7"/>
       <child  link="2Link8"/>
       <origin rpy="0 0 0" xyz="0 0 0.5" />
     <axis xyz="1 1 0"/>
       <limit effort="0.0" lower="-3.14159" upper="3.14159" velocity="0.0"/>
    </joint>
    <joint name="2Link8_2Link9" type="revolute">
       <parent link="2Link8"/>
       <child  link="2Link9"/>
       <origin rpy="0 0 0" xyz="0 0 0.5" />
     <axis xyz="1 1 0"/>
       <limit effort="0.0" lower="-3.14159" upper="3.14159" velocity="0.0"/>
    </joint>
    <joint name="2Link9_2Link10" type="revolute">
       <parent link="2Link9"/>
       <child  link="2Link10"/>
       <origin rpy="0 0 0" xyz="0 0 0.5" />
     <axis xyz="1 1 0"/>
       <limit effort="0.0" lower="-3.14159" upper="3.14159" velocity="0.0"/>
    </joint>
    <joint name="2Link10_2Link11" type="revolute">
       <parent link="2Link10"/>
       <child  link="2Link11"/>
       <origin rpy="0 0 0" xyz="0 0 0.5" />
     <axis xyz="1 1 0"/>
       <limit effort="0.0" lower="-3.14159" upper="3.14159" velocity="0.0"/>
    </joint>
    <joint name="2Link11_2Link12" type="revolute">
       <parent link="2Link11"/>
       <child  link="2Link12"/>
       <origin rpy="0 0 0" xyz="0 0 0.5" />
     <axis xyz="1 1 0"/>
       <limit effort="0.0" lower="-3.14159" upper="3.14159" velocity="0.0"/>
    </joint>
    <joint name="2Link12_2Link13" type="revolute">
       <parent link="2Link12"/>
       <child  link="2Link13"/>
       <origin rpy="0 0 0" xyz="0 0 0.5" />
     <axis xyz="1 1 0"/>
       <limit effort="0.0" lower="-3.14159" upper="3.14159" velocity="0.0"/>
    </joint>
    <joint name="2Link13_2Link14" type="revolute">
       <parent link="2Link13"/>
       <child  link="2Link14"/>
       <origin rpy="0 0 0" xyz="0 0 0.5" />
     <axis xyz="1 1 0"/>
       <limit effort="0.0" lower="-3.14159" upper="3.14159" velocity="0.0"/>
    </joint>
    <joint name="2Link14_2Link15" type="revolute">
       <parent link="2Link14"/>
       <child  link="2Link15"/>
       <origin rpy="0 0 0" xyz="0 0 0.5" />
     <axis xyz="1 1 0"/>
       <limit effort="0.0" lower="-3.14159" upper="3.14159" velocity="0.0"/>
    </joint>
    <link name="3Link0">
        <inertial>
            <origin xyz="0.5 0 0" rpy="0 0 0"/>
            <mass value="1" />
            <inertia ixx="100" ixy="0" ixz="0" iyy="100" iyz="0" izz="100" />
        </inertial>
        <visual>
            <origin xyz="0.5 0 0" rpy="0 0 0"/>
            <geometry>
                <box size="0.9489574487139847 0.7048289511707101 0.5767517639665383" />
            </geometry>
            <material name="Blue">
            <color rgba="0 0 1.0 1.0"/>
            </material>
        </visual>
        <collision>
            <origin xyz="0.5 0 0" rpy="0 0 0"/>
            <geometry>
                <box size="0.9489574487139847 0.7048289511707101 0.5767517639665383" />
            </geometry>
        </collision>
    </link>
    <link name="3Link1">
        <inertial>
            <origin xyz="0.5 0 0" rpy="0 0 0"/>
            <mass value="1" />
            <inertia ixx="100" ixy="0" ixz="0" iyy="100" iyz="0" izz="100" />
        </inertial>
        <visual>
            <origin xyz="0.5 0 0" rpy="0 0 0"/>
            <geometry>
                <box size="0.1240068720299018 0.7900319999552657 0.48065468689352353" />
            </geometry>
            <material name="Green">
            <color rgba="0 1.0 0 1.0"/>
            </material>
        </visual>
        <collision>
            <origin xyz="0.5 0 0" rpy="0 0 0"/>
            <geometry>
                <box size="0.1240068720299018 0.7900319999552657 0.48065468689352353" />
            </geometry>
        </collision>
    </link>
    <link name="3Link2">
        <inertial>
            <origin xyz="0.5 0 0" rpy="0 0 0"/>
            <mass value="1" />
            <inertia ixx="100" ixy="0" ixz="0" iyy="100" iyz="0" izz="100" />
        </inertial>
        <visual>
            <origin xyz="0.5 0 0" rpy="0 0 0"/>
            <geometry>
                <box size="0.8162156526326959 0.6583760856999763 0.8310459648076431" />
            </geometry>
            <material name="Blue">
            <color rgba="0 0 1.0 1.0"/>
            </material>
        </visual>
        <collision>
            <origin xyz="0.5 0 0" rpy="0 0 0"/>
            <geometry>
                <box size="0.8162156526326959 0.6583760856999763 0.8310459648076431" />
            </geometry>
        </collision>
    </link>
    <link name="3Link3">
        <inertial>
            <origin xyz="0.5 0 0" rpy="0 0 0"/>
            <mass value="1" />
            <inertia ixx="100" ixy="0" ixz="0" iyy="100" iyz="0" izz="100" />
        </inertial>
        <visual>
            <origin xyz="0.5 0 0" rpy="0 0 0"/>
            <geometry>
                <box size="0.4487522352171278 0.08971520201981764 0.37833044586113207" />
            </geometry>
            <material name="Blue">
            <color rgba="0 0 1.0 1.0"/>
            </material>
        </visual>
        <collision>
            <origin xyz="0.5 0 0" rpy="0 0 0"/>
            <geometry>
                <box size="0.4487522352171278 0.08971520201981764 0.37833044586113207" />
            </geometry>
        </collision>
    </link>
    <link name="3Link4">
        <inertial>
            <origin xyz="0.5 0 0" rpy="0 0 0"/>
            <mass value="1" />
            <inertia ixx="100" ixy="0" ixz="0" iyy="100" iyz="0" izz="100" />
        </inertial>
        <visual>
            <origin xyz="0.5 0 0" rpy="0 0 0"/>
            <geometry>
                <box size="0.18947453795776514 0.4543273650766876 0.07640551217627056" />
            </geometry>
            <material name="Blue">
            <color rgba="0 0 1.0 1.0"/>
            </material>
        </visual>
        <collision>
            <origin xyz="0.5 0 0" rpy="0 0 0"/>
            <geometry>
                <box size="0.18947453795776514 0.4543273650766876 0.07640551217627056" />
            </geometry>
        </collision>
    </link>
    <link name="3Link5">
        <inertial>
            <origin xyz="0.5 0 0" rpy="0 0 0"/>
            <mass value="1" />
            <inertia ixx="100" ixy="0" ixz="0" iyy="100" iyz="0" izz="100" />
        </inertial>
        <visual>
            <origin xyz="0.5 0 0" rpy="0 0 0"/>
            <geometry>
                <box size="0.5589178534560917 0.031183112250963263 0.9068047170316332" />
            </geometry>
            <material name="Blue">
            <color rgba="0 0 1.0 1.0"/>
            </material>
        </visual>
        <collision>
            <origin xyz="0.5 0 0" rpy="0 0 0"/>
            <geometry>
                <box size="0.5589178534560917 0.031183112250963263 0.9068047170316332" />
            </geometry>
        </collision>
    </link>
    <link name="3Link6">
        <inertial>
            <origin xyz="0.5 0 0" rpy="0 0 0"/>
            <mass value="1" />
            <inertia ixx="100" ixy="0" ixz="0" iyy="100" iyz="0" izz="100" />
        </inertial>
        <visual>
            <origin xyz="0.5 0 0" rpy="0 0 0"/>
            <geometry>
                <box size="0.12438054254669584 0.5228732939341357 0.7112032833974533" />
            </geometry>
            <material name="Blue">
            <color rgba="0 0 1.0 1.0"/>
            </material>
        </visual>
        <collision>
            <origin xyz="0.5 0 0" rpy="0 0 0"/>
            <geometry>
                <box size="0.12438054254669584 0.5228732939341357 0.7112032833974533" />
            </geometry>
        </collision>
    </link>
    <link name="3Link7">
        <inertial>
            <origin xyz="0.5 0 0" rpy="0 0 0"/>
            <mass value="1" />
            <inertia ixx="100" ixy="0" ixz="0" iyy="100" iyz="0" izz="100" />
        </inertial>
        <visual>
            <origin xyz="0.5 0 0" rpy="0 0 0"/>
            <geometry>
                <box size="0.9480456924693806 0.4538234601813955 0.8891416785829686" />
            </geometry>
            <material name="Green">
            <color rgba="0 1.0 0 1.0"/>
            </material>
        </visual>
        <collision>
            <origin xyz="0.5 0 0" rpy="0 0 0"/>
            <geometry>
                <box size="0.9480456924693806 0.4538234601813955 0.8891416785829686" />
            </geometry>
        </collision>
    </link>
    <link name="3Link8">
        <inertial>
            <origin xyz="0.5 0 0" rpy="0 0 0"/>
            <mass value="1" />
            <inertia ixx="100" ixy="0" ixz="0" iyy="100" iyz="0" izz="100" />
        </inertial>
        <visual>
            <origin xyz="0.5 0 0" rpy="0 0 0"/>
            <geometry>
                <box size="0.8780860999148932 0.7035154160620073 0.21090226321522398" />
            </geometry>
            <material name="Green">
            <color rgba="0 1.0 0 1.0"/>
            </material>
        </visual>
        <collision>
            <origin xyz="0.5 0 0" rpy="0 0 0"/>
            <geometry>
                <box size="0.8780860999148932 0.7035154160620073 0.21090226321522398" />
            </geometry>
        </collision>
    </link>
    <link name="3Link9">
        <inertial>
            <origin xyz="0.5 0 0" rpy="0 0 0"/>
            <mass value="1" />
            <inertia ixx="100" ixy="0" ixz="0" iyy="100" iyz="0" izz="100" />
        </inertial>
        <visual>
            <origin xyz="0.5 0 0" rpy="0 0 0"/>
            <geometry>
                <box size="0.2512969004498866 0.9808390304789087 0.2794385627371576" />
            </geometry>
            <material name="Green">
            <color rgba="0 1.0 0 1.0"/>
            </material>
        </visual>
        <collision>
            <origin xyz="0.5 0 0" rpy="0 0 0"/>
            <geometry>
                <box size="0.2512969004498866 0.9808390304789087 0.2794385627371576" />
            </geometry>
        </collision>
    </link>
    <link name="3Link10">
        <inertial>
            <origin xyz="0.5 0 0" rpy="0 0 0"/>
            <mass value="1" />
            <inertia ixx="100" ixy="0" ixz="0" iyy="100" iyz="0" izz="100" />
        </inertial>
        <visual>
            <origin xyz="0.5 0 0" rpy="0 0 0"/>
            <geometry>
                <box size="0.6646910058629291 0.6660451581848106 0.3826266697623675" />
            </geometry>
            <material name="Blue">
            <color rgba="0 0 1.0 1.0"/>
            </material>
        </visual>
        <collision>
            <origin xyz="0.5 0 0" rpy="0 0 0"/>
            <geometry>
                <box size="0.6646910058629291 0.6660451581848106 0.3826266697623675" />
            </geometry>
        </collision>
    </link>
    <link name="3Link11">
        <inertial>
            <origin xyz="0.5 0 0" rpy="0 0 0"/>
            <mass value="1" />
            <inertia ixx="100" ixy="0" ixz="0" iyy="100" iyz="0" izz="100" />
        </inertial>
        <visual>
            <origin xyz="0.5 0 0" rpy="0 0 0"/>
            <geometry>
                <box size="0.7444540809610773 0.864205896893844 0.26536569607675864" />
            </geometry>
            <material name="Blue">
            <color rgba="0 0 1.0 1.0"/>
            </material>
        </visual>
        <collision>
            <origin xyz="0.5 0 0" rpy="0 0 0"/>
            <geometry>
                <box size="0.7444540809610773 0.864205896893844 0.26536569607675864" />
            </geometry>
        </collision>
    </link>
    <link name="3Link12">
        <inertial>
            <origin xyz="0.5 0 0" rpy="0 0 0"/>
            <mass value="1" />
            <inertia ixx="100" ixy="0" ixz="0" iyy="100" iyz="0" izz="100" />
        </inertial>
        <visual>
            <origin xyz="0.5 0 0" rpy="0 0 0"/>
            <geometry>
                <box size="0.3763081958131895 0.912073069739509 0.18602088725891486" />
            </geometry>
            <material name="Blue">
            <color rgba="0 0 1.0 1.0"/>
            </material>
        </visual>
        <collision>
            <origin xyz="0.5 0 0" rpy="0 0 0"/>
            <geometry>
                <box size="0.3763081958131895 0.912073069739509 0.18602088725891486" />
            </geometry>
        </collision>
    </link>
    <link name="3Link13">
        <inertial>
            <origin xyz="0.5 0 0" rpy="0 0 0"/>
            <mass value="1" />
            <inertia ixx="100" ixy="0" ixz="0" iyy="100" iyz="0" izz="100" />
        </inertial>
        <visual>
            <origin xyz="0.5 0 0" rpy="0 0 0"/>
            <geometry>
                <box size="0.3775661463236948 0.42495167921644506 0.9044150373712919" />
            </geometry>
            <material name="Blue">
            <color rgba="0 0 1.0 1.0"/>
            </material>
        </visual>
        <collision>
            <origin xyz="0.5 0 0" rpy="0 0 0"/>
            <geometry>
                <box size="0.3775661463236948 0.42495167921644506 0.9044150373712919" />
            </geometry>
        </collision>
    </link>
    <joint name="Torso_3Link0" type="revolute">
       <parent link="Torso"/>
       <child  link="3Link0"/>
       <origin rpy="0 0 0" xyz="0.5 2.0 10.0" />
     <axis xyz="1 1 0"/>
       <limit effort="0.0" lower="-3.14159" upper="3.14159" velocity="0.0"/>
    </joint>
    <joint name="3Link0_3Link1" type="revolute">
       <parent link="3Link0"/>
       <child  link="3Link1"/>
       <origin rpy="0 0 0" xyz="0.5 0 0" />
     <axis xyz="1 1 0"/>
       <limit effort="0.0" lower="-3.14159" upper="3.14159" velocity="0.0"/>
    </joint>
    <joint name="3Link1_3Link2" type="revolute">
       <parent link="3Link1"/>
       <child  link="3Link2"/>
       <origin rpy="0 0 0" xyz="0.5 0 0" />
     <axis xyz="1 1 0"/>
       <limit effort="0.0" lower="-3.14159" upper="3.14159" velocity="0.0"/>
    </joint>
    <joint name="3Link2_3Link3" type="revolute">
       <parent link="3Link2"/>
       <child  link="3Link3"/>
       <origin rpy="0 0 0" xyz="0.5 0 0" />
     <axis xyz="1 1 0"/>
       <limit effort="0.0" lower="-3.14159" upper="3.14159" velocity="0.0"/>
    </joint>
    <joint name="3Link3_3Link4" type="revolute">
       <parent link="3Link3"/>
       <child  link="3Link4"/>
       <origin rpy="0 0 0" xyz="0.5 0 0" />
     <axis xyz="1 1 0"/>
       <limit effort="0.0" lower="-3.14159" upper="3.14159" velocity="0.0"/>
    </joint>
    <joint name="3Link4_3Link5" type="revolute">
       <parent link="3Link4"/>
       <child  link="3Link5"/>
       <origin rpy="0 0 0" xyz="0.5 0 0" />
     <axis xyz="1 1 0"/>
       <limit effort="0.0" lower="-3.14159" upper="3.14159" velocity="0.0"/>
    </joint>
    <joint name="3Link5_3Link6" type="revolute">
       <parent link="3Link5"/>
       <child  link="3Link6"/>
       <origin rpy="0 0 0" xyz="0.5 0 0" />
     <axis xyz="1 1 0"/>
       <limit effort="0.0" lower="-3.14159" upper="3.14159" velocity="0.0"/>
    </joint>
    <joint name="3Link6_3Link7" type="revolute">
       <parent link="3Link6"/>
       <child  link="3Link7"/>
       <origin rpy="0 0 0" xyz="0.5 0 0" />
     <axis xyz="1 1 0"/>
       <limit effort="0.0" lower="-3.14159" upper="3.14159" velocity="0.0"/>
    </joint>
    <joint name="3Link7_3Link8" type="revolute">
       <parent link="3Link7"/>
       <child  link="3Link8"/>
       <origin rpy="0 0 0" xyz="0.5 0 0" />
     <axis xyz="1 1 0"/>
       <limit effort="0.0" lower="-3.14159" upper="3.14159" velocity="0.0"/>
    </joint>
    <joint name="3Link8_3Link9" type="revolute">
       <parent link="3Link8"/>
       <child  link="3Link9"/>
       <origin rpy="0 0 0" xyz="0.5 0 0" />
     <axis xyz="1 1 0"/>
       <limit effort="0.0" lower="-3.14159" upper="3.14159" velocity="0.0"/>
    </joint>
    <joint name="3Link9_3Link10" type="revolute">
       <parent link="3Link9"/>
       <child  link="3Link10"/>
       <origin rpy="0 0 0" xyz="0.5 0 0" />
     <axis xyz="1 1 0"/>
       <limit effort="0.0" lower="-3.14159" upper="3.14159" velocity="0.0"/>
    </joint>
    <joint name="3Link10_3Link11" type="revolute">
       <parent link="3Link10"/>
       <child  link="3Link11"/>
       <origin rpy="0 0 0" xyz="0.5 0 0" />
     <axis xyz="1 1 0"/>
       <limit effort="0.0" lower="-3.14159" upper="3.14159" velocity="0.0"/>
    </joint>
    <joint name="3Link11_3Link12" type="revolute">
       <parent link="3Link11"/>
       <child  link="3Link12"/>
       <origin rpy="0 0 0" xyz="0.5 0 0" />
     <axis xyz="1 1 0"/>
       <limit effort="0.0" lower="-3.14159" upper="3.14159" velocity="0.0"/>
    </joint>
    <joint name="3Link12_3Link13" type="revolute">
       <parent link="3Link12"/>
       <child  link="3Link13"/>
       <origin rpy="0 0 0" xyz="0.5 0 0" />
     <axis xyz="1 1 0"/>
       <limit effort="0.0" lower="-3.14159" upper="3.14159" velocity="0.0"/>
    </joint>
</robot>