<robot name = "robot">
    <link name="Torso">
        <inertial>
            <origin xyz="0 2 5" rpy="0 0 0"/>
            <mass value="1" />
            <inertia ixx="100" ixy="0" ixz="0" iyy="100" iyz="0" izz="100" />
        </inertial>
        <visual>
            <origin xyz="0 2 5" rpy="0 0 0"/>
            <geometry>
                <box size="0.5 0.5 0.5" />
            </geometry>
            <material name="Blue">
            <color rgba="0 0 1.0 1.0"/>
            </material>
        </visual>
        <collision>
            <origin xyz="0 2 5" rpy="0 0 0"/>
            <geometry>
                <box size="0.5 0.5 0.5" />
            </geometry>
        </collision>
    </link>
    <joint name="Torso_Link0" type="revolute">
       <parent link="Torso"/>
       <child  link="Link0"/>
       <origin rpy="0 0 0" xyz="0 2.25 4.75" />
     <axis xyz="1 1 0"/>
       <limit effort="0.0" lower="-3.14159" upper="3.14159" velocity="0.0"/>
    </joint>
    <link name="LeftLink0">
        <inertial>
            <origin xyz="0 0.25 -0.25" rpy="0 0 0"/>
            <mass value="1" />
            <inertia ixx="100" ixy="0" ixz="0" iyy="100" iyz="0" izz="100" />
        </inertial>
        <visual>
            <origin xyz="0 0.25 -0.25" rpy="0 0 0"/>
            <geometry>
                <box size="0.15146327406410975 0.39525510101266226 0.47646985567856914" />
            </geometry>
            <material name="Blue">
            <color rgba="0 0 1.0 1.0"/>
            </material>
        </visual>
        <collision>
            <origin xyz="0 0.25 -0.25" rpy="0 0 0"/>
            <geometry>
                <box size="0.15146327406410975 0.39525510101266226 0.47646985567856914" />
            </geometry>
        </collision>
    </link>
    <link name="LeftLink1">
        <inertial>
            <origin xyz="0 0.25 -0.25" rpy="0 0 0"/>
            <mass value="1" />
            <inertia ixx="100" ixy="0" ixz="0" iyy="100" iyz="0" izz="100" />
        </inertial>
        <visual>
            <origin xyz="0 0.25 -0.25" rpy="0 0 0"/>
            <geometry>
                <box size="0.08498013645436908 0.3818982218334358 0.4655114490780352" />
            </geometry>
            <material name="Blue">
            <color rgba="0 0 1.0 1.0"/>
            </material>
        </visual>
        <collision>
            <origin xyz="0 0.25 -0.25" rpy="0 0 0"/>
            <geometry>
                <box size="0.08498013645436908 0.3818982218334358 0.4655114490780352" />
            </geometry>
        </collision>
    </link>
    <link name="LeftLink2">
        <inertial>
            <origin xyz="0 0.25 -0.25" rpy="0 0 0"/>
            <mass value="1" />
            <inertia ixx="100" ixy="0" ixz="0" iyy="100" iyz="0" izz="100" />
        </inertial>
        <visual>
            <origin xyz="0 0.25 -0.25" rpy="0 0 0"/>
            <geometry>
                <box size="0.8671698926157774 0.5389391242916889 0.7867751310369935" />
            </geometry>
            <material name="Blue">
            <color rgba="0 0 1.0 1.0"/>
            </material>
        </visual>
        <collision>
            <origin xyz="0 0.25 -0.25" rpy="0 0 0"/>
            <geometry>
                <box size="0.8671698926157774 0.5389391242916889 0.7867751310369935" />
            </geometry>
        </collision>
    </link>
    <link name="LeftLink3">
        <inertial>
            <origin xyz="0 0.25 -0.25" rpy="0 0 0"/>
            <mass value="1" />
            <inertia ixx="100" ixy="0" ixz="0" iyy="100" iyz="0" izz="100" />
        </inertial>
        <visual>
            <origin xyz="0 0.25 -0.25" rpy="0 0 0"/>
            <geometry>
                <box size="0.2591761951634459 0.07496747014955585 0.7837341624427193" />
            </geometry>
            <material name="Blue">
            <color rgba="0 0 1.0 1.0"/>
            </material>
        </visual>
        <collision>
            <origin xyz="0 0.25 -0.25" rpy="0 0 0"/>
            <geometry>
                <box size="0.2591761951634459 0.07496747014955585 0.7837341624427193" />
            </geometry>
        </collision>
    </link>
    <link name="LeftLink4">
        <inertial>
            <origin xyz="0 0.25 -0.25" rpy="0 0 0"/>
            <mass value="1" />
            <inertia ixx="100" ixy="0" ixz="0" iyy="100" iyz="0" izz="100" />
        </inertial>
        <visual>
            <origin xyz="0 0.25 -0.25" rpy="0 0 0"/>
            <geometry>
                <box size="0.030510979749644562 0.3683483229379745 0.9461063771987192" />
            </geometry>
            <material name="Green">
            <color rgba="0 1.0 0 1.0"/>
            </material>
        </visual>
        <collision>
            <origin xyz="0 0.25 -0.25" rpy="0 0 0"/>
            <geometry>
                <box size="0.030510979749644562 0.3683483229379745 0.9461063771987192" />
            </geometry>
        </collision>
    </link>
    <link name="LeftLink5">
        <inertial>
            <origin xyz="0 0.25 -0.25" rpy="0 0 0"/>
            <mass value="1" />
            <inertia ixx="100" ixy="0" ixz="0" iyy="100" iyz="0" izz="100" />
        </inertial>
        <visual>
            <origin xyz="0 0.25 -0.25" rpy="0 0 0"/>
            <geometry>
                <box size="0.10036159732585748 0.23344973215412346 0.9546716213446287" />
            </geometry>
            <material name="Green">
            <color rgba="0 1.0 0 1.0"/>
            </material>
        </visual>
        <collision>
            <origin xyz="0 0.25 -0.25" rpy="0 0 0"/>
            <geometry>
                <box size="0.10036159732585748 0.23344973215412346 0.9546716213446287" />
            </geometry>
        </collision>
    </link>
    <link name="LeftLink6">
        <inertial>
            <origin xyz="0 0.25 -0.25" rpy="0 0 0"/>
            <mass value="1" />
            <inertia ixx="100" ixy="0" ixz="0" iyy="100" iyz="0" izz="100" />
        </inertial>
        <visual>
            <origin xyz="0 0.25 -0.25" rpy="0 0 0"/>
            <geometry>
                <box size="0.113253489897576 0.8862025985801928 0.43703509169499066" />
            </geometry>
            <material name="Green">
            <color rgba="0 1.0 0 1.0"/>
            </material>
        </visual>
        <collision>
            <origin xyz="0 0.25 -0.25" rpy="0 0 0"/>
            <geometry>
                <box size="0.113253489897576 0.8862025985801928 0.43703509169499066" />
            </geometry>
        </collision>
    </link>
    <link name="LeftLink7">
        <inertial>
            <origin xyz="0 0.25 -0.25" rpy="0 0 0"/>
            <mass value="1" />
            <inertia ixx="100" ixy="0" ixz="0" iyy="100" iyz="0" izz="100" />
        </inertial>
        <visual>
            <origin xyz="0 0.25 -0.25" rpy="0 0 0"/>
            <geometry>
                <box size="0.3041670890698511 0.9488071195765505 0.029350538486849875" />
            </geometry>
            <material name="Green">
            <color rgba="0 1.0 0 1.0"/>
            </material>
        </visual>
        <collision>
            <origin xyz="0 0.25 -0.25" rpy="0 0 0"/>
            <geometry>
                <box size="0.3041670890698511 0.9488071195765505 0.029350538486849875" />
            </geometry>
        </collision>
    </link>
    <joint name="LeftLink0_LeftLink1" type="revolute">
       <parent link="LeftLink0"/>
       <child  link="eftLink1"/>
       <origin rpy="0 0 0" xyz="0 0.5 0" />
     <axis xyz="1 1 0"/>
       <limit effort="0.0" lower="-3.14159" upper="3.14159" velocity="0.0"/>
    </joint>
    <joint name="LeftLink1_LeftLink2" type="revolute">
       <parent link="LeftLink1"/>
       <child  link="eftLink2"/>
       <origin rpy="0 0 0" xyz="0 0.5 0" />
     <axis xyz="1 1 0"/>
       <limit effort="0.0" lower="-3.14159" upper="3.14159" velocity="0.0"/>
    </joint>
    <joint name="LeftLink2_LeftLink3" type="revolute">
       <parent link="LeftLink2"/>
       <child  link="eftLink3"/>
       <origin rpy="0 0 0" xyz="0 0.5 0" />
     <axis xyz="1 1 0"/>
       <limit effort="0.0" lower="-3.14159" upper="3.14159" velocity="0.0"/>
    </joint>
    <joint name="LeftLink3_LeftLink4" type="revolute">
       <parent link="LeftLink3"/>
       <child  link="eftLink4"/>
       <origin rpy="0 0 0" xyz="0 0.5 0" />
     <axis xyz="1 1 0"/>
       <limit effort="0.0" lower="-3.14159" upper="3.14159" velocity="0.0"/>
    </joint>
    <joint name="LeftLink4_LeftLink5" type="revolute">
       <parent link="LeftLink4"/>
       <child  link="eftLink5"/>
       <origin rpy="0 0 0" xyz="0 0.5 0" />
     <axis xyz="1 1 0"/>
       <limit effort="0.0" lower="-3.14159" upper="3.14159" velocity="0.0"/>
    </joint>
    <joint name="LeftLink5_LeftLink6" type="revolute">
       <parent link="LeftLink5"/>
       <child  link="eftLink6"/>
       <origin rpy="0 0 0" xyz="0 0.5 0" />
     <axis xyz="1 1 0"/>
       <limit effort="0.0" lower="-3.14159" upper="3.14159" velocity="0.0"/>
    </joint>
    <joint name="LeftLink6_LeftLink7" type="revolute">
       <parent link="LeftLink6"/>
       <child  link="eftLink7"/>
       <origin rpy="0 0 0" xyz="0 0.5 0" />
     <axis xyz="1 1 0"/>
       <limit effort="0.0" lower="-3.14159" upper="3.14159" velocity="0.0"/>
    </joint>
    <link name="RightLink0">
        <inertial>
            <origin xyz="0 -0.25 -0.25" rpy="0 0 0"/>
            <mass value="1" />
            <inertia ixx="100" ixy="0" ixz="0" iyy="100" iyz="0" izz="100" />
        </inertial>
        <visual>
            <origin xyz="0 -0.25 -0.25" rpy="0 0 0"/>
            <geometry>
                <box size="0.15146327406410975 0.39525510101266226 0.47646985567856914" />
            </geometry>
            <material name="Blue">
            <color rgba="0 0 1.0 1.0"/>
            </material>
        </visual>
        <collision>
            <origin xyz="0 -0.25 -0.25" rpy="0 0 0"/>
            <geometry>
                <box size="0.15146327406410975 0.39525510101266226 0.47646985567856914" />
            </geometry>
        </collision>
    </link>
    <link name="RightLink1">
        <inertial>
            <origin xyz="0 -0.25 -0.25" rpy="0 0 0"/>
            <mass value="1" />
            <inertia ixx="100" ixy="0" ixz="0" iyy="100" iyz="0" izz="100" />
        </inertial>
        <visual>
            <origin xyz="0 -0.25 -0.25" rpy="0 0 0"/>
            <geometry>
                <box size="0.08498013645436908 0.3818982218334358 0.4655114490780352" />
            </geometry>
            <material name="Green">
            <color rgba="0 1.0 0 1.0"/>
            </material>
        </visual>
        <collision>
            <origin xyz="0 -0.25 -0.25" rpy="0 0 0"/>
            <geometry>
                <box size="0.08498013645436908 0.3818982218334358 0.4655114490780352" />
            </geometry>
        </collision>
    </link>
    <link name="RightLink2">
        <inertial>
            <origin xyz="0 -0.25 -0.25" rpy="0 0 0"/>
            <mass value="1" />
            <inertia ixx="100" ixy="0" ixz="0" iyy="100" iyz="0" izz="100" />
        </inertial>
        <visual>
            <origin xyz="0 -0.25 -0.25" rpy="0 0 0"/>
            <geometry>
                <box size="0.8671698926157774 0.5389391242916889 0.7867751310369935" />
            </geometry>
            <material name="Green">
            <color rgba="0 1.0 0 1.0"/>
            </material>
        </visual>
        <collision>
            <origin xyz="0 -0.25 -0.25" rpy="0 0 0"/>
            <geometry>
                <box size="0.8671698926157774 0.5389391242916889 0.7867751310369935" />
            </geometry>
        </collision>
    </link>
    <link name="RightLink3">
        <inertial>
            <origin xyz="0 -0.25 -0.25" rpy="0 0 0"/>
            <mass value="1" />
            <inertia ixx="100" ixy="0" ixz="0" iyy="100" iyz="0" izz="100" />
        </inertial>
        <visual>
            <origin xyz="0 -0.25 -0.25" rpy="0 0 0"/>
            <geometry>
                <box size="0.2591761951634459 0.07496747014955585 0.7837341624427193" />
            </geometry>
            <material name="Green">
            <color rgba="0 1.0 0 1.0"/>
            </material>
        </visual>
        <collision>
            <origin xyz="0 -0.25 -0.25" rpy="0 0 0"/>
            <geometry>
                <box size="0.2591761951634459 0.07496747014955585 0.7837341624427193" />
            </geometry>
        </collision>
    </link>
    <link name="RightLink4">
        <inertial>
            <origin xyz="0 -0.25 -0.25" rpy="0 0 0"/>
            <mass value="1" />
            <inertia ixx="100" ixy="0" ixz="0" iyy="100" iyz="0" izz="100" />
        </inertial>
        <visual>
            <origin xyz="0 -0.25 -0.25" rpy="0 0 0"/>
            <geometry>
                <box size="0.030510979749644562 0.3683483229379745 0.9461063771987192" />
            </geometry>
            <material name="Blue">
            <color rgba="0 0 1.0 1.0"/>
            </material>
        </visual>
        <collision>
            <origin xyz="0 -0.25 -0.25" rpy="0 0 0"/>
            <geometry>
                <box size="0.030510979749644562 0.3683483229379745 0.9461063771987192" />
            </geometry>
        </collision>
    </link>
    <link name="RightLink5">
        <inertial>
            <origin xyz="0 -0.25 -0.25" rpy="0 0 0"/>
            <mass value="1" />
            <inertia ixx="100" ixy="0" ixz="0" iyy="100" iyz="0" izz="100" />
        </inertial>
        <visual>
            <origin xyz="0 -0.25 -0.25" rpy="0 0 0"/>
            <geometry>
                <box size="0.10036159732585748 0.23344973215412346 0.9546716213446287" />
            </geometry>
            <material name="Green">
            <color rgba="0 1.0 0 1.0"/>
            </material>
        </visual>
        <collision>
            <origin xyz="0 -0.25 -0.25" rpy="0 0 0"/>
            <geometry>
                <box size="0.10036159732585748 0.23344973215412346 0.9546716213446287" />
            </geometry>
        </collision>
    </link>
    <link name="RightLink6">
        <inertial>
            <origin xyz="0 -0.25 -0.25" rpy="0 0 0"/>
            <mass value="1" />
            <inertia ixx="100" ixy="0" ixz="0" iyy="100" iyz="0" izz="100" />
        </inertial>
        <visual>
            <origin xyz="0 -0.25 -0.25" rpy="0 0 0"/>
            <geometry>
                <box size="0.113253489897576 0.8862025985801928 0.43703509169499066" />
            </geometry>
            <material name="Blue">
            <color rgba="0 0 1.0 1.0"/>
            </material>
        </visual>
        <collision>
            <origin xyz="0 -0.25 -0.25" rpy="0 0 0"/>
            <geometry>
                <box size="0.113253489897576 0.8862025985801928 0.43703509169499066" />
            </geometry>
        </collision>
    </link>
    <link name="RightLink7">
        <inertial>
            <origin xyz="0 -0.25 -0.25" rpy="0 0 0"/>
            <mass value="1" />
            <inertia ixx="100" ixy="0" ixz="0" iyy="100" iyz="0" izz="100" />
        </inertial>
        <visual>
            <origin xyz="0 -0.25 -0.25" rpy="0 0 0"/>
            <geometry>
                <box size="0.3041670890698511 0.9488071195765505 0.029350538486849875" />
            </geometry>
            <material name="Blue">
            <color rgba="0 0 1.0 1.0"/>
            </material>
        </visual>
        <collision>
            <origin xyz="0 -0.25 -0.25" rpy="0 0 0"/>
            <geometry>
                <box size="0.3041670890698511 0.9488071195765505 0.029350538486849875" />
            </geometry>
        </collision>
    </link>
    <joint name="RightLink0_RightLink1" type="revolute">
       <parent link="RightLink0"/>
       <child  link="ightLink1"/>
       <origin rpy="0 0 0" xyz="0 0.5 0" />
     <axis xyz="1 1 0"/>
       <limit effort="0.0" lower="-3.14159" upper="3.14159" velocity="0.0"/>
    </joint>
    <joint name="RightLink1_RightLink2" type="revolute">
       <parent link="RightLink1"/>
       <child  link="ightLink2"/>
       <origin rpy="0 0 0" xyz="0 0.5 0" />
     <axis xyz="1 1 0"/>
       <limit effort="0.0" lower="-3.14159" upper="3.14159" velocity="0.0"/>
    </joint>
    <joint name="RightLink2_RightLink3" type="revolute">
       <parent link="RightLink2"/>
       <child  link="ightLink3"/>
       <origin rpy="0 0 0" xyz="0 0.5 0" />
     <axis xyz="1 1 0"/>
       <limit effort="0.0" lower="-3.14159" upper="3.14159" velocity="0.0"/>
    </joint>
    <joint name="RightLink3_RightLink4" type="revolute">
       <parent link="RightLink3"/>
       <child  link="ightLink4"/>
       <origin rpy="0 0 0" xyz="0 0.5 0" />
     <axis xyz="1 1 0"/>
       <limit effort="0.0" lower="-3.14159" upper="3.14159" velocity="0.0"/>
    </joint>
    <joint name="RightLink4_RightLink5" type="revolute">
       <parent link="RightLink4"/>
       <child  link="ightLink5"/>
       <origin rpy="0 0 0" xyz="0 0.5 0" />
     <axis xyz="1 1 0"/>
       <limit effort="0.0" lower="-3.14159" upper="3.14159" velocity="0.0"/>
    </joint>
    <joint name="RightLink5_RightLink6" type="revolute">
       <parent link="RightLink5"/>
       <child  link="ightLink6"/>
       <origin rpy="0 0 0" xyz="0 0.5 0" />
     <axis xyz="1 1 0"/>
       <limit effort="0.0" lower="-3.14159" upper="3.14159" velocity="0.0"/>
    </joint>
    <joint name="RightLink6_RightLink7" type="revolute">
       <parent link="RightLink6"/>
       <child  link="ightLink7"/>
       <origin rpy="0 0 0" xyz="0 0.5 0" />
     <axis xyz="1 1 0"/>
       <limit effort="0.0" lower="-3.14159" upper="3.14159" velocity="0.0"/>
    </joint>
</robot>