<robot name = "robot">
    <link name="Torso">
        <inertial>
            <origin xyz="0 2 10" rpy="0 0 0"/>
            <mass value="1" />
            <inertia ixx="100" ixy="0" ixz="0" iyy="100" iyz="0" izz="100" />
        </inertial>
        <visual>
            <origin xyz="0 2 10" rpy="0 0 0"/>
            <geometry>
                <box size="0.5 0.5 0.5" />
            </geometry>
            <material name="Red">
            <color rgba="1.0 0 0 1.0"/>
            </material>
        </visual>
        <collision>
            <origin xyz="0 2 10" rpy="0 0 0"/>
            <geometry>
                <box size="0.5 0.5 0.5" />
            </geometry>
        </collision>
    </link>
    <link name="0Link0">
        <inertial>
            <origin xyz="0 0 -0.5" rpy="0 0 0"/>
            <mass value="1" />
            <inertia ixx="100" ixy="0" ixz="0" iyy="100" iyz="0" izz="100" />
        </inertial>
        <visual>
            <origin xyz="0 0 -0.5" rpy="0 0 0"/>
            <geometry>
                <box size="0.11404602361424343 0.6772407137474431 0.29567618057915224" />
            </geometry>
            <material name="Green">
            <color rgba="0 1.0 0 1.0"/>
            </material>
        </visual>
        <collision>
            <origin xyz="0 0 -0.5" rpy="0 0 0"/>
            <geometry>
                <box size="0.11404602361424343 0.6772407137474431 0.29567618057915224" />
            </geometry>
        </collision>
    </link>
    <link name="0Link1">
        <inertial>
            <origin xyz="0 0 -0.5" rpy="0 0 0"/>
            <mass value="1" />
            <inertia ixx="100" ixy="0" ixz="0" iyy="100" iyz="0" izz="100" />
        </inertial>
        <visual>
            <origin xyz="0 0 -0.5" rpy="0 0 0"/>
            <geometry>
                <box size="0.2145746491670889 0.06808115778987989 0.9831476687270602" />
            </geometry>
            <material name="Green">
            <color rgba="0 1.0 0 1.0"/>
            </material>
        </visual>
        <collision>
            <origin xyz="0 0 -0.5" rpy="0 0 0"/>
            <geometry>
                <box size="0.2145746491670889 0.06808115778987989 0.9831476687270602" />
            </geometry>
        </collision>
    </link>
    <link name="0Link2">
        <inertial>
            <origin xyz="0 0 -0.5" rpy="0 0 0"/>
            <mass value="1" />
            <inertia ixx="100" ixy="0" ixz="0" iyy="100" iyz="0" izz="100" />
        </inertial>
        <visual>
            <origin xyz="0 0 -0.5" rpy="0 0 0"/>
            <geometry>
                <box size="0.4011531052011895 0.6785310629515737 0.7212911788018691" />
            </geometry>
            <material name="Blue">
            <color rgba="0 0 1.0 1.0"/>
            </material>
        </visual>
        <collision>
            <origin xyz="0 0 -0.5" rpy="0 0 0"/>
            <geometry>
                <box size="0.4011531052011895 0.6785310629515737 0.7212911788018691" />
            </geometry>
        </collision>
    </link>
    <link name="0Link3">
        <inertial>
            <origin xyz="0 0 -0.5" rpy="0 0 0"/>
            <mass value="1" />
            <inertia ixx="100" ixy="0" ixz="0" iyy="100" iyz="0" izz="100" />
        </inertial>
        <visual>
            <origin xyz="0 0 -0.5" rpy="0 0 0"/>
            <geometry>
                <box size="0.5838107784216657 0.5879220994754344 0.1486888962900319" />
            </geometry>
            <material name="Blue">
            <color rgba="0 0 1.0 1.0"/>
            </material>
        </visual>
        <collision>
            <origin xyz="0 0 -0.5" rpy="0 0 0"/>
            <geometry>
                <box size="0.5838107784216657 0.5879220994754344 0.1486888962900319" />
            </geometry>
        </collision>
    </link>
    <link name="0Link4">
        <inertial>
            <origin xyz="0 0 -0.5" rpy="0 0 0"/>
            <mass value="1" />
            <inertia ixx="100" ixy="0" ixz="0" iyy="100" iyz="0" izz="100" />
        </inertial>
        <visual>
            <origin xyz="0 0 -0.5" rpy="0 0 0"/>
            <geometry>
                <box size="0.4060900979974953 0.6369805859026559 0.8755781885502288" />
            </geometry>
            <material name="Blue">
            <color rgba="0 0 1.0 1.0"/>
            </material>
        </visual>
        <collision>
            <origin xyz="0 0 -0.5" rpy="0 0 0"/>
            <geometry>
                <box size="0.4060900979974953 0.6369805859026559 0.8755781885502288" />
            </geometry>
        </collision>
    </link>
    <link name="0Link5">
        <inertial>
            <origin xyz="0 0 -0.5" rpy="0 0 0"/>
            <mass value="1" />
            <inertia ixx="100" ixy="0" ixz="0" iyy="100" iyz="0" izz="100" />
        </inertial>
        <visual>
            <origin xyz="0 0 -0.5" rpy="0 0 0"/>
            <geometry>
                <box size="0.19046533659461806 0.35664397050647634 0.32989474907139704" />
            </geometry>
            <material name="Blue">
            <color rgba="0 0 1.0 1.0"/>
            </material>
        </visual>
        <collision>
            <origin xyz="0 0 -0.5" rpy="0 0 0"/>
            <geometry>
                <box size="0.19046533659461806 0.35664397050647634 0.32989474907139704" />
            </geometry>
        </collision>
    </link>
    <link name="0Link6">
        <inertial>
            <origin xyz="0 0 -0.5" rpy="0 0 0"/>
            <mass value="1" />
            <inertia ixx="100" ixy="0" ixz="0" iyy="100" iyz="0" izz="100" />
        </inertial>
        <visual>
            <origin xyz="0 0 -0.5" rpy="0 0 0"/>
            <geometry>
                <box size="0.2083110998987331 0.6595211748535085 0.32557093191864617" />
            </geometry>
            <material name="Green">
            <color rgba="0 1.0 0 1.0"/>
            </material>
        </visual>
        <collision>
            <origin xyz="0 0 -0.5" rpy="0 0 0"/>
            <geometry>
                <box size="0.2083110998987331 0.6595211748535085 0.32557093191864617" />
            </geometry>
        </collision>
    </link>
    <link name="0Link7">
        <inertial>
            <origin xyz="0 0 -0.5" rpy="0 0 0"/>
            <mass value="1" />
            <inertia ixx="100" ixy="0" ixz="0" iyy="100" iyz="0" izz="100" />
        </inertial>
        <visual>
            <origin xyz="0 0 -0.5" rpy="0 0 0"/>
            <geometry>
                <box size="0.6823629396204243 0.7989662657039543 0.09806528913246415" />
            </geometry>
            <material name="Green">
            <color rgba="0 1.0 0 1.0"/>
            </material>
        </visual>
        <collision>
            <origin xyz="0 0 -0.5" rpy="0 0 0"/>
            <geometry>
                <box size="0.6823629396204243 0.7989662657039543 0.09806528913246415" />
            </geometry>
        </collision>
    </link>
    <link name="0Link8">
        <inertial>
            <origin xyz="0 0 -0.5" rpy="0 0 0"/>
            <mass value="1" />
            <inertia ixx="100" ixy="0" ixz="0" iyy="100" iyz="0" izz="100" />
        </inertial>
        <visual>
            <origin xyz="0 0 -0.5" rpy="0 0 0"/>
            <geometry>
                <box size="0.873691123456535 0.5096174692002986 0.018686218059421056" />
            </geometry>
            <material name="Blue">
            <color rgba="0 0 1.0 1.0"/>
            </material>
        </visual>
        <collision>
            <origin xyz="0 0 -0.5" rpy="0 0 0"/>
            <geometry>
                <box size="0.873691123456535 0.5096174692002986 0.018686218059421056" />
            </geometry>
        </collision>
    </link>
    <link name="0Link9">
        <inertial>
            <origin xyz="0 0 -0.5" rpy="0 0 0"/>
            <mass value="1" />
            <inertia ixx="100" ixy="0" ixz="0" iyy="100" iyz="0" izz="100" />
        </inertial>
        <visual>
            <origin xyz="0 0 -0.5" rpy="0 0 0"/>
            <geometry>
                <box size="0.590982341047435 0.3502813079398055 0.8032084431791727" />
            </geometry>
            <material name="Blue">
            <color rgba="0 0 1.0 1.0"/>
            </material>
        </visual>
        <collision>
            <origin xyz="0 0 -0.5" rpy="0 0 0"/>
            <geometry>
                <box size="0.590982341047435 0.3502813079398055 0.8032084431791727" />
            </geometry>
        </collision>
    </link>
    <link name="0Link10">
        <inertial>
            <origin xyz="0 0 -0.5" rpy="0 0 0"/>
            <mass value="1" />
            <inertia ixx="100" ixy="0" ixz="0" iyy="100" iyz="0" izz="100" />
        </inertial>
        <visual>
            <origin xyz="0 0 -0.5" rpy="0 0 0"/>
            <geometry>
                <box size="0.6191823439026002 0.667080170332481 0.22498098074472073" />
            </geometry>
            <material name="Blue">
            <color rgba="0 0 1.0 1.0"/>
            </material>
        </visual>
        <collision>
            <origin xyz="0 0 -0.5" rpy="0 0 0"/>
            <geometry>
                <box size="0.6191823439026002 0.667080170332481 0.22498098074472073" />
            </geometry>
        </collision>
    </link>
    <joint name="Torso_0Link0" type="revolute">
       <parent link="Torso"/>
       <child  link="0Link0"/>
       <origin rpy="0 0 0" xyz="0.0 2.0 9.5" />
     <axis xyz="1 1 0"/>
       <limit effort="0.0" lower="-3.14159" upper="3.14159" velocity="0.0"/>
    </joint>
    <joint name="0Link0_0Link1" type="revolute">
       <parent link="0Link0"/>
       <child  link="0Link1"/>
       <origin rpy="0 0 0" xyz="0 0 -0.5" />
     <axis xyz="1 1 0"/>
       <limit effort="0.0" lower="-3.14159" upper="3.14159" velocity="0.0"/>
    </joint>
    <joint name="0Link1_0Link2" type="revolute">
       <parent link="0Link1"/>
       <child  link="0Link2"/>
       <origin rpy="0 0 0" xyz="0 0 -0.5" />
     <axis xyz="1 1 0"/>
       <limit effort="0.0" lower="-3.14159" upper="3.14159" velocity="0.0"/>
    </joint>
    <joint name="0Link2_0Link3" type="revolute">
       <parent link="0Link2"/>
       <child  link="0Link3"/>
       <origin rpy="0 0 0" xyz="0 0 -0.5" />
     <axis xyz="1 1 0"/>
       <limit effort="0.0" lower="-3.14159" upper="3.14159" velocity="0.0"/>
    </joint>
    <joint name="0Link3_0Link4" type="revolute">
       <parent link="0Link3"/>
       <child  link="0Link4"/>
       <origin rpy="0 0 0" xyz="0 0 -0.5" />
     <axis xyz="1 1 0"/>
       <limit effort="0.0" lower="-3.14159" upper="3.14159" velocity="0.0"/>
    </joint>
    <joint name="0Link4_0Link5" type="revolute">
       <parent link="0Link4"/>
       <child  link="0Link5"/>
       <origin rpy="0 0 0" xyz="0 0 -0.5" />
     <axis xyz="1 1 0"/>
       <limit effort="0.0" lower="-3.14159" upper="3.14159" velocity="0.0"/>
    </joint>
    <joint name="0Link5_0Link6" type="revolute">
       <parent link="0Link5"/>
       <child  link="0Link6"/>
       <origin rpy="0 0 0" xyz="0 0 -0.5" />
     <axis xyz="1 1 0"/>
       <limit effort="0.0" lower="-3.14159" upper="3.14159" velocity="0.0"/>
    </joint>
    <joint name="0Link6_0Link7" type="revolute">
       <parent link="0Link6"/>
       <child  link="0Link7"/>
       <origin rpy="0 0 0" xyz="0 0 -0.5" />
     <axis xyz="1 1 0"/>
       <limit effort="0.0" lower="-3.14159" upper="3.14159" velocity="0.0"/>
    </joint>
    <joint name="0Link7_0Link8" type="revolute">
       <parent link="0Link7"/>
       <child  link="0Link8"/>
       <origin rpy="0 0 0" xyz="0 0 -0.5" />
     <axis xyz="1 1 0"/>
       <limit effort="0.0" lower="-3.14159" upper="3.14159" velocity="0.0"/>
    </joint>
    <joint name="0Link8_0Link9" type="revolute">
       <parent link="0Link8"/>
       <child  link="0Link9"/>
       <origin rpy="0 0 0" xyz="0 0 -0.5" />
     <axis xyz="1 1 0"/>
       <limit effort="0.0" lower="-3.14159" upper="3.14159" velocity="0.0"/>
    </joint>
    <joint name="0Link9_0Link10" type="revolute">
       <parent link="0Link9"/>
       <child  link="0Link10"/>
       <origin rpy="0 0 0" xyz="0 0 -0.5" />
     <axis xyz="1 1 0"/>
       <limit effort="0.0" lower="-3.14159" upper="3.14159" velocity="0.0"/>
    </joint>
    <link name="1Link0">
        <inertial>
            <origin xyz="-0.5 0 0" rpy="0 0 0"/>
            <mass value="1" />
            <inertia ixx="100" ixy="0" ixz="0" iyy="100" iyz="0" izz="100" />
        </inertial>
        <visual>
            <origin xyz="-0.5 0 0" rpy="0 0 0"/>
            <geometry>
                <box size="0.23426789166955342 0.6121095263611341 0.45329547215295063" />
            </geometry>
            <material name="Blue">
            <color rgba="0 0 1.0 1.0"/>
            </material>
        </visual>
        <collision>
            <origin xyz="-0.5 0 0" rpy="0 0 0"/>
            <geometry>
                <box size="0.23426789166955342 0.6121095263611341 0.45329547215295063" />
            </geometry>
        </collision>
    </link>
    <link name="1Link1">
        <inertial>
            <origin xyz="-0.5 0 0" rpy="0 0 0"/>
            <mass value="1" />
            <inertia ixx="100" ixy="0" ixz="0" iyy="100" iyz="0" izz="100" />
        </inertial>
        <visual>
            <origin xyz="-0.5 0 0" rpy="0 0 0"/>
            <geometry>
                <box size="0.03400176825318646 0.7358123581499374 0.2747533303328319" />
            </geometry>
            <material name="Green">
            <color rgba="0 1.0 0 1.0"/>
            </material>
        </visual>
        <collision>
            <origin xyz="-0.5 0 0" rpy="0 0 0"/>
            <geometry>
                <box size="0.03400176825318646 0.7358123581499374 0.2747533303328319" />
            </geometry>
        </collision>
    </link>
    <link name="1Link2">
        <inertial>
            <origin xyz="-0.5 0 0" rpy="0 0 0"/>
            <mass value="1" />
            <inertia ixx="100" ixy="0" ixz="0" iyy="100" iyz="0" izz="100" />
        </inertial>
        <visual>
            <origin xyz="-0.5 0 0" rpy="0 0 0"/>
            <geometry>
                <box size="0.18215496388869845 0.8234709104324351 0.46530082002587303" />
            </geometry>
            <material name="Green">
            <color rgba="0 1.0 0 1.0"/>
            </material>
        </visual>
        <collision>
            <origin xyz="-0.5 0 0" rpy="0 0 0"/>
            <geometry>
                <box size="0.18215496388869845 0.8234709104324351 0.46530082002587303" />
            </geometry>
        </collision>
    </link>
    <link name="1Link3">
        <inertial>
            <origin xyz="-0.5 0 0" rpy="0 0 0"/>
            <mass value="1" />
            <inertia ixx="100" ixy="0" ixz="0" iyy="100" iyz="0" izz="100" />
        </inertial>
        <visual>
            <origin xyz="-0.5 0 0" rpy="0 0 0"/>
            <geometry>
                <box size="0.02131783992127778 0.31377035507082973 0.1657784426284249" />
            </geometry>
            <material name="Blue">
            <color rgba="0 0 1.0 1.0"/>
            </material>
        </visual>
        <collision>
            <origin xyz="-0.5 0 0" rpy="0 0 0"/>
            <geometry>
                <box size="0.02131783992127778 0.31377035507082973 0.1657784426284249" />
            </geometry>
        </collision>
    </link>
    <link name="1Link4">
        <inertial>
            <origin xyz="-0.5 0 0" rpy="0 0 0"/>
            <mass value="1" />
            <inertia ixx="100" ixy="0" ixz="0" iyy="100" iyz="0" izz="100" />
        </inertial>
        <visual>
            <origin xyz="-0.5 0 0" rpy="0 0 0"/>
            <geometry>
                <box size="0.6852055813096606 0.4525732343742723 0.14867134545131722" />
            </geometry>
            <material name="Blue">
            <color rgba="0 0 1.0 1.0"/>
            </material>
        </visual>
        <collision>
            <origin xyz="-0.5 0 0" rpy="0 0 0"/>
            <geometry>
                <box size="0.6852055813096606 0.4525732343742723 0.14867134545131722" />
            </geometry>
        </collision>
    </link>
    <link name="1Link5">
        <inertial>
            <origin xyz="-0.5 0 0" rpy="0 0 0"/>
            <mass value="1" />
            <inertia ixx="100" ixy="0" ixz="0" iyy="100" iyz="0" izz="100" />
        </inertial>
        <visual>
            <origin xyz="-0.5 0 0" rpy="0 0 0"/>
            <geometry>
                <box size="0.2698471295932705 0.0686071327132618 0.29370801931268153" />
            </geometry>
            <material name="Blue">
            <color rgba="0 0 1.0 1.0"/>
            </material>
        </visual>
        <collision>
            <origin xyz="-0.5 0 0" rpy="0 0 0"/>
            <geometry>
                <box size="0.2698471295932705 0.0686071327132618 0.29370801931268153" />
            </geometry>
        </collision>
    </link>
    <link name="1Link6">
        <inertial>
            <origin xyz="-0.5 0 0" rpy="0 0 0"/>
            <mass value="1" />
            <inertia ixx="100" ixy="0" ixz="0" iyy="100" iyz="0" izz="100" />
        </inertial>
        <visual>
            <origin xyz="-0.5 0 0" rpy="0 0 0"/>
            <geometry>
                <box size="0.13353596170401005 0.00994986321561786 0.42009878065087136" />
            </geometry>
            <material name="Green">
            <color rgba="0 1.0 0 1.0"/>
            </material>
        </visual>
        <collision>
            <origin xyz="-0.5 0 0" rpy="0 0 0"/>
            <geometry>
                <box size="0.13353596170401005 0.00994986321561786 0.42009878065087136" />
            </geometry>
        </collision>
    </link>
    <link name="1Link7">
        <inertial>
            <origin xyz="-0.5 0 0" rpy="0 0 0"/>
            <mass value="1" />
            <inertia ixx="100" ixy="0" ixz="0" iyy="100" iyz="0" izz="100" />
        </inertial>
        <visual>
            <origin xyz="-0.5 0 0" rpy="0 0 0"/>
            <geometry>
                <box size="0.764501585168526 0.6955269677418688 0.2490662859349687" />
            </geometry>
            <material name="Blue">
            <color rgba="0 0 1.0 1.0"/>
            </material>
        </visual>
        <collision>
            <origin xyz="-0.5 0 0" rpy="0 0 0"/>
            <geometry>
                <box size="0.764501585168526 0.6955269677418688 0.2490662859349687" />
            </geometry>
        </collision>
    </link>
    <link name="1Link8">
        <inertial>
            <origin xyz="-0.5 0 0" rpy="0 0 0"/>
            <mass value="1" />
            <inertia ixx="100" ixy="0" ixz="0" iyy="100" iyz="0" izz="100" />
        </inertial>
        <visual>
            <origin xyz="-0.5 0 0" rpy="0 0 0"/>
            <geometry>
                <box size="0.91704020846113 0.6467301672880945 0.5543579358849322" />
            </geometry>
            <material name="Green">
            <color rgba="0 1.0 0 1.0"/>
            </material>
        </visual>
        <collision>
            <origin xyz="-0.5 0 0" rpy="0 0 0"/>
            <geometry>
                <box size="0.91704020846113 0.6467301672880945 0.5543579358849322" />
            </geometry>
        </collision>
    </link>
    <joint name="Torso_1Link0" type="revolute">
       <parent link="Torso"/>
       <child  link="1Link0"/>
       <origin rpy="0 0 0" xyz="-0.5 2.0 10.0" />
     <axis xyz="1 1 0"/>
       <limit effort="0.0" lower="-3.14159" upper="3.14159" velocity="0.0"/>
    </joint>
    <joint name="1Link0_1Link1" type="revolute">
       <parent link="1Link0"/>
       <child  link="1Link1"/>
       <origin rpy="0 0 0" xyz="-0.5 0 0" />
     <axis xyz="1 1 0"/>
       <limit effort="0.0" lower="-3.14159" upper="3.14159" velocity="0.0"/>
    </joint>
    <joint name="1Link1_1Link2" type="revolute">
       <parent link="1Link1"/>
       <child  link="1Link2"/>
       <origin rpy="0 0 0" xyz="-0.5 0 0" />
     <axis xyz="1 1 0"/>
       <limit effort="0.0" lower="-3.14159" upper="3.14159" velocity="0.0"/>
    </joint>
    <joint name="1Link2_1Link3" type="revolute">
       <parent link="1Link2"/>
       <child  link="1Link3"/>
       <origin rpy="0 0 0" xyz="-0.5 0 0" />
     <axis xyz="1 1 0"/>
       <limit effort="0.0" lower="-3.14159" upper="3.14159" velocity="0.0"/>
    </joint>
    <joint name="1Link3_1Link4" type="revolute">
       <parent link="1Link3"/>
       <child  link="1Link4"/>
       <origin rpy="0 0 0" xyz="-0.5 0 0" />
     <axis xyz="1 1 0"/>
       <limit effort="0.0" lower="-3.14159" upper="3.14159" velocity="0.0"/>
    </joint>
    <joint name="1Link4_1Link5" type="revolute">
       <parent link="1Link4"/>
       <child  link="1Link5"/>
       <origin rpy="0 0 0" xyz="-0.5 0 0" />
     <axis xyz="1 1 0"/>
       <limit effort="0.0" lower="-3.14159" upper="3.14159" velocity="0.0"/>
    </joint>
    <joint name="1Link5_1Link6" type="revolute">
       <parent link="1Link5"/>
       <child  link="1Link6"/>
       <origin rpy="0 0 0" xyz="-0.5 0 0" />
     <axis xyz="1 1 0"/>
       <limit effort="0.0" lower="-3.14159" upper="3.14159" velocity="0.0"/>
    </joint>
    <joint name="1Link6_1Link7" type="revolute">
       <parent link="1Link6"/>
       <child  link="1Link7"/>
       <origin rpy="0 0 0" xyz="-0.5 0 0" />
     <axis xyz="1 1 0"/>
       <limit effort="0.0" lower="-3.14159" upper="3.14159" velocity="0.0"/>
    </joint>
    <joint name="1Link7_1Link8" type="revolute">
       <parent link="1Link7"/>
       <child  link="1Link8"/>
       <origin rpy="0 0 0" xyz="-0.5 0 0" />
     <axis xyz="1 1 0"/>
       <limit effort="0.0" lower="-3.14159" upper="3.14159" velocity="0.0"/>
    </joint>
    <link name="2Link0">
        <inertial>
            <origin xyz="0 0 0.5" rpy="0 0 0"/>
            <mass value="1" />
            <inertia ixx="100" ixy="0" ixz="0" iyy="100" iyz="0" izz="100" />
        </inertial>
        <visual>
            <origin xyz="0 0 0.5" rpy="0 0 0"/>
            <geometry>
                <box size="0.7163260318145707 0.23743605641655674 0.37603213612546005" />
            </geometry>
            <material name="Blue">
            <color rgba="0 0 1.0 1.0"/>
            </material>
        </visual>
        <collision>
            <origin xyz="0 0 0.5" rpy="0 0 0"/>
            <geometry>
                <box size="0.7163260318145707 0.23743605641655674 0.37603213612546005" />
            </geometry>
        </collision>
    </link>
    <link name="2Link1">
        <inertial>
            <origin xyz="0 0 0.5" rpy="0 0 0"/>
            <mass value="1" />
            <inertia ixx="100" ixy="0" ixz="0" iyy="100" iyz="0" izz="100" />
        </inertial>
        <visual>
            <origin xyz="0 0 0.5" rpy="0 0 0"/>
            <geometry>
                <box size="0.31497512894389956 0.21546183189268664 0.25615411716254743" />
            </geometry>
            <material name="Blue">
            <color rgba="0 0 1.0 1.0"/>
            </material>
        </visual>
        <collision>
            <origin xyz="0 0 0.5" rpy="0 0 0"/>
            <geometry>
                <box size="0.31497512894389956 0.21546183189268664 0.25615411716254743" />
            </geometry>
        </collision>
    </link>
    <link name="2Link2">
        <inertial>
            <origin xyz="0 0 0.5" rpy="0 0 0"/>
            <mass value="1" />
            <inertia ixx="100" ixy="0" ixz="0" iyy="100" iyz="0" izz="100" />
        </inertial>
        <visual>
            <origin xyz="0 0 0.5" rpy="0 0 0"/>
            <geometry>
                <box size="0.0969133758589813 0.8030595564825719 0.46117214033594045" />
            </geometry>
            <material name="Blue">
            <color rgba="0 0 1.0 1.0"/>
            </material>
        </visual>
        <collision>
            <origin xyz="0 0 0.5" rpy="0 0 0"/>
            <geometry>
                <box size="0.0969133758589813 0.8030595564825719 0.46117214033594045" />
            </geometry>
        </collision>
    </link>
    <link name="2Link3">
        <inertial>
            <origin xyz="0 0 0.5" rpy="0 0 0"/>
            <mass value="1" />
            <inertia ixx="100" ixy="0" ixz="0" iyy="100" iyz="0" izz="100" />
        </inertial>
        <visual>
            <origin xyz="0 0 0.5" rpy="0 0 0"/>
            <geometry>
                <box size="0.970505750933635 0.9943114946299643 0.9572085962570475" />
            </geometry>
            <material name="Blue">
            <color rgba="0 0 1.0 1.0"/>
            </material>
        </visual>
        <collision>
            <origin xyz="0 0 0.5" rpy="0 0 0"/>
            <geometry>
                <box size="0.970505750933635 0.9943114946299643 0.9572085962570475" />
            </geometry>
        </collision>
    </link>
    <link name="2Link4">
        <inertial>
            <origin xyz="0 0 0.5" rpy="0 0 0"/>
            <mass value="1" />
            <inertia ixx="100" ixy="0" ixz="0" iyy="100" iyz="0" izz="100" />
        </inertial>
        <visual>
            <origin xyz="0 0 0.5" rpy="0 0 0"/>
            <geometry>
                <box size="0.9175726791038579 0.44623795133237754 0.39465706137801493" />
            </geometry>
            <material name="Blue">
            <color rgba="0 0 1.0 1.0"/>
            </material>
        </visual>
        <collision>
            <origin xyz="0 0 0.5" rpy="0 0 0"/>
            <geometry>
                <box size="0.9175726791038579 0.44623795133237754 0.39465706137801493" />
            </geometry>
        </collision>
    </link>
    <link name="2Link5">
        <inertial>
            <origin xyz="0 0 0.5" rpy="0 0 0"/>
            <mass value="1" />
            <inertia ixx="100" ixy="0" ixz="0" iyy="100" iyz="0" izz="100" />
        </inertial>
        <visual>
            <origin xyz="0 0 0.5" rpy="0 0 0"/>
            <geometry>
                <box size="0.11163526398752621 0.4101598799602384 0.21583918450935413" />
            </geometry>
            <material name="Green">
            <color rgba="0 1.0 0 1.0"/>
            </material>
        </visual>
        <collision>
            <origin xyz="0 0 0.5" rpy="0 0 0"/>
            <geometry>
                <box size="0.11163526398752621 0.4101598799602384 0.21583918450935413" />
            </geometry>
        </collision>
    </link>
    <link name="2Link6">
        <inertial>
            <origin xyz="0 0 0.5" rpy="0 0 0"/>
            <mass value="1" />
            <inertia ixx="100" ixy="0" ixz="0" iyy="100" iyz="0" izz="100" />
        </inertial>
        <visual>
            <origin xyz="0 0 0.5" rpy="0 0 0"/>
            <geometry>
                <box size="0.14364296345296756 0.5576005234069553 0.7683737563212097" />
            </geometry>
            <material name="Blue">
            <color rgba="0 0 1.0 1.0"/>
            </material>
        </visual>
        <collision>
            <origin xyz="0 0 0.5" rpy="0 0 0"/>
            <geometry>
                <box size="0.14364296345296756 0.5576005234069553 0.7683737563212097" />
            </geometry>
        </collision>
    </link>
    <link name="2Link7">
        <inertial>
            <origin xyz="0 0 0.5" rpy="0 0 0"/>
            <mass value="1" />
            <inertia ixx="100" ixy="0" ixz="0" iyy="100" iyz="0" izz="100" />
        </inertial>
        <visual>
            <origin xyz="0 0 0.5" rpy="0 0 0"/>
            <geometry>
                <box size="0.010266039971264629 0.8364999344097903 0.37967285571128406" />
            </geometry>
            <material name="Green">
            <color rgba="0 1.0 0 1.0"/>
            </material>
        </visual>
        <collision>
            <origin xyz="0 0 0.5" rpy="0 0 0"/>
            <geometry>
                <box size="0.010266039971264629 0.8364999344097903 0.37967285571128406" />
            </geometry>
        </collision>
    </link>
    <joint name="Torso_2Link0" type="revolute">
       <parent link="Torso"/>
       <child  link="2Link0"/>
       <origin rpy="0 0 0" xyz="0.0 2.0 10.5" />
     <axis xyz="1 1 0"/>
       <limit effort="0.0" lower="-3.14159" upper="3.14159" velocity="0.0"/>
    </joint>
    <joint name="2Link0_2Link1" type="revolute">
       <parent link="2Link0"/>
       <child  link="2Link1"/>
       <origin rpy="0 0 0" xyz="0 0 0.5" />
     <axis xyz="1 1 0"/>
       <limit effort="0.0" lower="-3.14159" upper="3.14159" velocity="0.0"/>
    </joint>
    <joint name="2Link1_2Link2" type="revolute">
       <parent link="2Link1"/>
       <child  link="2Link2"/>
       <origin rpy="0 0 0" xyz="0 0 0.5" />
     <axis xyz="1 1 0"/>
       <limit effort="0.0" lower="-3.14159" upper="3.14159" velocity="0.0"/>
    </joint>
    <joint name="2Link2_2Link3" type="revolute">
       <parent link="2Link2"/>
       <child  link="2Link3"/>
       <origin rpy="0 0 0" xyz="0 0 0.5" />
     <axis xyz="1 1 0"/>
       <limit effort="0.0" lower="-3.14159" upper="3.14159" velocity="0.0"/>
    </joint>
    <joint name="2Link3_2Link4" type="revolute">
       <parent link="2Link3"/>
       <child  link="2Link4"/>
       <origin rpy="0 0 0" xyz="0 0 0.5" />
     <axis xyz="1 1 0"/>
       <limit effort="0.0" lower="-3.14159" upper="3.14159" velocity="0.0"/>
    </joint>
    <joint name="2Link4_2Link5" type="revolute">
       <parent link="2Link4"/>
       <child  link="2Link5"/>
       <origin rpy="0 0 0" xyz="0 0 0.5" />
     <axis xyz="1 1 0"/>
       <limit effort="0.0" lower="-3.14159" upper="3.14159" velocity="0.0"/>
    </joint>
    <joint name="2Link5_2Link6" type="revolute">
       <parent link="2Link5"/>
       <child  link="2Link6"/>
       <origin rpy="0 0 0" xyz="0 0 0.5" />
     <axis xyz="1 1 0"/>
       <limit effort="0.0" lower="-3.14159" upper="3.14159" velocity="0.0"/>
    </joint>
    <joint name="2Link6_2Link7" type="revolute">
       <parent link="2Link6"/>
       <child  link="2Link7"/>
       <origin rpy="0 0 0" xyz="0 0 0.5" />
     <axis xyz="1 1 0"/>
       <limit effort="0.0" lower="-3.14159" upper="3.14159" velocity="0.0"/>
    </joint>
    <link name="3Link0">
        <inertial>
            <origin xyz="0.5 0 0" rpy="0 0 0"/>
            <mass value="1" />
            <inertia ixx="100" ixy="0" ixz="0" iyy="100" iyz="0" izz="100" />
        </inertial>
        <visual>
            <origin xyz="0.5 0 0" rpy="0 0 0"/>
            <geometry>
                <box size="0.1521129336835907 0.22507178082394041 0.30195656968040796" />
            </geometry>
            <material name="Blue">
            <color rgba="0 0 1.0 1.0"/>
            </material>
        </visual>
        <collision>
            <origin xyz="0.5 0 0" rpy="0 0 0"/>
            <geometry>
                <box size="0.1521129336835907 0.22507178082394041 0.30195656968040796" />
            </geometry>
        </collision>
    </link>
    <link name="3Link1">
        <inertial>
            <origin xyz="0.5 0 0" rpy="0 0 0"/>
            <mass value="1" />
            <inertia ixx="100" ixy="0" ixz="0" iyy="100" iyz="0" izz="100" />
        </inertial>
        <visual>
            <origin xyz="0.5 0 0" rpy="0 0 0"/>
            <geometry>
                <box size="0.024182962292916277 0.5702598175441372 0.15368803641576" />
            </geometry>
            <material name="Green">
            <color rgba="0 1.0 0 1.0"/>
            </material>
        </visual>
        <collision>
            <origin xyz="0.5 0 0" rpy="0 0 0"/>
            <geometry>
                <box size="0.024182962292916277 0.5702598175441372 0.15368803641576" />
            </geometry>
        </collision>
    </link>
    <link name="3Link2">
        <inertial>
            <origin xyz="0.5 0 0" rpy="0 0 0"/>
            <mass value="1" />
            <inertia ixx="100" ixy="0" ixz="0" iyy="100" iyz="0" izz="100" />
        </inertial>
        <visual>
            <origin xyz="0.5 0 0" rpy="0 0 0"/>
            <geometry>
                <box size="0.22439561463861157 0.22644479466419387 0.24540069688576283" />
            </geometry>
            <material name="Blue">
            <color rgba="0 0 1.0 1.0"/>
            </material>
        </visual>
        <collision>
            <origin xyz="0.5 0 0" rpy="0 0 0"/>
            <geometry>
                <box size="0.22439561463861157 0.22644479466419387 0.24540069688576283" />
            </geometry>
        </collision>
    </link>
    <link name="3Link3">
        <inertial>
            <origin xyz="0.5 0 0" rpy="0 0 0"/>
            <mass value="1" />
            <inertia ixx="100" ixy="0" ixz="0" iyy="100" iyz="0" izz="100" />
        </inertial>
        <visual>
            <origin xyz="0.5 0 0" rpy="0 0 0"/>
            <geometry>
                <box size="0.11984558340207274 0.22651523110083882 0.9161349568302045" />
            </geometry>
            <material name="Green">
            <color rgba="0 1.0 0 1.0"/>
            </material>
        </visual>
        <collision>
            <origin xyz="0.5 0 0" rpy="0 0 0"/>
            <geometry>
                <box size="0.11984558340207274 0.22651523110083882 0.9161349568302045" />
            </geometry>
        </collision>
    </link>
    <link name="3Link4">
        <inertial>
            <origin xyz="0.5 0 0" rpy="0 0 0"/>
            <mass value="1" />
            <inertia ixx="100" ixy="0" ixz="0" iyy="100" iyz="0" izz="100" />
        </inertial>
        <visual>
            <origin xyz="0.5 0 0" rpy="0 0 0"/>
            <geometry>
                <box size="0.6009733328750122 0.4624676631856156 0.8217036242316126" />
            </geometry>
            <material name="Blue">
            <color rgba="0 0 1.0 1.0"/>
            </material>
        </visual>
        <collision>
            <origin xyz="0.5 0 0" rpy="0 0 0"/>
            <geometry>
                <box size="0.6009733328750122 0.4624676631856156 0.8217036242316126" />
            </geometry>
        </collision>
    </link>
    <link name="3Link5">
        <inertial>
            <origin xyz="0.5 0 0" rpy="0 0 0"/>
            <mass value="1" />
            <inertia ixx="100" ixy="0" ixz="0" iyy="100" iyz="0" izz="100" />
        </inertial>
        <visual>
            <origin xyz="0.5 0 0" rpy="0 0 0"/>
            <geometry>
                <box size="0.5256854248088688 0.3063268554703461 0.4694985584579765" />
            </geometry>
            <material name="Green">
            <color rgba="0 1.0 0 1.0"/>
            </material>
        </visual>
        <collision>
            <origin xyz="0.5 0 0" rpy="0 0 0"/>
            <geometry>
                <box size="0.5256854248088688 0.3063268554703461 0.4694985584579765" />
            </geometry>
        </collision>
    </link>
    <link name="3Link6">
        <inertial>
            <origin xyz="0.5 0 0" rpy="0 0 0"/>
            <mass value="1" />
            <inertia ixx="100" ixy="0" ixz="0" iyy="100" iyz="0" izz="100" />
        </inertial>
        <visual>
            <origin xyz="0.5 0 0" rpy="0 0 0"/>
            <geometry>
                <box size="0.7380256593110501 0.5935413021695578 0.8368678810887397" />
            </geometry>
            <material name="Blue">
            <color rgba="0 0 1.0 1.0"/>
            </material>
        </visual>
        <collision>
            <origin xyz="0.5 0 0" rpy="0 0 0"/>
            <geometry>
                <box size="0.7380256593110501 0.5935413021695578 0.8368678810887397" />
            </geometry>
        </collision>
    </link>
    <link name="3Link7">
        <inertial>
            <origin xyz="0.5 0 0" rpy="0 0 0"/>
            <mass value="1" />
            <inertia ixx="100" ixy="0" ixz="0" iyy="100" iyz="0" izz="100" />
        </inertial>
        <visual>
            <origin xyz="0.5 0 0" rpy="0 0 0"/>
            <geometry>
                <box size="0.13154727842842173 0.8161504742513886 0.2543272689578209" />
            </geometry>
            <material name="Green">
            <color rgba="0 1.0 0 1.0"/>
            </material>
        </visual>
        <collision>
            <origin xyz="0.5 0 0" rpy="0 0 0"/>
            <geometry>
                <box size="0.13154727842842173 0.8161504742513886 0.2543272689578209" />
            </geometry>
        </collision>
    </link>
    <link name="3Link8">
        <inertial>
            <origin xyz="0.5 0 0" rpy="0 0 0"/>
            <mass value="1" />
            <inertia ixx="100" ixy="0" ixz="0" iyy="100" iyz="0" izz="100" />
        </inertial>
        <visual>
            <origin xyz="0.5 0 0" rpy="0 0 0"/>
            <geometry>
                <box size="0.7701164076698406 0.05255300488704939 0.45687224844652374" />
            </geometry>
            <material name="Blue">
            <color rgba="0 0 1.0 1.0"/>
            </material>
        </visual>
        <collision>
            <origin xyz="0.5 0 0" rpy="0 0 0"/>
            <geometry>
                <box size="0.7701164076698406 0.05255300488704939 0.45687224844652374" />
            </geometry>
        </collision>
    </link>
    <joint name="Torso_3Link0" type="revolute">
       <parent link="Torso"/>
       <child  link="3Link0"/>
       <origin rpy="0 0 0" xyz="0.5 2.0 10.0" />
     <axis xyz="1 1 0"/>
       <limit effort="0.0" lower="-3.14159" upper="3.14159" velocity="0.0"/>
    </joint>
    <joint name="3Link0_3Link1" type="revolute">
       <parent link="3Link0"/>
       <child  link="3Link1"/>
       <origin rpy="0 0 0" xyz="0.5 0 0" />
     <axis xyz="1 1 0"/>
       <limit effort="0.0" lower="-3.14159" upper="3.14159" velocity="0.0"/>
    </joint>
    <joint name="3Link1_3Link2" type="revolute">
       <parent link="3Link1"/>
       <child  link="3Link2"/>
       <origin rpy="0 0 0" xyz="0.5 0 0" />
     <axis xyz="1 1 0"/>
       <limit effort="0.0" lower="-3.14159" upper="3.14159" velocity="0.0"/>
    </joint>
    <joint name="3Link2_3Link3" type="revolute">
       <parent link="3Link2"/>
       <child  link="3Link3"/>
       <origin rpy="0 0 0" xyz="0.5 0 0" />
     <axis xyz="1 1 0"/>
       <limit effort="0.0" lower="-3.14159" upper="3.14159" velocity="0.0"/>
    </joint>
    <joint name="3Link3_3Link4" type="revolute">
       <parent link="3Link3"/>
       <child  link="3Link4"/>
       <origin rpy="0 0 0" xyz="0.5 0 0" />
     <axis xyz="1 1 0"/>
       <limit effort="0.0" lower="-3.14159" upper="3.14159" velocity="0.0"/>
    </joint>
    <joint name="3Link4_3Link5" type="revolute">
       <parent link="3Link4"/>
       <child  link="3Link5"/>
       <origin rpy="0 0 0" xyz="0.5 0 0" />
     <axis xyz="1 1 0"/>
       <limit effort="0.0" lower="-3.14159" upper="3.14159" velocity="0.0"/>
    </joint>
    <joint name="3Link5_3Link6" type="revolute">
       <parent link="3Link5"/>
       <child  link="3Link6"/>
       <origin rpy="0 0 0" xyz="0.5 0 0" />
     <axis xyz="1 1 0"/>
       <limit effort="0.0" lower="-3.14159" upper="3.14159" velocity="0.0"/>
    </joint>
    <joint name="3Link6_3Link7" type="revolute">
       <parent link="3Link6"/>
       <child  link="3Link7"/>
       <origin rpy="0 0 0" xyz="0.5 0 0" />
     <axis xyz="1 1 0"/>
       <limit effort="0.0" lower="-3.14159" upper="3.14159" velocity="0.0"/>
    </joint>
    <joint name="3Link7_3Link8" type="revolute">
       <parent link="3Link7"/>
       <child  link="3Link8"/>
       <origin rpy="0 0 0" xyz="0.5 0 0" />
     <axis xyz="1 1 0"/>
       <limit effort="0.0" lower="-3.14159" upper="3.14159" velocity="0.0"/>
    </joint>
    <link name="4Link0">
        <inertial>
            <origin xyz="0 -0.5 0" rpy="0 0 0"/>
            <mass value="1" />
            <inertia ixx="100" ixy="0" ixz="0" iyy="100" iyz="0" izz="100" />
        </inertial>
        <visual>
            <origin xyz="0 -0.5 0" rpy="0 0 0"/>
            <geometry>
                <box size="0.1294672002497994 0.23300090415444386 0.14263271723373772" />
            </geometry>
            <material name="Blue">
            <color rgba="0 0 1.0 1.0"/>
            </material>
        </visual>
        <collision>
            <origin xyz="0 -0.5 0" rpy="0 0 0"/>
            <geometry>
                <box size="0.1294672002497994 0.23300090415444386 0.14263271723373772" />
            </geometry>
        </collision>
    </link>
    <link name="4Link1">
        <inertial>
            <origin xyz="0 -0.5 0" rpy="0 0 0"/>
            <mass value="1" />
            <inertia ixx="100" ixy="0" ixz="0" iyy="100" iyz="0" izz="100" />
        </inertial>
        <visual>
            <origin xyz="0 -0.5 0" rpy="0 0 0"/>
            <geometry>
                <box size="0.568268759659578 0.895995681714343 0.6079735186946426" />
            </geometry>
            <material name="Green">
            <color rgba="0 1.0 0 1.0"/>
            </material>
        </visual>
        <collision>
            <origin xyz="0 -0.5 0" rpy="0 0 0"/>
            <geometry>
                <box size="0.568268759659578 0.895995681714343 0.6079735186946426" />
            </geometry>
        </collision>
    </link>
    <link name="4Link2">
        <inertial>
            <origin xyz="0 -0.5 0" rpy="0 0 0"/>
            <mass value="1" />
            <inertia ixx="100" ixy="0" ixz="0" iyy="100" iyz="0" izz="100" />
        </inertial>
        <visual>
            <origin xyz="0 -0.5 0" rpy="0 0 0"/>
            <geometry>
                <box size="0.041730749564672376 0.26072509815471057 0.4094813311420502" />
            </geometry>
            <material name="Green">
            <color rgba="0 1.0 0 1.0"/>
            </material>
        </visual>
        <collision>
            <origin xyz="0 -0.5 0" rpy="0 0 0"/>
            <geometry>
                <box size="0.041730749564672376 0.26072509815471057 0.4094813311420502" />
            </geometry>
        </collision>
    </link>
    <link name="4Link3">
        <inertial>
            <origin xyz="0 -0.5 0" rpy="0 0 0"/>
            <mass value="1" />
            <inertia ixx="100" ixy="0" ixz="0" iyy="100" iyz="0" izz="100" />
        </inertial>
        <visual>
            <origin xyz="0 -0.5 0" rpy="0 0 0"/>
            <geometry>
                <box size="0.7740985766604971 0.9967819742191734 0.384111938858262" />
            </geometry>
            <material name="Green">
            <color rgba="0 1.0 0 1.0"/>
            </material>
        </visual>
        <collision>
            <origin xyz="0 -0.5 0" rpy="0 0 0"/>
            <geometry>
                <box size="0.7740985766604971 0.9967819742191734 0.384111938858262" />
            </geometry>
        </collision>
    </link>
    <link name="4Link4">
        <inertial>
            <origin xyz="0 -0.5 0" rpy="0 0 0"/>
            <mass value="1" />
            <inertia ixx="100" ixy="0" ixz="0" iyy="100" iyz="0" izz="100" />
        </inertial>
        <visual>
            <origin xyz="0 -0.5 0" rpy="0 0 0"/>
            <geometry>
                <box size="0.9223809048434752 0.5246591715545786 0.1550358237425551" />
            </geometry>
            <material name="Blue">
            <color rgba="0 0 1.0 1.0"/>
            </material>
        </visual>
        <collision>
            <origin xyz="0 -0.5 0" rpy="0 0 0"/>
            <geometry>
                <box size="0.9223809048434752 0.5246591715545786 0.1550358237425551" />
            </geometry>
        </collision>
    </link>
    <link name="4Link5">
        <inertial>
            <origin xyz="0 -0.5 0" rpy="0 0 0"/>
            <mass value="1" />
            <inertia ixx="100" ixy="0" ixz="0" iyy="100" iyz="0" izz="100" />
        </inertial>
        <visual>
            <origin xyz="0 -0.5 0" rpy="0 0 0"/>
            <geometry>
                <box size="0.8591533484736429 0.4436462862086238 0.7216024465931472" />
            </geometry>
            <material name="Blue">
            <color rgba="0 0 1.0 1.0"/>
            </material>
        </visual>
        <collision>
            <origin xyz="0 -0.5 0" rpy="0 0 0"/>
            <geometry>
                <box size="0.8591533484736429 0.4436462862086238 0.7216024465931472" />
            </geometry>
        </collision>
    </link>
    <link name="4Link6">
        <inertial>
            <origin xyz="0 -0.5 0" rpy="0 0 0"/>
            <mass value="1" />
            <inertia ixx="100" ixy="0" ixz="0" iyy="100" iyz="0" izz="100" />
        </inertial>
        <visual>
            <origin xyz="0 -0.5 0" rpy="0 0 0"/>
            <geometry>
                <box size="0.2014214782277567 0.995835509490336 0.027346958864758686" />
            </geometry>
            <material name="Blue">
            <color rgba="0 0 1.0 1.0"/>
            </material>
        </visual>
        <collision>
            <origin xyz="0 -0.5 0" rpy="0 0 0"/>
            <geometry>
                <box size="0.2014214782277567 0.995835509490336 0.027346958864758686" />
            </geometry>
        </collision>
    </link>
    <link name="4Link7">
        <inertial>
            <origin xyz="0 -0.5 0" rpy="0 0 0"/>
            <mass value="1" />
            <inertia ixx="100" ixy="0" ixz="0" iyy="100" iyz="0" izz="100" />
        </inertial>
        <visual>
            <origin xyz="0 -0.5 0" rpy="0 0 0"/>
            <geometry>
                <box size="0.6953074049742762 0.42491573472231625 0.867877538001802" />
            </geometry>
            <material name="Blue">
            <color rgba="0 0 1.0 1.0"/>
            </material>
        </visual>
        <collision>
            <origin xyz="0 -0.5 0" rpy="0 0 0"/>
            <geometry>
                <box size="0.6953074049742762 0.42491573472231625 0.867877538001802" />
            </geometry>
        </collision>
    </link>
    <link name="4Link8">
        <inertial>
            <origin xyz="0 -0.5 0" rpy="0 0 0"/>
            <mass value="1" />
            <inertia ixx="100" ixy="0" ixz="0" iyy="100" iyz="0" izz="100" />
        </inertial>
        <visual>
            <origin xyz="0 -0.5 0" rpy="0 0 0"/>
            <geometry>
                <box size="0.568735698751539 0.9858755388975221 0.7206810148529441" />
            </geometry>
            <material name="Blue">
            <color rgba="0 0 1.0 1.0"/>
            </material>
        </visual>
        <collision>
            <origin xyz="0 -0.5 0" rpy="0 0 0"/>
            <geometry>
                <box size="0.568735698751539 0.9858755388975221 0.7206810148529441" />
            </geometry>
        </collision>
    </link>
    <link name="4Link9">
        <inertial>
            <origin xyz="0 -0.5 0" rpy="0 0 0"/>
            <mass value="1" />
            <inertia ixx="100" ixy="0" ixz="0" iyy="100" iyz="0" izz="100" />
        </inertial>
        <visual>
            <origin xyz="0 -0.5 0" rpy="0 0 0"/>
            <geometry>
                <box size="0.6403930786742648 0.3054183886093448 0.37266569538992256" />
            </geometry>
            <material name="Green">
            <color rgba="0 1.0 0 1.0"/>
            </material>
        </visual>
        <collision>
            <origin xyz="0 -0.5 0" rpy="0 0 0"/>
            <geometry>
                <box size="0.6403930786742648 0.3054183886093448 0.37266569538992256" />
            </geometry>
        </collision>
    </link>
    <joint name="Torso_4Link0" type="revolute">
       <parent link="Torso"/>
       <child  link="4Link0"/>
       <origin rpy="0 0 0" xyz="0.0 1.5 10.0" />
     <axis xyz="1 1 0"/>
       <limit effort="0.0" lower="-3.14159" upper="3.14159" velocity="0.0"/>
    </joint>
    <joint name="4Link0_4Link1" type="revolute">
       <parent link="4Link0"/>
       <child  link="4Link1"/>
       <origin rpy="0 0 0" xyz="0 -0.5 0" />
     <axis xyz="1 1 0"/>
       <limit effort="0.0" lower="-3.14159" upper="3.14159" velocity="0.0"/>
    </joint>
    <joint name="4Link1_4Link2" type="revolute">
       <parent link="4Link1"/>
       <child  link="4Link2"/>
       <origin rpy="0 0 0" xyz="0 -0.5 0" />
     <axis xyz="1 1 0"/>
       <limit effort="0.0" lower="-3.14159" upper="3.14159" velocity="0.0"/>
    </joint>
    <joint name="4Link2_4Link3" type="revolute">
       <parent link="4Link2"/>
       <child  link="4Link3"/>
       <origin rpy="0 0 0" xyz="0 -0.5 0" />
     <axis xyz="1 1 0"/>
       <limit effort="0.0" lower="-3.14159" upper="3.14159" velocity="0.0"/>
    </joint>
    <joint name="4Link3_4Link4" type="revolute">
       <parent link="4Link3"/>
       <child  link="4Link4"/>
       <origin rpy="0 0 0" xyz="0 -0.5 0" />
     <axis xyz="1 1 0"/>
       <limit effort="0.0" lower="-3.14159" upper="3.14159" velocity="0.0"/>
    </joint>
    <joint name="4Link4_4Link5" type="revolute">
       <parent link="4Link4"/>
       <child  link="4Link5"/>
       <origin rpy="0 0 0" xyz="0 -0.5 0" />
     <axis xyz="1 1 0"/>
       <limit effort="0.0" lower="-3.14159" upper="3.14159" velocity="0.0"/>
    </joint>
    <joint name="4Link5_4Link6" type="revolute">
       <parent link="4Link5"/>
       <child  link="4Link6"/>
       <origin rpy="0 0 0" xyz="0 -0.5 0" />
     <axis xyz="1 1 0"/>
       <limit effort="0.0" lower="-3.14159" upper="3.14159" velocity="0.0"/>
    </joint>
    <joint name="4Link6_4Link7" type="revolute">
       <parent link="4Link6"/>
       <child  link="4Link7"/>
       <origin rpy="0 0 0" xyz="0 -0.5 0" />
     <axis xyz="1 1 0"/>
       <limit effort="0.0" lower="-3.14159" upper="3.14159" velocity="0.0"/>
    </joint>
    <joint name="4Link7_4Link8" type="revolute">
       <parent link="4Link7"/>
       <child  link="4Link8"/>
       <origin rpy="0 0 0" xyz="0 -0.5 0" />
     <axis xyz="1 1 0"/>
       <limit effort="0.0" lower="-3.14159" upper="3.14159" velocity="0.0"/>
    </joint>
    <joint name="4Link8_4Link9" type="revolute">
       <parent link="4Link8"/>
       <child  link="4Link9"/>
       <origin rpy="0 0 0" xyz="0 -0.5 0" />
     <axis xyz="1 1 0"/>
       <limit effort="0.0" lower="-3.14159" upper="3.14159" velocity="0.0"/>
    </joint>
</robot>