<robot name = "robot">
    <link name="Torso">
        <inertial>
            <origin xyz="0 2 0.5" rpy="0 0 0"/>
            <mass value="1" />
            <inertia ixx="100" ixy="0" ixz="0" iyy="100" iyz="0" izz="100" />
        </inertial>
        <visual>
            <origin xyz="0 2 0.5" rpy="0 0 0"/>
            <geometry>
                <box size="0.5 0.5 0.5" />
            </geometry>
            <material name="Cyan">
                <color rgba="0 1.0 1.0 1.0"/>
            </material>
        </visual>
        <collision>
            <origin xyz="0 2 0.5" rpy="0 0 0"/>
            <geometry>
                <box size="0.5 0.5 0.5" />
            </geometry>
        </collision>
    </link>
    <joint name="Torso_Link0" type="revolute">
       <parent link="Torso"/>
       <child  link="Link0"/>
       <origin rpy="0 0 0" xyz="0 2.25 0.5" />
     <axis xyz="1 1 0"/>
       <limit effort="0.0" lower="-3.14159" upper="3.14159" velocity="0.0"/>
    </joint>
    <link name="Link0">
        <inertial>
            <origin xyz="0 0.25 0" rpy="0 0 0"/>
            <mass value="1" />
            <inertia ixx="100" ixy="0" ixz="0" iyy="100" iyz="0" izz="100" />
        </inertial>
        <visual>
            <origin xyz="0 0.25 0" rpy="0 0 0"/>
            <geometry>
                <box size="0.5517751318653422 0.8962703709689743 0.3540665375815547" />
            </geometry>
            <material name="Blue">
            <color rgba="0 0 1.0 1.0"/>
            </material>
        </visual>
        <collision>
            <origin xyz="0 0.25 0" rpy="0 0 0"/>
            <geometry>
                <box size="0.5517751318653422 0.8962703709689743 0.3540665375815547" />
            </geometry>
        </collision>
    </link>
    <link name="Link1">
        <inertial>
            <origin xyz="0 0.25 0" rpy="0 0 0"/>
            <mass value="1" />
            <inertia ixx="100" ixy="0" ixz="0" iyy="100" iyz="0" izz="100" />
        </inertial>
        <visual>
            <origin xyz="0 0.25 0" rpy="0 0 0"/>
            <geometry>
                <box size="0.01632207201143354 0.017426879615386692 0.6722563570354422" />
            </geometry>
            <material name="Green">
            <color rgba="0 1.0 0 1.0"/>
            </material>
        </visual>
        <collision>
            <origin xyz="0 0.25 0" rpy="0 0 0"/>
            <geometry>
                <box size="0.01632207201143354 0.017426879615386692 0.6722563570354422" />
            </geometry>
        </collision>
    </link>
    <link name="Link2">
        <inertial>
            <origin xyz="0 0.25 0" rpy="0 0 0"/>
            <mass value="1" />
            <inertia ixx="100" ixy="0" ixz="0" iyy="100" iyz="0" izz="100" />
        </inertial>
        <visual>
            <origin xyz="0 0.25 0" rpy="0 0 0"/>
            <geometry>
                <box size="0.36871696893420547 0.6621633504164444 0.626902371650033" />
            </geometry>
            <material name="Green">
            <color rgba="0 1.0 0 1.0"/>
            </material>
        </visual>
        <collision>
            <origin xyz="0 0.25 0" rpy="0 0 0"/>
            <geometry>
                <box size="0.36871696893420547 0.6621633504164444 0.626902371650033" />
            </geometry>
        </collision>
    </link>
    <link name="Link3">
        <inertial>
            <origin xyz="0 0.25 0" rpy="0 0 0"/>
            <mass value="1" />
            <inertia ixx="100" ixy="0" ixz="0" iyy="100" iyz="0" izz="100" />
        </inertial>
        <visual>
            <origin xyz="0 0.25 0" rpy="0 0 0"/>
            <geometry>
                <box size="0.6940346628152932 0.9002849590279591 0.2975747619778175" />
            </geometry>
            <material name="Blue">
            <color rgba="0 0 1.0 1.0"/>
            </material>
        </visual>
        <collision>
            <origin xyz="0 0.25 0" rpy="0 0 0"/>
            <geometry>
                <box size="0.6940346628152932 0.9002849590279591 0.2975747619778175" />
            </geometry>
        </collision>
    </link>
    <link name="Link4">
        <inertial>
            <origin xyz="0 0.25 0" rpy="0 0 0"/>
            <mass value="1" />
            <inertia ixx="100" ixy="0" ixz="0" iyy="100" iyz="0" izz="100" />
        </inertial>
        <visual>
            <origin xyz="0 0.25 0" rpy="0 0 0"/>
            <geometry>
                <box size="0.5415986924940379 0.29528233856550523 0.1916421239530527" />
            </geometry>
            <material name="Green">
            <color rgba="0 1.0 0 1.0"/>
            </material>
        </visual>
        <collision>
            <origin xyz="0 0.25 0" rpy="0 0 0"/>
            <geometry>
                <box size="0.5415986924940379 0.29528233856550523 0.1916421239530527" />
            </geometry>
        </collision>
    </link>
    <link name="Link5">
        <inertial>
            <origin xyz="0 0.25 0" rpy="0 0 0"/>
            <mass value="1" />
            <inertia ixx="100" ixy="0" ixz="0" iyy="100" iyz="0" izz="100" />
        </inertial>
        <visual>
            <origin xyz="0 0.25 0" rpy="0 0 0"/>
            <geometry>
                <box size="0.3871417117157646 0.45900534896959655 0.4314032814880141" />
            </geometry>
            <material name="Blue">
            <color rgba="0 0 1.0 1.0"/>
            </material>
        </visual>
        <collision>
            <origin xyz="0 0.25 0" rpy="0 0 0"/>
            <geometry>
                <box size="0.3871417117157646 0.45900534896959655 0.4314032814880141" />
            </geometry>
        </collision>
    </link>
    <link name="Link6">
        <inertial>
            <origin xyz="0 0.25 0" rpy="0 0 0"/>
            <mass value="1" />
            <inertia ixx="100" ixy="0" ixz="0" iyy="100" iyz="0" izz="100" />
        </inertial>
        <visual>
            <origin xyz="0 0.25 0" rpy="0 0 0"/>
            <geometry>
                <box size="0.5165020736020559 0.15568360255754699 0.10179765048322387" />
            </geometry>
            <material name="Green">
            <color rgba="0 1.0 0 1.0"/>
            </material>
        </visual>
        <collision>
            <origin xyz="0 0.25 0" rpy="0 0 0"/>
            <geometry>
                <box size="0.5165020736020559 0.15568360255754699 0.10179765048322387" />
            </geometry>
        </collision>
    </link>
    <link name="Link7">
        <inertial>
            <origin xyz="0 0.25 0" rpy="0 0 0"/>
            <mass value="1" />
            <inertia ixx="100" ixy="0" ixz="0" iyy="100" iyz="0" izz="100" />
        </inertial>
        <visual>
            <origin xyz="0 0.25 0" rpy="0 0 0"/>
            <geometry>
                <box size="0.3384106315725034 0.09529451825882185 0.48998675141597114" />
            </geometry>
            <material name="Blue">
            <color rgba="0 0 1.0 1.0"/>
            </material>
        </visual>
        <collision>
            <origin xyz="0 0.25 0" rpy="0 0 0"/>
            <geometry>
                <box size="0.3384106315725034 0.09529451825882185 0.48998675141597114" />
            </geometry>
        </collision>
    </link>
    <link name="Link8">
        <inertial>
            <origin xyz="0 0.25 0" rpy="0 0 0"/>
            <mass value="1" />
            <inertia ixx="100" ixy="0" ixz="0" iyy="100" iyz="0" izz="100" />
        </inertial>
        <visual>
            <origin xyz="0 0.25 0" rpy="0 0 0"/>
            <geometry>
                <box size="0.3306323555961628 0.16279619375486065 0.678857253887734" />
            </geometry>
            <material name="Blue">
            <color rgba="0 0 1.0 1.0"/>
            </material>
        </visual>
        <collision>
            <origin xyz="0 0.25 0" rpy="0 0 0"/>
            <geometry>
                <box size="0.3306323555961628 0.16279619375486065 0.678857253887734" />
            </geometry>
        </collision>
    </link>
    <joint name="Link0_Link1" type="revolute">
       <parent link="Link0"/>
       <child  link="Link1"/>
       <origin rpy="0 0 0" xyz="0 0.5 0" />
     <axis xyz="1 1 0"/>
       <limit effort="0.0" lower="-3.14159" upper="3.14159" velocity="0.0"/>
    </joint>
    <joint name="Link1_Link2" type="revolute">
       <parent link="Link1"/>
       <child  link="Link2"/>
       <origin rpy="0 0 0" xyz="0 0.5 0" />
     <axis xyz="1 1 0"/>
       <limit effort="0.0" lower="-3.14159" upper="3.14159" velocity="0.0"/>
    </joint>
    <joint name="Link2_Link3" type="revolute">
       <parent link="Link2"/>
       <child  link="Link3"/>
       <origin rpy="0 0 0" xyz="0 0.5 0" />
     <axis xyz="1 1 0"/>
       <limit effort="0.0" lower="-3.14159" upper="3.14159" velocity="0.0"/>
    </joint>
    <joint name="Link3_Link4" type="revolute">
       <parent link="Link3"/>
       <child  link="Link4"/>
       <origin rpy="0 0 0" xyz="0 0.5 0" />
     <axis xyz="1 1 0"/>
       <limit effort="0.0" lower="-3.14159" upper="3.14159" velocity="0.0"/>
    </joint>
    <joint name="Link4_Link5" type="revolute">
       <parent link="Link4"/>
       <child  link="Link5"/>
       <origin rpy="0 0 0" xyz="0 0.5 0" />
     <axis xyz="1 1 0"/>
       <limit effort="0.0" lower="-3.14159" upper="3.14159" velocity="0.0"/>
    </joint>
    <joint name="Link5_Link6" type="revolute">
       <parent link="Link5"/>
       <child  link="Link6"/>
       <origin rpy="0 0 0" xyz="0 0.5 0" />
     <axis xyz="1 1 0"/>
       <limit effort="0.0" lower="-3.14159" upper="3.14159" velocity="0.0"/>
    </joint>
    <joint name="Link6_Link7" type="revolute">
       <parent link="Link6"/>
       <child  link="Link7"/>
       <origin rpy="0 0 0" xyz="0 0.5 0" />
     <axis xyz="1 1 0"/>
       <limit effort="0.0" lower="-3.14159" upper="3.14159" velocity="0.0"/>
    </joint>
    <joint name="Link7_Link8" type="revolute">
       <parent link="Link7"/>
       <child  link="Link8"/>
       <origin rpy="0 0 0" xyz="0 0.5 0" />
     <axis xyz="1 1 0"/>
       <limit effort="0.0" lower="-3.14159" upper="3.14159" velocity="0.0"/>
    </joint>
</robot>